Workbook

Sheet Changelog
A1: Änderungsdatum | B1: Bearbeitet durch: | C1: Blatt/Unterseite Website | D1: Zelle/Position auf Website | E1: Alter Code/ Änderung auf Website | F1: Neuer Code | G1: Priorität | H1: Im Online-Tool angepasst? | I1: Webumsetzung geprüft am: | J1: Anmerkung
A2: 45030 | B2: Julia | C2: Alle | E2: Formeln: Bezug auf Zellen | F2: Formeln: Bezug auf Variablennamen (siehe Reiter "Formeln" -> "Namens-Manager") | G2: Erledigt
A3: 45070 | B3: Julia | C3: Vorüberlegungen 1/4 | D3: Linke Seite | E3: Bei Aufzählung einzelne Wörter fettgedruckt wie in Figma | G3: Erledigt | I3: 45085
A4: 45070 | B4: Julia | C4: Vorüberlegungen 1/4 | D4: Rechte Seite | E4: Verknüpfung der Felder in der Übersichtsgrafik mit den Infoboxen (gleiche Infoboxen wie im Teil "Hintergrundinformationen") | G4: Erledigt | I4: 45077
A5: 45070 | B5: Julia | C5: Vorüberlegungen 2/4 | D5: Linke Seite | E5: Kopfzeile: Zurücksetzen-Funktion neben "ANGABEN" wie in Figma | G5: Erledigt | I5: 45078
A6: 45070 | B6: Julia | C6: Vorüberlegungen 2/4 | D6: Rechte Seite | E6: Kopfzeile wie in Figma ergänzen: DOKUMENTATION, Download-Funktion, Wechselbutton zwischen Dokumentation und Übersichtsgrafik | G6: Erledigt | I6: 45077
A7: 45070 | B7: Julia | C7: Vorüberlegungen 2/4 | D7: Rechte Seite | E7: Auswahl der Ansicht Dokumentation/Übersichtsgrafik über Wechselbutton in Kopfzeile + über Klicken auf DOKUMENTATION oder ÜBERSICHTSGRAFIK in Kopfzeile + über Pfeil links/rechts auf der rechten Seite neben der Übersichtsgrafik (siehe Animation in Figma) | G7: Erledigt | I7: 45076
A8: 45070 | B8: Julia | C8: Vorüberlegungen 2/4 | D8: Rechte Seite | E8: Der letzte Satz im Feld Nr. 1 "Bitte überlegen Sie mithilfe der nächsten Frage, ob der Fuhrpark noch weiter verkleinert werden kann." ist statisch und doppelt - einfach rausnehmen (der entsprechende Satz kommt eh über die Verknüpfungen in der Excel-Datei) | G8: Erledigt | I8: 45076
A9: 45070 | B9: Julia | C9: Vorüberlegungen 2/4 | D9: Rechte Seite | E9: "vergößern" und Prozentzahl in Rot, wenn "vergrößern" gezogen wird; "verkleinern" und "0%" in Gelb, wenn "verkleinern" + 0% berechnet wird; bei Prozentzahlen über 1000 wird zurzeit ein Komma statt Tausenderpunkt angezeigt -> bitte zu Punkt ändern | G9: Erledigt | I9: 45078
A10: 45070 | B10: Julia | C10: Vorüberlegungen 2/4 | D10: Linke Seite | E10: Eingabekästen: Rahmen auch schon vor der Eingabe/Auswahl in dunkelgrau (wie in Figma) und Sternchen weglassen | G10: Erledigt | I10: 45085
A11: 45070 | B11: Julia | C11: Vorüberlegungen 2/4 | D11: Linke Seite | E11: Fragebutton neben "Wie viele Fahrzeuge aus einem vorhandenen Fuhrpark werden durch diese Beschaffung ersetzt?" (siehe Figma, Text für Hilfebox siehe Link in Kommentar) | G11: Erledigt | I11: 45077
A12: 45070 | B12: Julia | C12: Vorüberlegungen 3/4 | D12: Linke Seite | E12: PKW (über der Auswahl für Pooling etc.) | F12: Pkw | G12: Erledigt | I12: 45085
A13: 45070 | B13: Julia | C13: Vorüberlegungen 3/4 | D13: Linke Seite | E13: Farbige Buttons neben Auswahloptionen hinzufügen (siehe Figma), die dann die entsprechenden Infoboxen öffnen | G13: Erledigt | I13: 45086
A14: 45070 | B14: Julia | C14: Vorüberlegungen 3/4 | D14: Linke Seite | E14: Auswahlfelder verbreitern, sodass "Häufigkeit der Nutzung" ganz zu sehen ist -> Schrift ggf. auch ein bisschen kleiner; Erste Auswahlfelder etwas von "Eine Analyse der bisherigen Nutzung des Fuhrparks kann bei der Beantwortung der Frage helfen." abrücken/etwas tiefer (siehe Figma) | G14: Erledigt | I14: 45085
A15: 45070 | B15: Julia | C15: Vorüberlegungen 4/4 | D15: Rechte Seite | E15: Unter 3. -> Hinweis auf Download + Download-Button (siehe Figma) -> im Gegensatz zu Figma soll im Button allerdings stehen "Download Vorüberlegungen" | G15: Erledigt | I15: 45077
A16: 45070 | B16: Julia | C16: Startseite | D16: Text über Tooleinstieg | E16: Text in zwei Zeilen anordnen, damit der Text nicht über die gesamte Seite geht | G16: Erledigt | I16: 45078
A17: 45070 | B17: Julia | C17: Startseite | D17: Burgermenü oben rechts | E17: Menü nur als Box auf der rechten Seite ausklappen (siehe Figma) | G17: Erledigt | I17: 45076
A18: 45070 | B18: Julia | C18: Startseite | D18: Fußzeile | E18: ifeu-Logo nach rechts rücken (sieht bei mir verrutscht aus und ist unter den anderen drei Logos gelandet) | G18: Erledigt | I18: 45078
A19: 45070 | B19: Julia | C19: Startseite | D19: Fußzeile | E19: Link auf Logos setzen -> DBU: https://www.dbu.de/; Berlin: https://www.berlin.de/sen/uvk/; Brandenburg: https://mluk.brandenburg.de/mluk/de/ | G19: Erledigt | I19: 45076
A20: 45070 | B20: Julia | C20: Startseite | D20: Akkordeonmenü | E20: Nicht als Kasten mit Schatten außenrum, sondern vom Design her wie in Figma | G20: Erledigt | I20: 45086
A21: 45070 | B21: Julia | C21: Startseite | D21: Fußzeile | E21: Impressum und Datenschutz: Overlays mit Infos ergänzen | G21: Erledigt | I21: 45077
A22: 45070 | B22: Julia | C22: Bildschirmbreite | E22: Tool nicht über die ganze Breite gehen lassen, sondern so wie in Figma + etwas mehr Platz am Rand lassen (wie in Figma) | G22: Erledigt | I22: 45085
A23: 45070 | B23: Julia | C23: Empfehlungen 1/4 | D23: Linke Seite | E23: Kopfzeile: Auto-Icon ist wie in Figma ganz ohne Schatten. Bei den Vorüberlegungen hattest du die Version mit ein bisschen Schatten (weniger als in der Übersichtsgrafik, aber mehr als jetzt gerade in Figma in der Kopfzeile) genommen. Das finde ich sogar besser, also gerne auch hier die Version mit ein bisschen Schatten | G23: Erledigt | I23: 45085
A24: 45070 | B24: Julia | C24: Empfehlungen 1/4 | D24: Linke Seite | E24: Etwas Abstand zwischen den Aufzählungspunkten lassen (siehe Figma) | G24: Erledigt | I24: 45085
A25: 45070 | B25: Julia | C25: Empfehlungen 2/4 | D25: Linke Seite | E25: Die ersten beiden Fragen haben schon einen Eintrag, obwohl ich ein neues privates Fenster geöffnet habe | G25: Erledigt | I25: 45076
A26: 45070 | B26: Julia | C26: Empfehlungen 3/4 | D26: Linke Seite | E26: Die Ja/Nein-Buttons sehen schon für "Ja" vorausgewählt aus, aber werden anscheinend erst gezogen, nachdem man nochmal draufklickt/die Auswahl wechselt. Hier bitte im ersten Schritt keine Seite einfärben und mit Häkchen versehen | G26: Erledigt | I26: 45076
A27: 45070 | B27: Julia | C27: Empfehlungen 4/4 | D27: Linke Seite | E27: Kopfzeile: ANGABEN statt FAHRZEUGSEGMENT | G27: Erledigt | I27: 45078
A28: 45070 | B28: Julia | C28: Empfehlungen 4/4 | D28: Linke Seite | E28: Infokasten zu Umweltanforderungen: Bindestrich in "Umwelt-anforderungen" rausnehmen -> also erster Satz "Neben der Wahl der Antriebsart und des Fahrzeugsegments können Umweltanforderungen in der Ausschreibung einen Beitrag zur umweltverträglichen Pkw-Beschaffung leisten." | G28: Erledigt | I28: 45078
A29: 45070 | B29: Julia | C29: Empfehlungen 4/4 | D29: Ansicht | E29: Bei mir muss man gerade scrollen, um alles zu sehen. In Figma ist das nicht nötig, aber da ist die Schrift dann auch noch kleiner, oder? Kleiner würde ich mit der Schrift lieber nicht werden. Falls sich das Scrollen nicht vermeiden lässt, gerne die Kopfzeile mit "EMPFEHLUNGEN 4/4" etc. fixieren | G29: Erledigt | I29: 45090
A30: 45071 | B30: Julia | C30: Vorüberlegungen 3/4 | D30: Rechte Seite | E30: Grafik Alternativen zum Pkw-Kauf -> Anordnung: Einordnung oben/unten in Grafik tauschen, also Fahrrad + ÖPNV oben, die Pkw-bezogenen Kreise (Pooling, Sharing, Mieten) unten; Kreisgröße abhängig machen von x-Achse, also links kleine Kreise, rechts die größten Kreise; Grafik schon anzeigen, sobald die erste Auswahl getroffen wird und dann nach und nach Kreise ergänzen, sobald jeweilige Auswahl getroffen | G30: Gering | H30: ja | I30: siehe Kommentar | J30: @Till: Ist mit Susanne besprochen; kannst du jetzt umsetzen (siehe Kommentar)
A31: 45071 | B31: Julia | C31: Vorüberlegungen 3/4 | D31: Rechte Seite | E31: Grafik Alternativen zum Pkw-Kauf -> Text + Hovern: y-Achsen-Beschriftung: "PKW" ersetzen mit "PKW-KAUF"; x-Achse -> REGELMÄSSIG hat ein S zu viel; Beschriftung aus Legende beim Hovern über Kreise anzeigen (siehe Figma) | G31: Erledigt | I31: 45078
A32: 45076 | B32: Julia | C32: Titel in Tab | E32: Wenn man auf die offizielle Website klickt, steht oben als Kurztitel im Tab zurzeit "DBU Online-Tool". Kannst du das ändern zu "Pkw-Beschaffung"? | G32: Erledigt | I32: 45078
A33: 45076 | B33: Julia | C33: Hintergrundinformationen | D33: UX | E33: Blassere Boxen für Car-Pooling etc. (entsprechend auch bei Öffentl. + Fahrrad) noch etwas blasser einfärben, damit sie sich noch besser abheben | G33: Erledigt | I33: 45085
A34: 45076 | B34: Julia | C34: Hintergrundinformationen | D34: Funktion | E34: Suchfunktion ergänzen (siehe Figma) | G34: Erledigt | I34: 45078
A35: 45076 | B35: Julia | C35: Hintergrundinformationen | D35: UX | E35: Bildchen neben Infoboxen passen nicht ganz in den Rahmen, wenn der Bildschirm sehr breit ist -> Problem löst sich ggf. ohnehin, wenn die Bildschirmbreite nicht mehr ganz ausgenutzt wird (siehe Changelog Zeile 22) | G35: Erledigt | I35: 45086
A36: 45076 | B36: Julia | C36: Download-Funktion | E36: Cool, dass du die Download-Funktion schon eingebaut hast. Die war an sich von Susanne erstmal nur vorgemerkt für einen späteren Zeitpunkt, aber scheint ja gut zu funktionieren. Eine Sache ist mir dabei jedoch aufgefallen: Die Infoboxen werden in der Druckansicht immer doppelt ausgegeben, also immer zwei Seiten mit dem gleichen Inhalt. Falls sich das einfach lösen lässt, gerne - ansonsten das Icon einfach erstmal weglassen | G36: Erledigt | I36: 45077
A37: 45076 | B37: Julia | C37: Hintergrundinformationen | D37: Infoboxen - Teilen | E37: Das Symbol zum Teilen war auch nur von Susanne vorgemerkt - das kannst du erstmal einfach rauslassen | G37: Erledigt | I37: 45076
A38: 45076 | B38: Julia | C38: Hintergrundinformationen | D38: Infoboxen - Links | E38: Links zu externen Websites in neuem Tab öffnen | G38: Mittel | H38: ja | I38: siehe Kommentar | J38: @Till: Ist mit Susanne besprochen; kannst du jetzt umsetzen (siehe Kommentar)
A39: 45076 | B39: Julia | C39: Hintergrundinformationen | D39: THG-Vergleich von Verkehrsmitteln | E39: In erstem Absatz und in Abb.-Beschriftung: CO2 -> 2 tiefgestellt; in Abb.-Beschriftung: (UBA 2021) verlinken (siehe Word) | G39: Erledigt | I39: 45085
A40: 45076 | B40: Julia | C40: Hintergrundinformationen | D40: THG-Vergleich von Verkehrsmitteln | E40: Grafik ist bei breitem Bildschirm sehr groß - so anpassen, dass die Schriftgröße in der Grafik in etwa so groß ist wie der restliche Text; Zoomfunktion für Grafik ermöglichen (siehe Figma) | G40: Erledigt | I40: 45086
...

Sheet Matrix
A1: Abfrage-Empfehlung-Matrix für das DBU-Online-Tool
A3: Kategorie | B3: Abfrage_1 | C3: Auswahl_1 | D3: Abfrage_2 | E3: Auswahl_2 | F3: Abfrage_3 | G3: Auswahl_3 | H3: Abfrage_4 | I3: Auswahl_4 | J3: Abfrage_5 | K3: Auswahl_5 | L3: Abfrage_6 | M3: Auswahl_6 | N3: Empfehlung
A4: Antriebsart | B4: Nicht relevant | C4: Nicht relevant | D4: Nicht relevant | E4: Nicht relevant | F4: Nicht relevant | G4: Nicht relevant | H4: Ladesäulen Standort | I4: Nein | J4: Nicht relevant | K4: Nicht relevant | L4: - | M4: - | N4: =E_A1 -> Wenn weder am Arbeitsplatz (bzw. im umliegenden öffentlichen Raum) noch am Wohnort der Nutzenden eine für mehrere Stunden nutzbare Lademöglichkeit besteht, ist die Beschaffung eines E-Autos nicht sinnvoll. In diesem Fall sollte ein möglichst sparsamer Verbrenner beschafft werden. Der Auf- und Ausbau von Ladeinfrastruktur ist jedoch unbedingt zu empfehlen, um in Zukunft E-Autos beschaffen zu können.
A5: Antriebsart | B5: Strecke pro Tag | C5: Kleiner gleich 150 km/Tag | D5: Strecken über 150 km | E5: Selten | F5: Nicht relevant | G5: Nicht relevant | H5: Nicht relevant | I5: Nicht relevant | J5: Fuhrpark | K5: Ja | L5: - | M5: - | N5: =E_A2 -> Ein E-Auto (BEV - rein batteriebetrieben) ist bevorzugt zu beschaffen, da Reichweiten bis 150 km mit den heute üblichen E-Pkw in der Regel erzielbar sind, sodass das Laden über Nacht ausreicht. Für einzelne Tagesstrecken über 150 km sollte idealerweise die Bahn oder der Fernbus genutzt werden. Bei schlechter Anbindung an den öffentlichen Verkehr oder mit viel Gepäck/Transportgut kann das E-Auto auch auf längeren Tagesstrecken zum Einsatz kommen, sofern unterwegs oder am Zielort (Schnell-)Lademöglichkeiten genutzt werden können. Besteht die Möglichkeit zum Laden nicht, kann in diesen Ausnahmefällen (falls vefügbar) ein anderes Fahrzeug mit entsprechender Reichweite aus dem Fuhrpark oder sonst ein Mietwagen genutzt werden.
A6: Antriebsart | B6: Strecke pro Tag | C6: Kleiner gleich 150 km/Tag | D6: Strecken über 150 km | E6: Selten | F6: Nicht relevant | G6: Nicht relevant | H6: Nicht relevant | I6: Nicht relevant | J6: Fuhrpark | K6: Nein | L6: - | M6: - | N6: =E_A3 -> Ein E-Auto (BEV - rein batteriebetrieben) ist bevorzugt zu beschaffen, da Reichweiten bis 150 km mit den heute üblichen E-Pkw in der Regel erzielbar sind, sodass das Laden über Nacht ausreicht. Für einzelne Tagesstrecken über 150 km sollte idealerweise die Bahn oder der Fernbus genutzt werden. Bei schlechter Anbindung an den öffentlichen Verkehr oder mit viel Gepäck/Transportgut kann das E-Auto auch auf längeren Tagesstrecken zum Einsatz kommen, sofern unterwegs oder am Zielort (Schnell-)Lademöglichkeiten genutzt werden können. Besteht die Möglichkeit zum Laden nicht, kann in diesen Ausnahmefällen ein Mietwagen genutzt werden.
A7: Antriebsart | B7: Strecke pro Tag | C7: Kleiner gleich 150 km/Tag | D7: Strecken über 150 km | E7: Häufig | F7: Nicht relevant | G7: Nicht relevant | H7: Nicht relevant | I7: Nicht relevant | J7: Fuhrpark | K7: Ja | L7: - | M7: - | N7: =E_A4 -> Ein E-Auto (BEV - rein batteriebetrieben) ist bevorzugt zu beschaffen, da Reichweiten bis 150 km mit den heute üblichen E-Pkw in der Regel erzielbar sind, sodass das Laden über Nacht ausreicht. Wenn häufiger auch mal Tagesstrecken über 150 km zurückgelegt werden sollen und unterwegs oder am Zielort (Schnell-) Lademöglichkeiten genutzt werden können, kann das E-Auto auch auf diesen Strecken zum Einsatz kommen. Besteht die Möglichkeit zum Laden nicht, sollte geprüft werden, ob für die Einsatztage mit längeren Strecken regelmäßig ein anderes Fahrzeug mit entsprechender Reichweite aus dem Fuhrpark genutzt werden kann. Dieses Fahrzeug kann auch ein E-Auto mit größerer Batterie sein, da in höheren Preissegmenten reale 300 km Reichweite gängig sind. Zudem ist zu prüfen, ob die Tagesstrecken über 150 km tatsächlich zum Großteil mit dem Pkw zurückgelegt werden müssen (aufgrund schlechter Anbindung an den öffentlichen Verkehr oder viel Gepäck/Transportgut) oder ob mit Bahn oder Fernbus gereist werden kann.
A8: Antriebsart | B8: Strecke pro Tag | C8: Kleiner gleich 150 km/Tag | D8: Strecken über 150 km | E8: Häufig | F8: Nicht relevant | G8: Nicht relevant | H8: Nicht relevant | I8: Nicht relevant | J8: Fuhrpark | K8: Nein | L8: - | M8: - | N8: =E_A5 -> Ein E-Auto (BEV - rein batteriebetrieben) ist bevorzugt zu beschaffen, da Reichweiten bis 150 km mit den heute üblichen E-Pkw in der Regel erzielbar sind, sodass das Laden über Nacht ausreicht. Wenn häufiger auch mal Tagesstrecken über 150 km zurückgelegt werden sollen und unterwegs oder am Zielort (Schnell-) Lademöglichkeiten genutzt werden können, kann das E-Auto auch auf diesen Strecken zum Einsatz kommen. Zudem ist zu prüfen, ob die Tagesstrecken über 150 km tatsächlich zum Großteil mit dem Pkw zurückgelegt werden müssen (aufgrund schlechter Anbindung an den öffentlichen Verkehr oder viel Gepäck/Transportgut) oder ob mit Bahn oder Fernbus gereist werden kann. Ist dies nicht der Fall und besteht keine Möglichkeit zum Laden während längerer Strecken, kann die Beschaffung eines Plug-in-Hybrids (PHEV) sinnvoll sein. In diesem Fall sollte jedoch darauf geachtet werden, dass bei den kürzeren Strecken, die im Regelfall gefahren werden, ein elektrischer Fahranteil von über 70 % erzielt wird. Dazu muss ein regelmäßiges Laden gewährleistet sein. Zudem sind PHEVs eher in größeren Fahrzeugsegmenten verfügbar. Je nach Anwendungsfall kann ein kleiner, sparsamer Verbrenner auch aus Umweltsicht vorteilhaft ggü. einem PHEV sein.
A9: Antriebsart | B9: Strecke pro Tag | C9: Kleiner gleich 150 km/Tag | D9: Strecken über 150 km | E9: Meistens | F9: Nicht relevant | G9: Nicht relevant | H9: Nicht relevant | I9: Nicht relevant | J9: Nicht relevant | K9: Nicht relevant | L9: - | M9: - | N9: =E_A6 -> Inkonsistente Eingabe: Die Aussage zur Häufigkeit längerer Strecken passt nicht mit der angegeben Streckenlänge eines repräsentativen Tages zusammen. Bitte passen Sie die Streckenlänge so an, dass sie den Fahrten im Regelfall entspricht.
A10: Antriebsart | B10: Strecke pro Tag | C10: Größer 150 km/Tag | D10: Strecken über 150 km | E10: Selten | F10: Nicht relevant | G10: Nicht relevant | H10: Nicht relevant | I10: Nicht relevant | J10: Nicht relevant | K10: Nicht relevant | L10: - | M10: - | N10: =E_A6 -> Inkonsistente Eingabe: Die Aussage zur Häufigkeit längerer Strecken passt nicht mit der angegeben Streckenlänge eines repräsentativen Tages zusammen. Bitte passen Sie die Streckenlänge so an, dass sie den Fahrten im Regelfall entspricht.
A11: Antriebsart | B11: Strecke pro Tag | C11: Größer 150 km/Tag | D11: Nicht relevant | E11: Nicht relevant | F11: Standzeiten | G11: Fast nie | H11: Nicht relevant | I11: Nicht relevant | J11: Nicht relevant | K11: Nicht relevant | L11: - | M11: - | N11: =E_A9 -> Erlaubt die Terminplanung auf langen Strecken keine bzw. nur sehr kurze Fahrtunterbrechungen unter 30 min, ist die Beschaffung eines E-Autos nicht sinnvoll. In diesem Fall sollte ein möglichst sparsamer Verbrenner beschafft werden.
A12: Antriebsart | B12: Strecke pro Tag | C12: Größer 150 km/Tag | D12: Strecken über 150 km | E12: Häufig | F12: Standzeiten | G12: Ab und zu | H12: Ladesäulen Strecken | I12: Ja | J12: Nicht relevant | K12: Nicht relevant | L12: - | M12: - | N12: =E_A8 -> Ein E-Auto (BEV - rein batteriebetrieben) mit großer Reichweite ist ggf. geeignet. In höheren Preissegmenten ist eine Reichweite von 300 km gängig. Es sollte jedoch beachtet werden, dass dem Umweltvorteil eines BEV in der Nutzung die Herstellungsemissionen einer großen Batterie gegenüberstehen. Zudem sind große Batterien vor allem in größeren Fahrzeugen verbaut. Ein kleinerer, möglichst sparsamer Verbrenner kann in diesem Anwendungsfall aus Umweltsicht (und aus Kostensicht ohnehin) also durchaus vorteilhaft sein.
A13: Antriebsart | B13: Strecke pro Tag | C13: Größer 150 km/Tag | D13: Nicht relevant | E13: Nicht relevant | F13: Standzeiten | G13: Ab und zu | H13: Ladesäulen Strecken | I13: Nein | J13: Nicht relevant | K13: Nicht relevant | L13: - | M13: - | N13: =E_A10 -> Bei vielen langen Strecken, auf denen keine Lademöglichkeit besteht, ist die Beschaffung eines E-Autos nicht sinnvoll. In diesem Fall sollte ein möglichst sparsamer Verbrenner beschafft werden.
A14: Antriebsart | B14: Strecke pro Tag | C14: Größer 150 km/Tag | D14: Strecken über 150 km | E14: Häufig | F14: Standzeiten | G14: Regelmäßig | H14: Ladesäulen Strecken | I14: Ja | J14: Nicht relevant | K14: Nicht relevant | L14: - | M14: - | N14: =E_A7 -> Erlaubt die Terminplanung Fahrtunterbrechungen von mind. 20-40 min an Standorten mit (Schnell-)Lademöglichkeiten, ist ein E-Auto (BEV - rein batteriebetrieben) trotz häufiger längerer Strecken bevorzugt zu beschaffen.
A15: Antriebsart | B15: Strecke pro Tag | C15: Größer 150 km/Tag | D15: Strecken über 150 km | E15: Häufig | F15: Standzeiten | G15: Regelmäßig | H15: Ladesäulen Strecken | I15: Nein | J15: Nicht relevant | K15: Nicht relevant | L15: - | M15: - | N15: =E_A11 -> Bei vielen langen Strecken, auf denen keine Lademöglichkeit besteht, ist die Beschaffung eines E-Autos nicht sinnvoll. In diesem Fall sollte ein möglichst sparsamer Verbrenner beschafft werden. Das Fahrprofil mit regelmäßigen längeren Fahrtunterbrechungen eignet sich an sich allerdings für E-Autos. Der weitere Ausbau der öffentlichen Ladeinfrastruktur oder die Wahl von Alternativrouten mit verfügbaren Ladesäulen kann also (in Zukunft) eine E-Auto-Beschaffung durchaus ermöglichen.
A16: Antriebsart | B16: Strecke pro Tag | C16: Größer 150 km/Tag | D16: Strecken über 150 km | E16: Meistens | F16: Standzeiten | G16: Ab und zu | H16: Ladesäulen Strecken | I16: Ja | J16: Nicht relevant | K16: Nicht relevant | L16: - | M16: - | N16: =E_A8 -> Ein E-Auto (BEV - rein batteriebetrieben) mit großer Reichweite ist ggf. geeignet. In höheren Preissegmenten ist eine Reichweite von 300 km gängig. Es sollte jedoch beachtet werden, dass dem Umweltvorteil eines BEV in der Nutzung die Herstellungsemissionen einer großen Batterie gegenüberstehen. Zudem sind große Batterien vor allem in größeren Fahrzeugen verbaut. Ein kleinerer, möglichst sparsamer Verbrenner kann in diesem Anwendungsfall aus Umweltsicht (und aus Kostensicht ohnehin) also durchaus vorteilhaft sein.
A17: Antriebsart | B17: Strecke pro Tag | C17: Größer 150 km/Tag | D17: Strecken über 150 km | E17: Meistens | F17: Standzeiten | G17: Regelmäßig | H17: Ladesäulen Strecken | I17: Ja | J17: Nicht relevant | K17: Nicht relevant | L17: - | M17: - | N17: =E_A8 -> Ein E-Auto (BEV - rein batteriebetrieben) mit großer Reichweite ist ggf. geeignet. In höheren Preissegmenten ist eine Reichweite von 300 km gängig. Es sollte jedoch beachtet werden, dass dem Umweltvorteil eines BEV in der Nutzung die Herstellungsemissionen einer großen Batterie gegenüberstehen. Zudem sind große Batterien vor allem in größeren Fahrzeugen verbaut. Ein kleinerer, möglichst sparsamer Verbrenner kann in diesem Anwendungsfall aus Umweltsicht (und aus Kostensicht ohnehin) also durchaus vorteilhaft sein.
A18: Antriebsart | B18: Strecke pro Tag | C18: Größer 150 km/Tag | D18: Strecken über 150 km | E18: Meistens | F18: Standzeiten | G18: Regelmäßig | H18: Ladesäulen Strecken | I18: Nein | J18: Nicht relevant | K18: Nicht relevant | L18: - | M18: - | N18: =E_A11 -> Bei vielen langen Strecken, auf denen keine Lademöglichkeit besteht, ist die Beschaffung eines E-Autos nicht sinnvoll. In diesem Fall sollte ein möglichst sparsamer Verbrenner beschafft werden. Das Fahrprofil mit regelmäßigen längeren Fahrtunterbrechungen eignet sich an sich allerdings für E-Autos. Der weitere Ausbau der öffentlichen Ladeinfrastruktur oder die Wahl von Alternativrouten mit verfügbaren Ladesäulen kann also (in Zukunft) eine E-Auto-Beschaffung durchaus ermöglichen.
A19: Fahrzeugsegment | B19: Anzahl_max Personen | C19: Kleiner 6 | D19: Nicht relevant | E19: Nicht relevant | F19: Transport Van | G19: Regelmäßig | H19: Nicht relevant | I19: Nicht relevant | J19: Nicht relevant | K19: Nicht relevant | L19: Nicht relevant | M19: Nicht relevant | N19: =E_F1 -> Bei regelmäßigen aufwändigen Transportanforderungen ist ein Van oder ein Fahrzeug der Rubrik Utilities (Hochdachkombis, Kleinbusse und Pick-ups, die als Pkw zugelassen sind) notwendig.
A20: Fahrzeugsegment | B20: Anzahl_max Personen | C20: Kleiner 6 | D20: Nicht relevant | E20: Nicht relevant | F20: Transport Van | G20: Nie (oder k.A.) | H20: Leitungsebene | I20: Ja | J20: Nicht relevant | K20: Nicht relevant | L20: Nicht relevant | M20: Nicht relevant | N20: =E_F2 -> Für die Leitungsebene besteht ggf. Anspruch auf ein Fahrzeug aus einem höheren Fahrzeugsegment. Trotzdem sollte aus Umweltgründen abgewogen werden, ob ein kleineres Fahrzeug geeignet ist und die Leitungsebene freiwillig auf diesen Anspruch verzichtet.
A21: Fahrzeugsegment | B21: Anzahl_max Personen | C21: 1 bis 2 | D21: Nicht relevant | E21: Nicht relevant | F21: Transport Van | G21: Nie | H21: Leitungsebene | I21: Nein | J21: Nicht relevant | K21: Nicht relevant | L21: Strecken über 150 km | M21: Selten | N21: =E_F3 -> Aus Umweltsicht sollte bei einer Nutzung des Fahrzeugs durch max. zwei Personen idealerweise ein Kleinstwagen beschafft werden. Ist mehr Komfort und/oder Stauraum nötig, sollte genau abgewogen werden, welches Segment den Umweltansprüchen und der Vorbildfunktion der Institution entspricht.
A22: Fahrzeugsegment | B22: Anzahl_max Personen | C22: 1 bis 2 | D22: Nicht relevant | E22: Nicht relevant | F22: Transport Van | G22: Nie | H22: Leitungsebene | I22: Nein | J22: Nicht relevant | K22: Nicht relevant | L22: Strecken über 150 km | M22: Häufig, Meistens | N22: =E_F4 -> Aus Umweltsicht sollte bei einer Nutzung des Fahrzeugs durch max. zwei Personen idealerweise ein Kleinstwagen beschafft werden. Ist (gerade bei vielen längeren Strecken) mehr Komfort und/oder Stauraum nötig, sollte genau abgewogen werden, welches Segment den Umweltansprüchen und der Vorbildfunktion der Institution entspricht.
A23: Fahrzeugsegment | B23: Anzahl_max Personen | C23: 3 bis 4 | D23: Alle Sitzplätze benötigt | E23: Selten | F23: Transport Van | G23: Nie | H23: Leitungsebene | I23: Nein | J23: Nicht relevant | K23: Nicht relevant | L23: Strecken über 150 km | M23: Selten | N23: =E_F5 -> Werden nur selten mehr als zwei Sitzplätze benötigt, sollte aus Umweltsicht bevorzugt ein Kleinwagen beschafft werden. Ist mehr Komfort und/oder Stauraum nötig, sollte genau abgewogen werden, welches Segment den Umweltansprüchen und der Vorbildfunktion der Institution entspricht.
A24: Fahrzeugsegment | B24: Anzahl_max Personen | C24: 3 bis 4 | D24: Alle Sitzplätze benötigt | E24: Selten | F24: Transport Van | G24: Nie | H24: Leitungsebene | I24: Nein | J24: Nicht relevant | K24: Nicht relevant | L24: Strecken über 150 km | M24: Häufig, Meistens | N24: =E_F6 -> Werden nur selten mehr als zwei Sitzplätze benötigt, sollte aus Umweltsicht bevorzugt ein Kleinwagen beschafft werden. Ist (gerade bei vielen längeren Strecken) mehr Komfort und/oder Stauraum nötig, sollte genau abgewogen werden, welches Segment den Umweltansprüchen und der Vorbildfunktion der Institution entspricht.
A25: Fahrzeugsegment | B25: Anzahl_max Personen | C25: 3 bis 4 | D25: Alle Sitzplätze benötigt | E25: Häufig | F25: Transport Van | G25: Nie | H25: Leitungsebene | I25: Nein | J25: Nicht relevant | K25: Nicht relevant | L25: Nicht relevant | M25: Nicht relevant | N25: =E_F7 -> Werden häufig mehr als zwei Sitzplätze benötigt, sollte aus Umweltsicht bevorzugt ein Fahrzeug der Kompaktklasse beschafft werden. Ist mehr Komfort und/oder Stauraum nötig, sollte genau abgewogen werden, welches Segment den Umweltansprüchen und der Vorbildfunktion der Institution entspricht.
A26: Fahrzeugsegment | B26: Anzahl_max Personen | C26: 3 bis 4 | D26: Alle Sitzplätze benötigt | E26: Meistens | F26: Transport Van | G26: Nie | H26: Leitungsebene | I26: Nein | J26: Nicht relevant | K26: Nicht relevant | L26: Nicht relevant | M26: Nicht relevant | N26: =E_F8 -> Auch wenn meistens bis zu vier Personen in dem Auto fahren, sollte aus Umweltsicht bevorzugt ein Fahrzeug der Kompaktklasse beschafft werden. Bereits in diesem Fahrzeugsegment gibt es viele Modelle mit ausreichend Platz für große Erwachsene auf der Rückbank. Ist mehr Komfort und/oder Stauraum nötig, sollte genau abgewogen werden, welches Segment den Umweltansprüchen und der Vorbildfunktion der Institution entspricht.
A27: Fahrzeugsegment | B27: Anzahl_max Personen | C27: 5 | D27: Alle Sitzplätze benötigt | E27: Selten | F27: Transport Van | G27: Nie | H27: Leitungsebene | I27: Nein | J27: Nicht relevant | K27: Nicht relevant | L27: Nicht relevant | M27: Nicht relevant | N27: =E_F9 -> Wenn selten alle fünf Sitzplätze benötigt werden, sollte aus Umweltsicht bevorzugt ein Fahrzeug der Kompaktklasse beschafft werden. Bereits in diesem Fahrzeugsegment gibt es viele Modelle mit ausreichend Platz für große Erwachsene auf der Rückbank. Ist mehr Komfort und/oder Stauraum nötig, sollte genau abgewogen werden, welches Segment den Umweltansprüchen und der Vorbildfunktion der Institution entspricht.
A28: Fahrzeugsegment | B28: Anzahl_max Personen | C28: 5 | D28: Alle Sitzplätze benötigt | E28: Häufig, Meistens | F28: Transport Van | G28: Nie | H28: Leitungsebene | I28: Nein | J28: Nicht relevant | K28: Nicht relevant | L28: Nicht relevant | M28: Nicht relevant | N28: =E_F10 -> Werden oft alle fünf Sitzplätze benötigt, ist ein Fahrzeug der Mittelklasse zu empfehlen.
A29: Fahrzeugsegment | B29: Anzahl_max Personen | C29: 6 bis 7 | D29: Alle Sitzplätze benötigt | E29: Selten | F29: Transport Van | G29: Nie | H29: Nicht relevant | I29: Nicht relevant | J29: Fuhrpark | K29: Ja | L29: Nicht relevant | M29: Nicht relevant | N29: =E_F11 -> Im betrachteten Beschaffungsfall sollte bei bis zu vier Personen aus Umweltsicht bevorzugt ein Fahrzeug der Kompaktklasse beschafft werden. Bereits in diesem Fahrzeugsegment gibt es viele Modelle mit ausreichend Platz für große Erwachsene auf der Rückbank. Werden oft fünf Sitzplätze oder mehr Komfort/Stauraum benötigt, ist ein Fahrzeug der Mittelklasse zu empfehlen. Für die Ausnahmefälle, in denen über fünf Sitzplätze benötigt werden, kann ein Hochdachkombi (falls verfügbar) aus dem Fuhrpark verwendet oder sonst gemietet werden.
A30: Fahrzeugsegment | B30: Anzahl_max Personen | C30: 6 bis 7 | D30: Alle Sitzplätze benötigt | E30: Selten | F30: Transport Van | G30: Nie | H30: Nicht relevant | I30: Nicht relevant | J30: Fuhrpark | K30: Nein | L30: Nicht relevant | M30: Nicht relevant | N30: =E_F12 -> Im betrachteten Beschaffungsfall sollte bei bis zu vier Personen aus Umweltsicht bevorzugt ein Fahrzeug der Kompaktklasse beschafft werden. Bereits in diesem Fahrzeugsegment gibt es viele Modelle mit ausreichend Platz für große Erwachsene auf der Rückbank. Werden oft fünf Sitzplätze oder mehr Komfort/Stauraum benötigt, ist ein Fahrzeug der Mittelklasse zu empfehlen. Für die Ausnahmefälle, in denen über fünf Sitzplätze benötigt werden, kann ein Hochdachkombi gemietet werden.
A31: Fahrzeugsegment | B31: Anzahl_max Personen | C31: 6 bis 7 | D31: Alle Sitzplätze benötigt | E31: Selten | F31: Transport Van | G31: Regelmäßig | H31: Nicht relevant | I31: Nicht relevant | J31: Fuhrpark | K31: Ja | L31: Nicht relevant | M31: Nicht relevant | N31: =E_F13 -> Wenn nur selten über fünf Sitzplätze benötigt werden, kann für diese Ausnahmefälle ein Hochdachkombi oder Kleinbus (falls verfügbar) aus dem Fuhrpark verwendet oder sonst gemietet werden. Bei regelmäßigen aufwändigen Transportanforderungen ist allerdings ohnehin ein Van oder ein Fahrzeug der Rubrik Utilities (Hochdachkombis, Kleinbusse und Pick-ups, die als Pkw zugelassen sind) notwendig. Bei der Wahl der Fahrzeugart ist also abzuwägen, ob der Personentransport (-> Hochdachkombi, Kleinbus) oder der Transport von Gegenständen (-> Van, Hochdachkombi, Pick-up) überwiegt.
A32: Fahrzeugsegment | B32: Anzahl_max Personen | C32: 6 bis 7 | D32: Alle Sitzplätze benötigt | E32: Selten | F32: Transport Van | G32: Regelmäßig | H32: Nicht relevant | I32: Nicht relevant | J32: Fuhrpark | K32: Nein | L32: Nicht relevant | M32: Nicht relevant | N32: =E_F14 -> Wenn nur selten über fünf Sitzplätze benötigt werden, kann für diese Ausnahmefälle ein Hochdachkombi oder Kleinbus gemietet werden. Bei regelmäßigen aufwändigen Transportanforderungen ist allerdings ohnehin ein Van oder ein Fahrzeug der Rubrik Utilities (Hochdachkombis, Kleinbusse und Pick-ups, die als Pkw zugelassen sind) notwendig. Bei der Wahl der Fahrzeugart ist also abzuwägen, ob der Personentransport (-> Hochdachkombi, Kleinbus) oder der Transport von Gegenständen (-> Van, Hochdachkombi, Pick-up) überwiegt.
A33: Fahrzeugsegment | B33: Anzahl_max Personen | C33: 6 bis 7 | D33: Alle Sitzplätze benötigt | E33: Häufig, Meistens | F33: Nicht relevant | G33: Nicht relevant | H33: Nicht relevant | I33: Nicht relevant | J33: Nicht relevant | K33: Nicht relevant | L33: Nicht relevant | M33: Nicht relevant | N33: =E_F15 -> Werden oft mind. sechs Sitzplätze benötigt, sollte ein Hochdachkombi beschafft werden. Diese Fahrzeugart hat unter den 7-Sitzern in der Regel das beste Preis-Leistungs-Verhältnis und fährt sparsamer als z.B. ein SUV.
A34: Fahrzeugsegment | B34: Anzahl_max Personen | C34: 8 bis 9 | D34: Alle Sitzplätze benötigt | E34: Selten | F34: Transport Van | G34: Nie | H34: Nicht relevant | I34: Nicht relevant | J34: Fuhrpark | K34: Ja | L34: Nicht relevant | M34: Nicht relevant | N34: =E_F16 -> Im betrachteten Beschaffungsfall sollte bei bis zu vier Personen aus Umweltsicht bevorzugt ein Fahrzeug der Kompaktklasse beschafft werden. Bereits in diesem Fahrzeugsegment gibt es viele Modelle mit ausreichend Platz für große Erwachsene auf der Rückbank. Werden oft fünf Sitzplätze oder mehr Komfort/Stauraum benötigt, ist ein Fahrzeug der Mittelklasse zu empfehlen. Für die Ausnahmefälle, in denen über sieben Sitzplätze benötigt werden, kann ein Kleinbus (falls verfügbar) aus dem Fuhrpark verwendet oder sonst gemietet werden.
A35: Fahrzeugsegment | B35: Anzahl_max Personen | C35: 8 bis 9 | D35: Alle Sitzplätze benötigt | E35: Selten | F35: Transport Van | G35: Nie | H35: Nicht relevant | I35: Nicht relevant | J35: Fuhrpark | K35: Nein | L35: Nicht relevant | M35: Nicht relevant | N35: =E_F17 -> Im betrachteten Beschaffungsfall sollte bei bis zu vier Personen aus Umweltsicht bevorzugt ein Fahrzeug der Kompaktklasse beschafft werden. Bereits in diesem Fahrzeugsegment gibt es viele Modelle mit ausreichend Platz für große Erwachsene auf der Rückbank. Werden oft fünf Sitzplätze oder mehr Komfort/Stauraum benötigt, ist ein Fahrzeug der Mittelklasse zu empfehlen. Für die Ausnahmefälle, in denen über sieben Sitzplätze benötigt werden, kann ein Kleinbus gemietet werden.
A36: Fahrzeugsegment | B36: Anzahl_max Personen | C36: 8 bis 9 | D36: Alle Sitzplätze benötigt | E36: Selten | F36: Transport Van | G36: Regelmäßig | H36: Nicht relevant | I36: Nicht relevant | J36: Fuhrpark | K36: Ja | L36: Nicht relevant | M36: Nicht relevant | N36: =E_F18 -> Wenn nur selten über sieben Sitzplätze benötigt werden, kann für diese Ausnahmefälle ein Kleinbus (falls verfügbar) aus dem Fuhrpark verwendet oder sonst gemietet werden. Bei regelmäßigen aufwändigen Transportanforderungen ist allerdings ohnehin ein Van oder ein Fahrzeug der Rubrik Utilities (Hochdachkombis, Kleinbusse und Pick-ups, die als Pkw zugelassen sind) notwendig. Bei der Wahl der Fahrzeugart ist also abzuwägen, ob der Personentransport (-> Hochdachkombi, Kleinbus) oder der Transport von Gegenständen (-> Van, Hochdachkombi, Pick-up) überwiegt.
A37: Fahrzeugsegment | B37: Anzahl_max Personen | C37: 8 bis 9 | D37: Alle Sitzplätze benötigt | E37: Selten | F37: Transport Van | G37: Regelmäßig | H37: Nicht relevant | I37: Nicht relevant | J37: Fuhrpark | K37: Nein | L37: Nicht relevant | M37: Nicht relevant | N37: =E_F19 -> Wenn nur selten über sieben Sitzplätze benötigt werden, kann für diese Ausnahmefälle ein Kleinbus gemietet werden. Bei regelmäßigen aufwändigen Transportanforderungen ist allerdings ohnehin ein Van oder ein Fahrzeug der Rubrik Utilities (Hochdachkombis, Kleinbusse und Pick-ups, die als Pkw zugelassen sind) notwendig. Bei der Wahl der Fahrzeugart ist also abzuwägen, ob der Personentransport (-> Hochdachkombi, Kleinbus) oder der Transport von Gegenständen (-> Van, Hochdachkombi, Pick-up) überwiegt.
A38: Fahrzeugsegment | B38: Anzahl_max Personen | C38: 8 bis 9 | D38: Alle Sitzplätze benötigt | E38: Häufig, Meistens | F38: Nicht relevant | G38: Nicht relevant | H38: Nicht relevant | I38: Nicht relevant | J38: Nicht relevant | K38: Nicht relevant | L38: Nicht relevant | M38: Nicht relevant | N38: =E_F20 -> Werden oft mind. acht Sitzplätze benötigt, sollte ein Kleinbus beschafft werden.
A39: Fahrzeugsegment | B39: Anzahl_max Personen | C39: Kleiner 6 | D39: Nicht relevant | E39: Nicht relevant | F39: Transport Van | G39: Gelegentlich | H39: Leitungsebene | I39: Ja | J39: Fuhrpark | K39: Ja | L39: Nicht relevant | M39: Nicht relevant | N39: =E_F21 -> Für die Leitungsebene besteht ggf. Anspruch auf ein Fahrzeug aus einem höheren Fahrzeugsegment. Trotzdem sollte aus Umweltgründen abgewogen werden, ob ein kleineres Fahrzeug geeignet ist und die Leitungsebene freiwillig auf diesen Anspruch verzichtet. Wenn nur gelegentlich aufwändige Transportanforderungen bestehen, die einen Van/ein Fahrzeug aus der Rubrik Utilities nötig machen, kann für diese Ausnahmefälle ein entsprechendes Fahrzeug (falls verfügbar) aus dem Fuhrpark verwendet oder sonst gemietet werden.
A40: Fahrzeugsegment | B40: Anzahl_max Personen | C40: Kleiner 6 | D40: Nicht relevant | E40: Nicht relevant | F40: Transport Van | G40: Gelegentlich | H40: Leitungsebene | I40: Ja | J40: Fuhrpark | K40: Nein | L40: Nicht relevant | M40: Nicht relevant | N40: =E_F22 -> Für die Leitungsebene besteht ggf. Anspruch auf ein Fahrzeug aus einem höheren Fahrzeugsegment. Trotzdem sollte aus Umweltgründen abgewogen werden, ob ein kleineres Fahrzeug geeignet ist und die Leitungsebene freiwillig auf diesen Anspruch verzichtet. Wenn nur gelegentlich aufwändige Transportanforderungen bestehen, die einen Van/ein Fahrzeug aus der Rubrik Utilities nötig machen, kann für diese Ausnahmefälle ein entsprechendes Fahrzeug gemietet werden.
A41: Fahrzeugsegment | B41: Anzahl_max Personen | C41: 1 bis 2 | D41: Nicht relevant | E41: Nicht relevant | F41: Transport Van | G41: Gelegentlich | H41: Leitungsebene | I41: Nein | J41: Fuhrpark | K41: Ja | L41: Strecken über 150 km | M41: Selten | N41: =E_F23 -> Aus Umweltsicht sollte bei einer Nutzung des Fahrzeugs durch max. zwei Personen idealerweise ein Kleinstwagen beschafft werden. Ist mehr Komfort und/oder Stauraum nötig, sollte genau abgewogen werden, welches Segment den Umweltansprüchen und der Vorbildfunktion der Institution entspricht. Wenn nur gelegentlich aufwändige Transportanforderungen bestehen, die einen Van/ein Fahrzeug aus der Rubrik Utilities nötig machen, kann für diese Ausnahmefälle ein entsprechendes Fahrzeug (falls verfügbar) aus dem Fuhrpark verwendet oder sonst gemietet werden.
...

Sheet Fragen_Prototyp_Einzelfahrzeug
B2: Fragen - Prototyp Einzelfahrzeug
B4: Einzelfahrzeug beschaffen
A6: ID | B6: Antriebsart
B8: In diesem Abschnitt geht es darum, wie das Fahrprofil aussieht und ob Lademöglichkeiten bestehen. Diese Fragestellungen sind relevant, um ein möglichst umweltverträgliches Fahrzeug bzgl. der Antriebsart zu wählen.
B10: Welche Distanz soll mit dem zu beschaffenden Pkw im Normalfall pro Tag zurückgelegt werden? | E10: Wie oft werden übers Jahr Tagesstrecken über 150 km zurückgelegt?
A11: F_R1 | B11: 200 | C11: km/Tag | D11: F_S1 | E11: Häufig | F11: <- Bitte auswählen
B13: Wie häufig werden die Tagesstrecken im Normalfall von Standzeiten (≈ mind. 30 min) unterbrochen?
A14: F_SZ1 | B14: Regelmäßig | C14: <- Bitte auswählen
B16: Sind Ladesäulen am Standort bzw. im umliegenden öffentlichen Raum oder am Wohnort der Nutzenden verfügbar?
A17: F_L1 | B17: Ja | C17: <- Bitte auswählen
B19: Sind Ladesäulen auf den zu befahrenden Strecken verfügbar?
A20: F_L2 | B20: Ja | C20: <- Bitte auswählen
B22: Ist das zu beschaffende Fahrzeug Teil eines Fuhrparks?
A23: F_F1 | B23: Nein | C23: <- Bitte auswählen
B25: Empfehlung zur Antriebsart:
A26: E_A0 | B26: =_xlfn.IFS(F_L1=A_JN2, E_A1, AND(F_R1<=A_R1, F_S1=A_S1, F_F1=A_JN1), E_A2, AND(F_R1<=A_R1, F_S1=A_S1, F_F1=A_JN2), E_A3, AND(F_R1<=A_R1, F_S1=A_S2, F_F1=A_JN1), E_A4, AND(F_R1<=A_R1, F_S1=A_S2, F_F1=A_JN2), E_A5, AND(F_R1<=A_R1, F_S1=A_S3), E_A6, AND(F_R1>A_R1, F_S1=A_S1), E_A6, AND(F_R1>A_R1, F_SZ1=A_SV1), E_A9, AND(F_R1>A_R1, F_S1=A_S2, F_SZ1=A_SV2, F_L2=A_JN1), E_A8, AND(F_R1>A_R1, F_SZ1=A_SV2, F_L2=A_JN2), E_A10, AND(F_R1>A_R1, F_S1=A_S2, F_SZ1=A_SV3, F_L2=A_JN1), E_A7, AND(F_R1>A_R1, F_S1=A_S2, F_SZ1=A_SV3, F_L2=A_JN2), E_A11, AND(F_R1>A_R1, F_S1=A_S3, F_SZ1=A_SV2, F_L2=A_JN1), E_A8, AND(F_R1>A_R1, F_S1=A_S3, F_SZ1=A_SV3, F_L2=A_JN1), E_A8, AND(F_R1>A_R1, F_S1=A_S3, F_SZ1=A_SV3, F_L2=A_JN2), E_A11, TRUE(), " ") -> Erlaubt die Terminplanung Fahrtunterbrechungen von mind. 20-40 min an Standorten mit (Schnell-)Lademöglichkeiten, ist ein E-Auto (BEV - rein batteriebetrieben) trotz häufiger längerer Strecken bevorzugt zu beschaffen.
B28: Fahrzeugsegment
B30: In diesem Abschnitt geht es darum, welche Aufgabenstellung erfüllt werden soll, um ein möglichst umweltverträgliches Fahrzeug bzgl. des Fahrzeugsegments zu wählen. Die Abfragen bezüglich der Antriebsart gehen teilweise ebenfalls mit ein in die Empfehlung zum Fahrzeugsegment.
B32: Wie viele Personen fahren maximal zusammen in dem Pkw? | E32: Wie häufig werden alle Sitzplätze benötigt?
A33: F_P1 | B33: 3 | C33: Person(en) | D33: F_SP1 | E33: Häufig | F33: <- Bitte auswählen
A35: i | B35: Wie häufig bestehen aufwändige Anforderungen an den Transport von Gegenständen (z.B. viele/große/schwere Gegenstände), sodass Vans/Utilities notwendig sind?
A36: F_T1 | B36: Gelegentlich | C36: <- Bitte auswählen
B38: Wird der Pkw für die Leitungsebene beschafft?
A39: F_LE1 | B39: Nein | C39: <- Bitte auswählen
B41: Empfehlung zum Fahrzeugsegment:
A42: E_F0 | B42: =_xlfn.IFS(AND(F_P1<6, F_T1=A_T3), E_F1, AND(F_P1<6, OR(F_T1=A_T1, ISBLANK(F_T1)), F_LE1=A_JN1), E_F2, AND(F_P1>=1, F_P1<=2, F_T1=A_T1, F_LE1=A_JN2, F_S1=A_S1), E_F3, AND(F_P1>=1, F_P1<=2, F_T1=A_T1, F_LE1=A_JN2, OR(F_S1=A_S2, F_S1=A_S3)), E_F4, AND(F_P1>=3, F_P1<=4, F_SP1=A_SP1, F_T1=A_T1, F_LE1=A_JN2, F_S1=A_S1), E_F5, AND(F_P1>=3, F_P1<=4, F_SP1=A_SP1, F_T1=A_T1, F_LE1=A_JN2, OR(F_S1=A_S2, F_S1=A_S3)), E_F6, AND(F_P1>=3, F_P1<=4, F_SP1=A_SP2, F_T1=A_T1, F_LE1=A_JN2), E_F7, AND(F_P1>=3, F_P1<=4, F_SP1=A_SP3, F_T1=A_T1, F_LE1=A_JN2), E_F8, AND(F_P1=5, F_SP1=A_SP1, F_T1=A_T1, F_LE1=A_JN2), E_F9, AND(F_P1=5, OR(F_SP1=A_SP2, F_SP1=A_SP3), F_T1=A_T1, F_LE1=A_JN2), E_F10, AND(F_P1>=6, F_P1<=7, F_SP1=A_SP1, F_T1=A_T1, F_F1=A_JN1), E_F11, AND(F_P1>=6, F_P1<=7, F_SP1=A_SP1, F_T1=A_T1, F_F1=A_JN2), E_F12, AND(F_P1>=6, F_P1<=7, F_SP1=A_SP1, F_T1=A_T3, F_F1=A_JN1), E_F13, AND(F_P1>=6, F_P1<=7, F_SP1=A_SP1, F_T1=A_T3, F_F1=A_JN2), E_F14, AND(F_P1>=6, F_P1<=7, OR(F_SP1=A_SP2, F_SP1=A_SP3)), E_F15, AND(F_P1>=8, F_P1<=9, F_SP1=A_SP1, F_T1=A_T1, F_F1=A_JN1), E_F16, AND(F_P1>=8, F_P1<=9, F_SP1=A_SP1, F_T1=A_T1, F_F1=A_JN2), E_F17, AND(F_P1>=8, F_P1<=9, F_SP1=A_SP1, F_T1=A_T3, F_F1=A_JN1), E_F18, AND(F_P1>=8, F_P1<=9, F_SP1=A_SP1, F_T1=A_T3, F_F1=A_JN2), E_F19, AND(F_P1>=8, F_P1<=9, OR(F_SP1=A_SP2, F_SP1=A_SP3)), E_F20, AND(F_P1<6, F_T1=A_T2, F_LE1=A_JN1, F_F1=A_JN1), E_F21, AND(F_P1<6, F_T1=A_T2, F_LE1=A_JN1, F_F1=A_JN2), E_F22, AND(F_P1>=1, F_P1<=2, F_T1=A_T2, F_LE1=A_JN2, F_F1=A_JN1, F_S1=A_S1), E_F23, AND(F_P1>=1, F_P1<=2, F_T1=A_T2, F_LE1=A_JN2, F_F1=A_JN2, F_S1=A_S1), E_F24, AND(F_P1>=1, F_P1<=2, F_T1=A_T2, F_LE1=A_JN2, F_F1=A_JN1, OR(F_S1=A_S2, F_S1=A_S3)), E_F25, AND(F_P1>=1, F_P1<=2, F_T1=A_T2, F_LE1=A_JN2, F_F1=A_JN2, OR(F_S1=A_S2, F_S1=A_S3)), E_F26, AND(F_P1>=3, F_P1<=4, F_SP1=A_SP1, F_T1=A_T2, F_LE1=A_JN2, F_F1=A_JN1, F_S1=A_S1), E_F27, AND(F_P1>=3, F_P1<=4, F_SP1=A_SP1, F_T1=A_T2, F_LE1=A_JN2, F_F1=A_JN2, F_S1=A_S1), E_F28, AND(F_P1>=3, F_P1<=4, F_SP1=A_SP1, F_T1=A_T2, F_LE1=A_JN2, F_F1=A_JN1, OR(F_S1=A_S2, F_S1=A_S3)), E_F29, AND(F_P1>=3, F_P1<=4, F_SP1=A_SP1, F_T1=A_T2, F_LE1=A_JN2, F_F1=A_JN2, OR(F_S1=A_S2, F_S1=A_S3)), E_F30, AND(F_P1>=3, F_P1<=4, F_SP1=A_SP2, F_T1=A_T2, F_LE1=A_JN2, F_F1=A_JN1), E_F31, AND(F_P1>=3, F_P1<=4, F_SP1=A_SP2, F_T1=A_T2, F_LE1=A_JN2, F_F1=A_JN2), E_F32, AND(F_P1>=3, F_P1<=4, F_SP1=A_SP3, F_T1=A_T2, F_LE1=A_JN2, F_F1=A_JN1), E_F33, AND(F_P1>=3, F_P1<=4, F_SP1=A_SP3, F_T1=A_T2, F_LE1=A_JN2, F_F1=A_JN2), E_F34, AND(F_P1=5, F_SP1=A_SP1, F_T1=A_T2, F_LE1=A_JN2, F_F1=A_JN1), E_F35, AND(F_P1=5, F_SP1=A_SP1, F_T1=A_T2, F_LE1=A_JN2, F_F1=A_JN2), E_F36, AND(F_P1=5, OR(F_SP1=A_SP2, F_SP1=A_SP3), F_T1=A_T2, F_LE1=A_JN2, F_F1=A_JN1), E_F37, AND(F_P1=5, OR(F_SP1=A_SP2, F_SP1=A_SP3), F_T1=A_T2, F_LE1=A_JN2, F_F1=A_JN2), E_F38, AND(F_P1>=6, F_P1<=7, F_SP1=A_SP1, F_T1=A_T2, F_F1=A_JN1), E_F39, AND(F_P1>=6, F_P1<=7, F_SP1=A_SP1, F_T1=A_T2, F_F1=A_JN2), E_F40, AND(F_P1>=8, F_P1<=9, F_SP1=A_SP1, F_T1=A_T2, F_F1=A_JN1), E_F41, AND(F_P1>=8, F_P1<=9, F_SP1=A_SP1, F_T1=A_T2, F_F1=A_JN2), E_F42, TRUE(), " ") -> Werden häufig mehr als zwei Sitzplätze benötigt, sollte aus Umweltsicht bevorzugt ein Fahrzeug der Kompaktklasse beschafft werden. Ist mehr Komfort und/oder Stauraum nötig, sollte genau abgewogen werden, welches Segment den Umweltansprüchen und der Vorbildfunktion der Institution entspricht. Wenn nur gelegentlich aufwändige Transportanforderungen bestehen, die einen Van/ein Fahrzeug aus der Rubrik Utilities nötig machen, kann für diese Ausnahmefälle ein entsprechendes Fahrzeug gemietet werden.

Sheet Fragen_Prototyp_Flotte
B2: Fragen - Prototyp Flotte
B4: Mehrere Fahrzeuge/Flotte beschaffen
B6: Verkehrsmittel
B8: Der folgende Teil beschäftigt sich mit den Fragen, wie der Mobilitätsbedarf gedeckt werden kann und ob alle Pkw-Beschaffungen tatsächlich notwendig sind. Solche Vorüberlegungen bezüglich der Bedarfsermittlung sind z.B. im Land Berlin verpflichtend zu dokumentieren. Die Fragen sollten jeweils für einen Standort bzw. für Zusammenschlüsse von Standorten/Institutionen, die Fahrzeuge untereinander austauschen/gemeinsam nutzen, beantwortet werden.
B10: Wie viele Pkw sollen beschafft werden?
A11: F_B1 | B11: 12 | D11: Pkw
B13: Wie viele Fahrzeuge aus einem vorhandenen Fuhrpark werden durch diese Beschaffung ersetzt?
A14: F_E1 | B14: 10 | D14: Pkw
B16: =IF(OR(ISBLANK(F_B1), ISBLANK(F_E1)), "", "Mit dieser Beschaffung") -> Mit dieser Beschaffung | E16: =_xlfn.IFS(OR(ISBLANK(F_B1), ISBLANK(F_E1)), "", F_E1>=F_B1, H_F1, TRUE(), H_F2) -> vergrößern | F16: =IF(OR(ISBLANK(F_B1), ISBLANK(F_E1)), "", "Sie Ihren Fuhrpark um") -> Sie Ihren Fuhrpark um | G16: =IF(OR(ISBLANK(F_B1), ISBLANK(F_E1)), "", ABS((F_E1-F_B1)/F_E1)) -> 0.2 | H16: =IF(OR(ISBLANK(F_B1), ISBLANK(F_E1)), "", ".") -> .
B17: =_xlfn.IFS(OR(ISBLANK(F_B1), ISBLANK(F_E1)), "", F_E1>F_B1, H_F5, F_E1<F_B1, H_F3, TRUE(), H_F4) -> Bitte überlegen Sie mithilfe der nächsten Frage, ob der Fuhrpark verkleinert statt vergrößert werden kann. Damit würden Sie einen entscheidenden Beitrag zur umweltverträglichen Beschaffung leisten.
B19: Wie oft können die geplanten Strecken/Einsatzzwecke mit folgenden Verkehrsmitteln erledigt werden?
B20: Bedenken Sie bei der Beantwortung der Frage, dass die abgefragten Optionen auch kombiniert werden können (z.B. Fahrrad und ÖPNV). Eine Analyse der bisherigen Nutzung des Fuhrparks kann bei der Beantwortung der Frage helfen.
A22: F_BF1 | B22: Ab und zu | D22: ÖPNV bzw. Bahn/Fernbus
A24: F_FL1 | B24: Fast nie | D24: (Elektro-)Fahrrad/Lastenrad
A26: F_CP1 | B26: Regelmäßig | D26: Gemeinsame Nutzung vorhandener Pkw (Car-Pooling)
A28: F_CS1 | B28: Ab und zu | D28: Nutzung von Pkw eines Car-Sharing-Anbieters
A30: F_M1 | B30: Ab und zu | D30: Mietwagen für einzelne Strecken
B32: Folgende Verkehrsmittel/Nutzungsarten kommen neben einer Pkw-Beschaffung zur Deckung des betrachteten Mobilitätsbedarfs in Frage:
B55: Die folgende Frage bezieht sich auf Ihre Einschätzung, nachdem Sie die Vorüberlegungen zur Flottenbeschaffung durchgegangen sind:
B56: Auf wie viele der ursprünglich zu beschaffenden Pkw kann durch eine optimale Ausnutzung des Fuhrparks und die Kombination mit anderen Verkehrsmitteln verzichtet werden?
A57: F_E2 | B57: 10 | D57: Pkw
B59: =_xlfn.IFS(ISBLANK(F_E2), "", AND(F_E2=0, F_E1<=F_B1), H_V3, AND(F_E2=0, F_E1>F_B1), H_V2, AND(F_E2>0, F_E1<F_B1, F_E2<(F_B1-F_E1)), H_V4, AND(F_E2>0, F_E1<F_B1, F_E2=(F_B1-F_E1)), H_V5, TRUE(), H_V1) -> Mit dem Verzicht auf zu beschaffende Pkw leisten Sie einen entscheidenden Beitrag zur umweltverträglichen Beschaffung.
B61: Für die verbleibenden Pkw nutzen Sie bitte den Tooleinstieg (B) "Einzelfahrzeug beschaffen". Sollte der Einsatzzweck für alle zu beschaffenden Pkw gleich sein, können die resultierenden Empfehlungen für die komplette Ausschreibung übernommen werden. Bei sich deutlich unterscheidenden Einsatzzwecken sollten die Abfragen pro Einsatzzweck bearbeitet werden.

Sheet Darstellung_Flotte
B2: Semiquantitatives Diagramm: Verkehrsmittel zur Deckung des Mobilitätsbedarfs
B5: Umformung der Anteile: | C5: Semiquantitativer Anteil | D5: Zahlenwert für die Darstellung
C6: =Auswahllisten!B16 -> Fast nie | D6: 2
C7: =Auswahllisten!B17 -> Ab und zu | D7: 4
C8: =Auswahllisten!B18 -> Regelmäßig | D8: 6
B10: Verkehrsmittel | C10: Semiquantitativer Anteil | D10: Substitutionsmöglichkeit | E10: Umweltvorteil
B11: Mietwagen | C11: =Fragen_Prototyp_Flotte!$B$30 -> Ab und zu | D11: =VLOOKUP(C11,$C$6:$D$8,2,FALSE()) -> 4 | E11: 1
B12: Car-Sharing | C12: =Fragen_Prototyp_Flotte!$B$28 -> Ab und zu | D12: =VLOOKUP(C12,$C$6:$D$8,2,FALSE()) -> 4 | E12: 1
B13: Car-Pooling | C13: =Fragen_Prototyp_Flotte!$B$26 -> Regelmäßig | D13: =VLOOKUP(C13,$C$6:$D$8,2,FALSE()) -> 6 | E13: 1
B14: Fahrrad | C14: =Fragen_Prototyp_Flotte!$B$24 -> Fast nie | D14: =VLOOKUP(C14,$C$6:$D$8,2,FALSE()) -> 2 | E14: 2
B15: ÖPNV/Bahn/Fernbus | C15: =Fragen_Prototyp_Flotte!$B$22 -> Ab und zu | D15: =VLOOKUP(C15,$C$6:$D$8,2,FALSE()) -> 4 | E15: 2

Sheet Auswahllisten
A1: Auswahllisten für Drop-Down-Menüs
A3: ID | B3: Reichweiten-Grenze für BEV [km]
A4: A_R1 | B4: 150
B6: Ja/Nein-Fragen
A7: A_JN1 | B7: Ja
A8: A_JN2 | B8: Nein
B10: Wie oft werden übers Jahr Strecken über 150 km zurückgelegt?
A11: A_S1 | B11: Selten
A12: A_S2 | B12: Häufig
A13: A_S3 | B13: Meistens
B15: Standzeiten / Verkehrsmittel (für Prototyp_Flotte)
A16: A_SV1 | B16: Fast nie
A17: A_SV2 | B17: Ab und zu
A18: A_SV3 | B18: Regelmäßig
B20: Wie häufig werden alle Sitzplätze benötigt?
A21: A_SP1 | B21: Selten
A22: A_SP2 | B22: Häufig
A23: A_SP3 | B23: Meistens
B25: Transportanforderungen
A26: A_T1 | B26: Nie
A27: A_T2 | B27: Gelegentlich
A28: A_T3 | B28: Regelmäßig

Sheet Empfehlungslisten
A1: Empfehlungslisten für Antwortkombinationen
A3: ID | B3: Empfehlung zur Antriebsart | C3: Anmerkung für Changelog
A4: E_A1 | B4: Wenn weder am Arbeitsplatz (bzw. im umliegenden öffentlichen Raum) noch am Wohnort der Nutzenden eine für mehrere Stunden nutzbare Lademöglichkeit besteht, ist die Beschaffung eines E-Autos nicht sinnvoll. In diesem Fall sollte ein möglichst sparsamer Verbrenner beschafft werden. Der Auf- und Ausbau von Ladeinfrastruktur ist jedoch unbedingt zu empfehlen, um in Zukunft E-Autos beschaffen zu können. | C4: siehe rote Markierungen
A5: E_A2 | B5: Ein E-Auto (BEV - rein batteriebetrieben) ist bevorzugt zu beschaffen, da Reichweiten bis 150 km mit den heute üblichen E-Pkw in der Regel erzielbar sind, sodass das Laden über Nacht ausreicht. Für einzelne Tagesstrecken über 150 km sollte idealerweise die Bahn oder der Fernbus genutzt werden. Bei schlechter Anbindung an den öffentlichen Verkehr oder mit viel Gepäck/Transportgut kann das E-Auto auch auf längeren Tagesstrecken zum Einsatz kommen, sofern unterwegs oder am Zielort (Schnell-)Lademöglichkeiten genutzt werden können. Besteht die Möglichkeit zum Laden nicht, kann in diesen Ausnahmefällen (falls vefügbar) ein anderes Fahrzeug mit entsprechender Reichweite aus dem Fuhrpark oder sonst ein Mietwagen genutzt werden. | C5: siehe rote Markierungen
A6: E_A3 | B6: Ein E-Auto (BEV - rein batteriebetrieben) ist bevorzugt zu beschaffen, da Reichweiten bis 150 km mit den heute üblichen E-Pkw in der Regel erzielbar sind, sodass das Laden über Nacht ausreicht. Für einzelne Tagesstrecken über 150 km sollte idealerweise die Bahn oder der Fernbus genutzt werden. Bei schlechter Anbindung an den öffentlichen Verkehr oder mit viel Gepäck/Transportgut kann das E-Auto auch auf längeren Tagesstrecken zum Einsatz kommen, sofern unterwegs oder am Zielort (Schnell-)Lademöglichkeiten genutzt werden können. Besteht die Möglichkeit zum Laden nicht, kann in diesen Ausnahmefällen ein Mietwagen genutzt werden. | C6: siehe rote Markierungen
A7: E_A4 | B7: Ein E-Auto (BEV - rein batteriebetrieben) ist bevorzugt zu beschaffen, da Reichweiten bis 150 km mit den heute üblichen E-Pkw in der Regel erzielbar sind, sodass das Laden über Nacht ausreicht. Wenn häufiger auch mal Tagesstrecken über 150 km zurückgelegt werden sollen und unterwegs oder am Zielort (Schnell-) Lademöglichkeiten genutzt werden können, kann das E-Auto auch auf diesen Strecken zum Einsatz kommen. Besteht die Möglichkeit zum Laden nicht, sollte geprüft werden, ob für die Einsatztage mit längeren Strecken regelmäßig ein anderes Fahrzeug mit entsprechender Reichweite aus dem Fuhrpark genutzt werden kann. Dieses Fahrzeug kann auch ein E-Auto mit größerer Batterie sein, da in höheren Preissegmenten reale 300 km Reichweite gängig sind. Zudem ist zu prüfen, ob die Tagesstrecken über 150 km tatsächlich zum Großteil mit dem Pkw zurückgelegt werden müssen (aufgrund schlechter Anbindung an den öffentlichen Verkehr oder viel Gepäck/Transportgut) oder ob mit Bahn oder Fernbus gereist werden kann. | C7: siehe rote Markierungen
A8: E_A5 | B8: Ein E-Auto (BEV - rein batteriebetrieben) ist bevorzugt zu beschaffen, da Reichweiten bis 150 km mit den heute üblichen E-Pkw in der Regel erzielbar sind, sodass das Laden über Nacht ausreicht. Wenn häufiger auch mal Tagesstrecken über 150 km zurückgelegt werden sollen und unterwegs oder am Zielort (Schnell-) Lademöglichkeiten genutzt werden können, kann das E-Auto auch auf diesen Strecken zum Einsatz kommen. Zudem ist zu prüfen, ob die Tagesstrecken über 150 km tatsächlich zum Großteil mit dem Pkw zurückgelegt werden müssen (aufgrund schlechter Anbindung an den öffentlichen Verkehr oder viel Gepäck/Transportgut) oder ob mit Bahn oder Fernbus gereist werden kann. Ist dies nicht der Fall und besteht keine Möglichkeit zum Laden während längerer Strecken, kann die Beschaffung eines Plug-in-Hybrids (PHEV) sinnvoll sein. In diesem Fall sollte jedoch darauf geachtet werden, dass bei den kürzeren Strecken, die im Regelfall gefahren werden, ein elektrischer Fahranteil von über 70 % erzielt wird. Dazu muss ein regelmäßiges Laden gewährleistet sein. Zudem sind PHEVs eher in größeren Fahrzeugsegmenten verfügbar. Je nach Anwendungsfall kann ein kleiner, sparsamer Verbrenner auch aus Umweltsicht vorteilhaft ggü. einem PHEV sein. | C8: siehe rote Markierungen
A9: E_A6 | B9: Inkonsistente Eingabe: Die Aussage zur Häufigkeit längerer Strecken passt nicht mit der angegeben Streckenlänge eines repräsentativen Tages zusammen. Bitte passen Sie die Streckenlänge so an, dass sie den Fahrten im Regelfall entspricht.
A10: E_A7 | B10: Erlaubt die Terminplanung Fahrtunterbrechungen von mind. 20-40 min an Standorten mit (Schnell-)Lademöglichkeiten, ist ein E-Auto (BEV - rein batteriebetrieben) trotz häufiger längerer Strecken bevorzugt zu beschaffen. | C10: siehe rote Markierungen
A11: E_A8 | B11: Ein E-Auto (BEV - rein batteriebetrieben) mit großer Reichweite ist ggf. geeignet. In höheren Preissegmenten ist eine Reichweite von 300 km gängig. Es sollte jedoch beachtet werden, dass dem Umweltvorteil eines BEV in der Nutzung die Herstellungsemissionen einer großen Batterie gegenüberstehen. Zudem sind große Batterien vor allem in größeren Fahrzeugen verbaut. Ein kleinerer, möglichst sparsamer Verbrenner kann in diesem Anwendungsfall aus Umweltsicht (und aus Kostensicht ohnehin) also durchaus vorteilhaft sein. | C11: siehe rote Markierungen
A12: E_A9 | B12: Erlaubt die Terminplanung auf langen Strecken keine bzw. nur sehr kurze Fahrtunterbrechungen unter 30 min, ist die Beschaffung eines E-Autos nicht sinnvoll. In diesem Fall sollte ein möglichst sparsamer Verbrenner beschafft werden.
A13: E_A10 | B13: Bei vielen langen Strecken, auf denen keine Lademöglichkeit besteht, ist die Beschaffung eines E-Autos nicht sinnvoll. In diesem Fall sollte ein möglichst sparsamer Verbrenner beschafft werden.
A14: E_A11 | B14: Bei vielen langen Strecken, auf denen keine Lademöglichkeit besteht, ist die Beschaffung eines E-Autos nicht sinnvoll. In diesem Fall sollte ein möglichst sparsamer Verbrenner beschafft werden. Das Fahrprofil mit regelmäßigen längeren Fahrtunterbrechungen eignet sich an sich allerdings für E-Autos. Der weitere Ausbau der öffentlichen Ladeinfrastruktur oder die Wahl von Alternativrouten mit verfügbaren Ladesäulen kann also (in Zukunft) eine E-Auto-Beschaffung durchaus ermöglichen.
A16: ID | B16: Empfehlung zum Fahrzeugsegment | C16: Anmerkung für Changelog
A17: E_F1 | B17: Bei regelmäßigen aufwändigen Transportanforderungen ist ein Van oder ein Fahrzeug der Rubrik Utilities (Hochdachkombis, Kleinbusse und Pick-ups, die als Pkw zugelassen sind) notwendig.
A18: E_F2 | B18: Für die Leitungsebene besteht ggf. Anspruch auf ein Fahrzeug aus einem höheren Fahrzeugsegment. Trotzdem sollte aus Umweltgründen abgewogen werden, ob ein kleineres Fahrzeug geeignet ist und die Leitungsebene freiwillig auf diesen Anspruch verzichtet. | C18: "bis zur Oberen Mittelklasse" gelöscht; siehe rote Markierungen
A19: E_F3 | B19: Aus Umweltsicht sollte bei einer Nutzung des Fahrzeugs durch max. zwei Personen idealerweise ein Kleinstwagen beschafft werden. Ist mehr Komfort und/oder Stauraum nötig, sollte genau abgewogen werden, welches Segment den Umweltansprüchen und der Vorbildfunktion der Institution entspricht. | C19: siehe rote Markierungen
A20: E_F4 | B20: Aus Umweltsicht sollte bei einer Nutzung des Fahrzeugs durch max. zwei Personen idealerweise ein Kleinstwagen beschafft werden. Ist (gerade bei vielen längeren Strecken) mehr Komfort und/oder Stauraum nötig, sollte genau abgewogen werden, welches Segment den Umweltansprüchen und der Vorbildfunktion der Institution entspricht. | C20: siehe rote Markierungen
A21: E_F5 | B21: Werden nur selten mehr als zwei Sitzplätze benötigt, sollte aus Umweltsicht bevorzugt ein Kleinwagen beschafft werden. Ist mehr Komfort und/oder Stauraum nötig, sollte genau abgewogen werden, welches Segment den Umweltansprüchen und der Vorbildfunktion der Institution entspricht. | C21: siehe rote Markierungen
A22: E_F6 | B22: Werden nur selten mehr als zwei Sitzplätze benötigt, sollte aus Umweltsicht bevorzugt ein Kleinwagen beschafft werden. Ist (gerade bei vielen längeren Strecken) mehr Komfort und/oder Stauraum nötig, sollte genau abgewogen werden, welches Segment den Umweltansprüchen und der Vorbildfunktion der Institution entspricht. | C22: siehe rote Markierungen
A23: E_F7 | B23: Werden häufig mehr als zwei Sitzplätze benötigt, sollte aus Umweltsicht bevorzugt ein Fahrzeug der Kompaktklasse beschafft werden. Ist mehr Komfort und/oder Stauraum nötig, sollte genau abgewogen werden, welches Segment den Umweltansprüchen und der Vorbildfunktion der Institution entspricht. | C23: siehe rote Markierungen
A24: E_F8 | B24: Auch wenn meistens bis zu vier Personen in dem Auto fahren, sollte aus Umweltsicht bevorzugt ein Fahrzeug der Kompaktklasse beschafft werden. Bereits in diesem Fahrzeugsegment gibt es viele Modelle mit ausreichend Platz für große Erwachsene auf der Rückbank. Ist mehr Komfort und/oder Stauraum nötig, sollte genau abgewogen werden, welches Segment den Umweltansprüchen und der Vorbildfunktion der Institution entspricht. | C24: siehe rote Markierungen; Verlinkung (siehe Kommentar) über "Modelle"
A25: E_F9 | B25: Wenn selten alle fünf Sitzplätze benötigt werden, sollte aus Umweltsicht bevorzugt ein Fahrzeug der Kompaktklasse beschafft werden. Bereits in diesem Fahrzeugsegment gibt es viele Modelle mit ausreichend Platz für große Erwachsene auf der Rückbank. Ist mehr Komfort und/oder Stauraum nötig, sollte genau abgewogen werden, welches Segment den Umweltansprüchen und der Vorbildfunktion der Institution entspricht. | C25: siehe rote Markierungen; Verlinkung (siehe Kommentar) über "Modelle"
A26: E_F10 | B26: Werden oft alle fünf Sitzplätze benötigt, ist ein Fahrzeug der Mittelklasse zu empfehlen.
