Workbook
Name Deckenheizung: #REF!
Name Deckenheizung: #REF!
Name Deckenheizung: #REF!
Name Deckenheizung: #REF!
Name Deckenheizung: #REF!
Name Deckenheizung: #REF!
Name Deckenheizung: #REF!
Name Deckenheizung: #REF!
Name Deckenheizung: #REF!
Name DropdownlisteHeizungsrohre: #REF!
Name DropdownlisteHeizungsrohre: #REF!
Name Flachheizkörper: Flachheizkoerper_senkrecht_profiliert[Flachheizkoerper_senkrecht_profiliert]
Name Flachheizkörper: Flachheizkoerper_senkrecht_profiliert[Flachheizkoerper_senkrecht_profiliert]
Name Flachheizkörper: Flachheizkoerper_senkrecht_profiliert[Flachheizkoerper_senkrecht_profiliert]
Name Flachheizkörper: Flachheizkoerper_senkrecht_profiliert[Flachheizkoerper_senkrecht_profiliert]
Name Flachheizkörper: Flachheizkoerper_senkrecht_profiliert[Flachheizkoerper_senkrecht_profiliert]
Name Flachheizkörper: Flachheizkoerper_senkrecht_profiliert[Flachheizkoerper_senkrecht_profiliert]
Name Flachheizkörper: Flachheizkoerper_senkrecht_profiliert[Flachheizkoerper_senkrecht_profiliert]
Name Flachheizkörper: Flachheizkoerper_senkrecht_profiliert[Flachheizkoerper_senkrecht_profiliert]
Name Flachheizkörper: Flachheizkoerper_senkrecht_profiliert[Flachheizkoerper_senkrecht_profiliert]
Name Fußbodenheizung: #REF!
Name Fußbodenheizung: #REF!
Name Fußbodenheizung: #REF!
Name Gewinderohr: Tabelle8[[#All],[Gewinderohr_Hoehe]]
Name Gewinderohr: Tabelle8[[#All],[Gewinderohr_Hoehe]]
Name Gewinderohr: Tabelle8[[#All],[Gewinderohr_Hoehe]]
Name Gliederheizkröper: Gliederheizkörper[[#All],[Gliederheizkörper]]
Name Gliederheizkröper: Gliederheizkörper[[#All],[Gliederheizkörper]]
Name Gliederheizkröper: Gliederheizkörper[[#All],[Gliederheizkörper]]
Name Gliederheizkröper: Gliederheizkörper[[#All],[Gliederheizkörper]]
Name Gliederheizkröper: Gliederheizkörper[[#All],[Gliederheizkörper]]
Name Gliederheizkröper: Gliederheizkörper[[#All],[Gliederheizkörper]]
Name Gliederheizkröper: Gliederheizkörper[[#All],[Gliederheizkörper]]
Name Gliederheizkröper: Gliederheizkörper[[#All],[Gliederheizkörper]]
Name Gliederheizkröper: Gliederheizkörper[[#All],[Gliederheizkörper]]
Name HeinzungsrohreDatensaetze: #REF!
Name HeinzungsrohreDatensaetze: #REF!
Name Heizkörpertypen: Heizkoerpertyp[Heizkörpertypen]
Name Heizkörpertypen: Heizkoerpertyp[Heizkörpertypen]
Name Heizkörpertypen: Heizkoerpertyp[Heizkörpertypen]
Name Heizkörpertypen: Heizkoerpertyp[Heizkörpertypen]
Name Heizkörpertypen: Heizkoerpertyp[Heizkörpertypen]
Name Heizkörpertypen: Heizkoerpertyp[Heizkörpertypen]
Name Heizkörpertypen: Heizkoerpertyp[Heizkörpertypen]
Name Heizkörpertypen: Heizkoerpertyp[Heizkörpertypen]
Name Heizkörpertypen: Heizkoerpertyp[Heizkörpertypen]
Name Konvektor: Tabelle12[Konvektor]
Name Konvektor: Tabelle12[Konvektor]
Name Konvektor: Tabelle12[Konvektor]
Name Konvektor: Tabelle12[Konvektor]
Name Konvektor: Tabelle12[Konvektor]
Name Konvektor: Tabelle12[Konvektor]
Name Konvektor: Tabelle12[Konvektor]
Name Konvektor: Tabelle12[Konvektor]
Name Konvektor: Tabelle12[Konvektor]
Name lambda_ins_thick: PAR!$B$2
Name Log_ÜT_Norm: 49.83
Name p: "INDEX(PAR[Parameter];1)"
Name Rohrheizkörper: Tabelle11[Rohrheizkörper]
Name Rohrheizkörper: Tabelle11[Rohrheizkörper]

Sheet PAR
A1: Bezeichnung | B1: Parameter | C1: Einheit | D1: Beschreibung | E1: Kommentar | F1: Bezeichnung | G1: lambda_ins_thick | H1: U_inwall | I1: T_air_norm | J1: T_air_norm_bath | K1: ang_roof_slop | L1: ang_roof_steep | M1: ang_roof_steepr | N1: U_opaque_lim | O1: U_win_lim | P1: r_worst_lim | Q1: NO_round_Qdot | R1: NO_round_Qdot_spez | S1: NO_round_rcover | T1: NO_r_nt1 | U1: NO_r_nt2 | V1: NO_r_nt3 | W1: Spalte13 | X1: Spalte14 | Y1: Spalte15 | Z1: Spalte16 | AA1: Spalte17 | AB1: Spalte18 | AC1: Spalte19 | AD1: Spalte20 | AE1: Spalte21 | AF1: Spalte22 | AG1: Spalte23 | AH1: Spalte24 | AI1: Spalte25 | AJ1: Spalte26 | AK1: Spalte27 | AL1: Spalte28 | AM1: Spalte29 | AN1: Spalte30 | AO1: Spalte31 | AP1: Spalte32 | AQ1: Spalte33 | AR1: Spalte34 | AS1: Spalte35 | AT1: Spalte36 | AU1: Spalte37 | AV1: Spalte38 | AW1: Spalte39 | AX1: Spalte40 | AY1: Spalte41 | AZ1: Spalte42 | BA1: Spalte43 | BB1: Spalte44 | BC1: Spalte45 | BD1: Spalte46 | BE1: Spalte47 | BF1: Spalte48 | BG1: Spalte49 | BH1: Spalte50 | BI1: Spalte51 | BJ1: Spalte52 | BK1: Spalte53 | BL1: Spalte54 | BM1: Spalte55 | BN1: Spalte56 | BO1: Spalte57 | BP1: Spalte58 | BQ1: Spalte59 | BR1: Spalte60 | BS1: Spalte61 | BT1: Spalte62 | BU1: Spalte63 | BV1: Spalte64 | BW1: Spalte65 | BX1: Spalte66 | BY1: Spalte67 | BZ1: Spalte68 | CA1: Spalte69 | CB1: Spalte70 | CC1: Spalte71 | CD1: Spalte72 | CE1: Spalte73 | CF1: Spalte74 | CG1: Spalte75 | CH1: Spalte76 | CI1: Spalte77 | CJ1: Spalte78 | CK1: Spalte79 | CL1: Spalte80 | CM1: Spalte81 | CN1: Spalte82 | CO1: Spalte83 | CP1: Spalte84 | CQ1: Spalte85 | CR1: Spalte86 | CS1: Spalte87 | CT1: Spalte88 | CU1: Spalte89 | CV1: Spalte90 | CW1: Spalte91 | CX1: Spalte92 | CY1: Spalte93 | CZ1: Spalte94 | DA1: Spalte95 | DB1: Spalte96
A2: lambda_ins_thick | B2: 0.04 | C2: W/(mK) | D2: Annahme für lambda Wert der nachträglich aufgebrachten Dämmebene | F2: Parameter | G2: 0.045 | H2: 1 | I2: 20 | J2: 24 | K2: 25 | L2: 40 | M2: 55 | N2: 0.8 | O2: 2.7 | P2: 0.2 | Q2: 100 | R2: 5 | S2: 0.1 | T2: 0.6 | U2: 0.8 | V2: 1
A3: T_air_norm | B3: 20 | C3: °C | D3: Norm-Raumtemperatur Standardraum | F3: Einheit | G3: W/(mK) | H3: W/(m²K) | I3: °C | J3: °C | K3: ° | L3: ° | M3: ° | N3: W/(m²K) | O3: W/(m²K) | P3: % | Q3: W | R3: W/m² | S3: % | T3: % | U3: % | V3: %
A4: T_air_norm_bath | B4: 24 | C4: °C | D4: Norm-Raumtemperatur Badezimmer | F4: Beschreibung | G4: Annahme für lambda Wert der nachträglich aufgebrachten Dämmebene | I4: Norm-Raumtemperatur Standardraum | J4: Norm-Raumtemperatur Badezimmer
F5: Kommentar
F10: =INDEX(PAR[T_air_norm],1) -> 20

Sheet Syntax
A2: Syntax Variablen: Größe | Medium | System | Subsystem | Spezifikation | Spezifikation 2
A3: Kursive Kategorien sind optional
B5: Variable | C5: Bezeichnung | D5: Einheit
A6: (phys.) Größe | B6: A | C6: Fläche | D6: m²
B7: B | C7: Zustandsgröße
B8: EXIST | C8: Merkmal vorhanden
B9: freq | C9: Frequenz | D9: 1/h
B10: ID | C10: Identifikationsnummer
B11: lambda | C11: Wärmeleitfähigkeit | D11: W/(mK)
B12: L | C12: Distanz | D12: m
B13: n | C13: Anzahl / Heizkörperexponent
B14: NO | C14: Nummer
B15: Q | C15: Wärmemenge | D15: Wh
B16: q | C16: spez. Wärmemenge
B17: Qdot | C17: Wärmestrom | D17: W
B18: qdot | C18: spez. Wärmeleistung
B19: R | C19: Wärmedurchgangswiderstand | D19: m²K/W
B20: r | C20: Anteil
B21: S | C21: Status
B22: T | C22: Temperatur | D22: °C
B23: Tdif | C23: Temperaturdifferenz | D23: K
B24: TXT | C24: Text
B25: TYP | C25: Art
B26: STYP | C26: Unterart
B27: U | C27: Wärmedurchgangskoeffizient | D27: W/(m²K)
B28: V | C28: Volumen | D28: m³
B29: Vdot | C29: Volumenstrom | D29: m³/h
B30: YEAR | C30: Jahr | D30: -
A36: System/Subsystem | B36: build | C36: Gebäude
B37: room | C37: Raum
B38: wall | C38: Außenwand
B39: inwall | C39: Innenwand
B40: rad | C40: Radiator
B41: win | C41: Fenster
B42: roof | C42: Dach
B43: topceil | C43: Decke
B44: botceil | C44: Boden
B45: ins | C45: Dämmung
B46: conn | C46: Bauteilanschluss
B47: slop | C47: Schräge
...

Sheet Frontend_allg_OLD
A1: Bauteil (ifeu intern)
A2: Frage (ifeu intern) | C2: Zur Person | D2: Standort | E2: Gebäudetyp | F2: Baujahr des Gebäudes | AF2: Effizienzklasse sofern bekannt | AG2: Nachträglich gedämmte Bauteile | AH2: Nachträglich gedämmte Bauteile | AI2: wenn bekannt, in welcher Dicke wurde gedämmt? | AJ2: Nachträglich gedämmte Bauteile | AK2: wenn bekannt, in welcher Dicke wurde gedämmt? | AL2: Nachträglich gedämmte Bauteile | AM2: wenn bekannt, in welcher Dicke wurde gedämmt? | AN2: Denkmalschutz | AO2: Wärmeübergabe | AP2: -Lüftung | AQ2: ich weiß, auf welchen Wert die TVL in der Heizungsregelung eingestellt ist | AR2: ich kann im Heizungsraum die Vorlauftemperatur ablesen und kann die Außentemperatur messen | AS2: =IF(AND($AQ$17="Nein",$AR$17="Nein"),"70°C",IF(AND($AQ$17="Ja",$AR$17="Nein"),"Bitte tragen sie die Vorlauftemperatur ein",IF(AND($AQ$17="Nein",$AR$17="Ja"),"Bitte tragen sie die Vorlauftemperatur ein","Bitte tragen Sie die Vorlauftemperatur ein"))) -> Bitte tragen Sie die Vorlauftemperatur ein | AT2: =IF($AR$17="Ja","Bitte tragen Sie die Außentemperatur zum Zeitpunkt ihrer Ablesung ein","") | AU2: Wärmeverteilung | AV2: Gibt es in Ihrem Haus / Ihrer Wohnung Räume, die nicht ausreichend warm werden? | AW2: 1 | AX2: 2 | AY2: 3 | AZ2: 4 | BA2: Gibt es in Ihrem Haus / Ihrer Wohnung Räume mit besonders vielen Außenbauteilen (Außenwände, Dachschräge, Flachdach, Räume mit Erker, oberhalb einer Durchfahrt, unter unbeheiztem Dachboden, über unbeheiztem Keller, viele Fenster) | BB2: 1 | BC2: 2 | BD2: 3 | BE2: 4
A3: Gruppe | G3: san | H3: san | I3: san | J3: san | K3: san | L3: san | M3: san | N3: san | O3: san | P3: san | Q3: san | R3: san | S3: san | T3: san | U3: san | V3: san | W3: san | X3: san | Y3: san | Z3: san | AA3: san | AB3: san | AC3: san | AD3: san | AE3: san
A4: Subgruppe | G4: wall | H4: wall | I4: wall | J4: wall | K4: wall | L4: win | M4: win | N4: win | O4: win | P4: win | Q4: roof | R4: roof | S4: roof | T4: roof | U4: roof | V4: botceil | W4: botceil | X4: botceil | Y4: botceil | Z4: botceil | AA4: topceil | AB4: topceil | AC4: topceil | AD4: topceil | AE4: topceil
A5: Fragentext
A6: Hilfstext
A7: Antworttyp
A8: Filter
A9: Einheit
A10: Datentyp
A11: Pflichtfeld
A12: Nachkommastellen
A13: Wertebereich min
A14: Wertebereich max
A15: Defaultwert
A16: Variablenname | G16: EXIST_build_wall_san | H16: YEAR_build_wall_san_intern | I16: YEAR_build_wall_san | J16: L_build_wall_ins_intern | K16: L_build_wall_ins
C17: Hauseigentümer*in | D17: 67435 | E17: Ein- oder Zweifamilienhaus | F17: 1969 - 1978 | AF17: Nicht bekannt | AG17: Ja | AH17: Dämmung der obersten Geschossdecke | AI17: 12 | AN17: das Gebäude steht nicht unter Denkmalschutz | AO17: Heizkörper | AP17: Freie Lüftung | AQ17: Ja | AS17: 75 | AT17: -10 | AU17: Zweirohrheizung | AV17: Ja | AW17: Sonstige | AX17: Sonstige | BA17: Ja | BB17: Sonstige | BC17: Schlafzimmer | BD17: Sonstige
C18: Art der Ansprache ggf. anpassen | D18: Bitte Plz eingeben | E18: ggf. bei Plausibilisierung mit Empirie berücksichtigen (W/m²) | F18: U-Werte nach IWU | AH18: Wir müssen dieses Multiple Choice Feld in alle Einzelfälle abdecken, um die Daten verarbeiten zu können, oder? | AI18: für Berechnung der U-Werte | AK18: für Berechnung der U-Werte | AM18: für Berechnung der U-Werte | AN18: =IF(AN17=Daten!E54, "keine WDVS empfehlen","WDVS können empfohlen werden") -> WDVS können empfohlen werden | AO18: =IF(AO17=Daten!E58,"Pauschal für WP geeignet",IF(AO17=Daten!E60,"Maßnahmen für den optimalen WP-Betrieb erforderlich",IF(AO17=Daten!E61,"Pauschal für WP geeignet",IF(AO17=Daten!E62,"Maßnahmen für den optimalen WP-Betrieb erforderlich","")))) | AQ18: TVL in °C | AS18: TVL in °C | AT18: AT in °C | AU18: =IF(AU17="Zweirohrheizung","Bitte überprüfen Sie, ob ihr Heizsystem hydraulisch abgeglichen ist","") -> Bitte überprüfen Sie, ob ihr Heizsystem hydraulisch abgeglichen ist | AV18: =IF(AV17="Ja","Bitte wählen Sie die Räume aus, die am schlechtesten warm werden") -> Bitte wählen Sie die Räume aus, die am schlechtesten warm werden | BA18: =IF(BA17="Ja","Bitte wählen Sie die Räume mit den meisten Außenbauteilen aus") -> Bitte wählen Sie die Räume mit den meisten Außenbauteilen aus
AQ19: Wenn ja, dann Eingabe der Vorlauftemperatur | AR19: Wenn ja, dann Eingabe der Vorlauftemperatur und Außentemperatur | AT19: max. TVL(AT)
AR20: Wenn beide nein, dann TVL pauschal 70°C | AT20: =AT17*-1.8257+43.457+AT17 -> 51.714
AR21: TVL<AT*(-1,8257)+43,457+AT | AT21: ich kann im Heizungsraum die Vorlauftemperatur ablesen und kann die Außentemperatur messen
E26: Löschen? | AG26: löschen, da Abfrageart überarbeitet. Bisher gibt es hier keine Spur zum Nachfolger
E27: Todo | G27: ggf. nach unten schieben
AO69: =IF(AO17="elektrische Nachtspeicherheizung","Frage 1.5 nicht stellen",IF(AO17="Luftheizung","Frage nicht stellen!",""))

Sheet Frontend_Räume_OLD
A1: Bauteil (ifeu intern) | K1: Decke | L1: Fußboden | M1: Außenwand | N1: Außenwand 1 | O1: Außenwand | P1: Außenwand Art | Q1: Außenwand 2 | R1: Außenwand 2 | S1: Außenwand 2 | T1: Außenwand Art | U1: Außenwand 3 | V1: Außenwand 3 | W1: Außenwand 3 | X1: Außenwand Art | Y1: Außenwand 4 | Z1: Außenwand 4 | AA1: Außenwand 4 | AB1: Außenwand Art | AC1: Dachfläche | AD1: Dachfläche | AE1: Dachfläche | AF1: Dachfläche | AG1: Dachfläche | AH1: Dachfläche | AI1: Dachfläche 2 | AJ1: Dachfläche 2 | AK1: Dachfläche 2 | AL1: Dachfläche 3 | AM1: Dachfläche 3 | AN1: Dachfläche 3 | AO1: Decke | AP1: Decke | AQ1: Decke | AR1: Fußboden | AS1: Fußboden | AT1: Fußboden | AU1: Fenster 1 in Außenwand | AV1: Fenster 1 in Außenwand | AW1: Fenster 1 in Außenwand | AX1: Fenster 1 in Außenwand | AY1: Fenster 2 in Außenwand | AZ1: Fenster 2 in Außenwand | BA1: Fenster 2 in Außenwand | BB1: Fenster 2 in Außenwand | BC1: Fenster 3 in Außenwand 1 | BD1: Fenster 3 in Außenwand 1 | BE1: Fenster 3 in Außenwand 1 | BF1: Fenster 3 in Außenwand | BG1: Fenster 4 in Außenwand 1 | BH1: Fenster 4 in Außenwand 1 | BI1: Fenster 4 in Außenwand 1 | BJ1: Fenster 1 in Außenwand 2 | BK1: Fenster 1 in Außenwand 2 | BL1: Fenster 1 in Außenwand 2 | BM1: Fenster 2 in Außenwand 2 | BN1: Fenster 2 in Außenwand 2 | BO1: Fenster 2 in Außenwand 2 | BP1: Fenster 3 in Außenwand 2 | BQ1: Fenster 3 in Außenwand 2 | BR1: Fenster 3 in Außenwand 2 | BS1: Fenster 4 in Außenwand 2 | BT1: Fenster 4 in Außenwand 2 | BU1: Fenster 4 in Außenwand 2 | BV1: Fenster 1 in Außenwand 3 | BW1: Fenster 1 in Außenwand 3 | BX1: Fenster 1 in Außenwand 3 | BY1: Fenster 2 in Außenwand 3 | BZ1: Fenster 2 in Außenwand 3 | CA1: Fenster 2 in Außenwand 3 | CB1: Fenster 3 in Außenwand 3 | CC1: Fenster 3 in Außenwand 3 | CD1: Fenster 3 in Außenwand 3 | CE1: Fenster 4 in Außenwand 3 | CF1: Fenster 4 in Außenwand 3 | CG1: Fenster 4 in Außenwand 3 | CH1: Fenster 1 in Außenwand 4 | CI1: Fenster 1 in Außenwand 4 | CJ1: Fenster 1 in Außenwand 4 | CK1: Fenster 2 in Außenwand 4 | CL1: Fenster 2 in Außenwand 4 | CM1: Fenster 2 in Außenwand 4 | CN1: Fenster 3 in Außenwand 4 | CO1: Fenster 3 in Außenwand 4 | CP1: Fenster 3 in Außenwand 4 | CQ1: Fenster 4 in Außenwand 4 | CR1: Fenster 4 in Außenwand 4 | CS1: Fenster 4 in Außenwand 4 | CT1: Fenster 1 in Dachfläche 1 | CU1: Fenster 1 in Dachfläche 1 | CV1: Fenster 1 in Dachfläche 1 | CW1: Fenster 2 in Dachfläche 1 | CX1: Fenster 2 in Dachfläche 1 | CY1: Fenster 2 in Dachfläche 1 | CZ1: Fenster 3 in Dachfläche 1 | DA1: Fenster 3 in Dachfläche 1 | DB1: Fenster 3 in Dachfläche 1 | DC1: Fenster 1 in Dachfläche 2 | DD1: Fenster 1 in Dachfläche 2 | DE1: Fenster 1 in Dachfläche 2 | DF1: Fenster 2 in Dachfläche 2 | DG1: Fenster 2 in Dachfläche 2 | DH1: Fenster 2 in Dachfläche 2 | DI1: Fenster 3 in Dachfläche 2 | DJ1: Fenster 3 in Dachfläche 2 | DK1: Fenster 3 in Dachfläche 2 | DL1: Fenster 1 in Dachfläche 3 | DM1: Fenster 1 in Dachfläche 3 | DN1: Fenster 1 in Dachfläche 3 | DO1: Fenster 2 in Dachfläche 3 | DP1: Fenster 2 in Dachfläche 3 | DQ1: Fenster 2 in Dachfläche 3 | DR1: Fenster 3 in Dachfläche 3 | DS1: Fenster 3 in Dachfläche 3 | DT1: Fenster 3 in Dachfläche 3 | DU1: Heizkörper 1 im Raum 1 | DV1: Heizkörper 1 im Raum 1 | DW1: Heizkörper 1 im Raum 1 | DX1: Heizkörper 1 im Raum 1 | DY1: Heizkörper 1 im Raum 1 | DZ1: Heizkörper 1 im Raum 1 | EA1: Heizkörper 1 im Raum 1 | EB1: Heizkörper 2 im Raum 1 | EC1: Heizkörper 2 im Raum 1 | ED1: Heizkörper 2 im Raum 1 | EE1: Heizkörper 2 im Raum 1 | EF1: Heizkörper 2 im Raum 1 | EG1: Heizkörper 2 im Raum 1 | EH1: Heizkörper 2 im Raum 1 | EI1: Heizkörper 3 im Raum 1 | EJ1: Heizkörper 3 im Raum 1 | EK1: Heizkörper 3 im Raum 1 | EL1: Heizkörper 3 im Raum 1 | EM1: Heizkörper 3 im Raum 1 | EN1: Heizkörper 3 im Raum 1 | EO1: Heizkörper 3 im Raum 1 | EP1: Heizkörper 4 im Raum 1 | EQ1: Heizkörper 4 im Raum 1 | ER1: Heizkörper 4 im Raum 1 | ES1: Heizkörper 4 im Raum 1 | ET1: Heizkörper 4 im Raum 1 | EU1: Heizkörper 4 im Raum 1 | EV1: Heizkörper 4 im Raum 1 | EW1: Heizkörper 5 im Raum 1 | EX1: Heizkörper 5 im Raum 1 | EY1: Heizkörper 5 im Raum 1 | EZ1: Heizkörper 5 im Raum 1 | FA1: Heizkörper 5 im Raum 1 | FB1: Heizkörper 5 im Raum 1 | FC1: Heizkörper 5 im Raum 1
A2: Frage (ifeu intern) | B2: Raumindex | C2: Raumbezeichnung | D2: Hat der Raum eine rechteckige Grundfläche? | E2: Länge | F2: Breite | G2: Wohnfläche | H2: Raumhöhe | I2: Gewünschte Raumtemperatur | J2: Norm-Innentemperatur | K2: Grenzt an | L2: Grenzt an | M2: Länge | N2: Höhe | O2: Von Gebäude abweichende Dämmschicht? | P2: Grenzt an | Q2: Länge | R2: Höhe | S2: Von Gebäude abweichende Dämmschicht? | T2: Grenzt an | U2: Länge | V2: Höhe | W2: Von Gebäude abweichende Dämmschicht? | X2: Grenzt an | Y2: Länge | Z2: Höhe | AA2: Von Gebäude abweichende Dämmschicht? | AB2: Grenzt an | AD2: Breite | AE2: Höhe | AF2: Von Gebäude abweichende Dämmschicht? | AI2: Länge | AJ2: Breite | AK2: Von Gebäude abweichende Dämmschicht? | AL2: Länge | AM2: Breite | AN2: Von Gebäude abweichende Dämmschicht? | AO2: Länge | AP2: Breite | AQ2: Von Gebäude abweichende Dämmschicht? | AR2: Länge | AS2: Breite | AT2: Von Gebäude abweichende Dämmschicht? | AU2: Breite | AV2: Höhe | AW2: Jahr, in dem die Fenster zuletzt ausgetauscht wurden | AX2: Anzahl | AY2: Breite | AZ2: Höhe | BA2: Jahr, in dem die Fenster zuletzt ausgetauscht wurden | BC2: Breite | BD2: Höhe | BE2: Jahr, in dem die Fenster zuletzt ausgetauscht wurden | BF2: Anzahl | BG2: Breite | BH2: Höhe | BI2: Jahr, in dem die Fenster zuletzt ausgetauscht wurden | BJ2: Breite | BK2: Höhe | BL2: Jahr, in dem die Fenster zuletzt ausgetauscht wurden | BM2: Breite | BN2: Höhe | BO2: Jahr, in dem die Fenster zuletzt ausgetauscht wurden | BP2: Breite | BQ2: Höhe | BR2: Jahr, in dem die Fenster zuletzt ausgetauscht wurden | BS2: Breite | BT2: Höhe | BU2: Jahr, in dem die Fenster zuletzt ausgetauscht wurden | BV2: Breite | BW2: Höhe | BX2: Jahr, in dem die Fenster zuletzt ausgetauscht wurden | BY2: Breite | BZ2: Höhe | CA2: Jahr, in dem die Fenster zuletzt ausgetauscht wurden | CB2: Breite | CC2: Höhe | CD2: Jahr, in dem die Fenster zuletzt ausgetauscht wurden | CE2: Breite | CF2: Höhe | CG2: Jahr, in dem die Fenster zuletzt ausgetauscht wurden | CH2: Breite | CI2: Höhe | CJ2: Jahr, in dem die Fenster zuletzt ausgetauscht wurden | CK2: Breite | CL2: Höhe | CM2: Jahr, in dem die Fenster zuletzt ausgetauscht wurden | CN2: Breite | CO2: Höhe | CP2: Jahr, in dem die Fenster zuletzt ausgetauscht wurden | CQ2: Breite | CR2: Höhe | CS2: Jahr, in dem die Fenster zuletzt ausgetauscht wurden | CT2: Breite | CU2: Höhe | CV2: Jahr, in dem die Fenster zuletzt ausgetauscht wurden | CW2: Breite | CX2: Höhe | CY2: Jahr, in dem die Fenster zuletzt ausgetauscht wurden | CZ2: Breite | DA2: Höhe | DB2: Jahr, in dem die Fenster zuletzt ausgetauscht wurden | DC2: Breite | DD2: Höhe | DE2: Jahr, in dem die Fenster zuletzt ausgetauscht wurden | DF2: Breite | DG2: Höhe | DH2: Jahr, in dem die Fenster zuletzt ausgetauscht wurden | DI2: Breite | DJ2: Höhe | DK2: Jahr, in dem die Fenster zuletzt ausgetauscht wurden | DL2: Breite | DM2: Höhe | DN2: Jahr, in dem die Fenster zuletzt ausgetauscht wurden | DO2: Breite | DP2: Höhe | DQ2: Jahr, in dem die Fenster zuletzt ausgetauscht wurden | DR2: Breite | DS2: Höhe | DT2: Jahr, in dem die Fenster zuletzt ausgetauscht wurden | DU2: Typ | DV2: Subtyp | DW2: Subtyp 2 | DX2: Höhe | DY2: Breite | DZ2: Tiefe | EA2: Anzahl Glieder | EB2: Typ | EC2: Subtyp | ED2: Subtyp 2 | EE2: Höhe | EF2: Breite | EG2: Tiefe | EH2: Anzahl Glieder | EI2: Typ | EJ2: Subtyp | EK2: Subtyp 2 | EL2: Höhe | EM2: Breite | EN2: Tiefe | EO2: Anzahl Glieder | EP2: Typ | EQ2: Subtyp | ER2: Subtyp 2 | ES2: Höhe | ET2: Breite | EU2: Tiefe | EV2: Anzahl Glieder | EW2: Typ | EX2: Subtyp | EY2: Subtyp 2 | EZ2: Höhe | FA2: Breite | FB2: Tiefe | FC2: Anzahl Glieder
A3: Gruppe | K3: ceiling1 | L3: floor | M3: wall | N3: wall | O3: wall | Q3: wall2 | R3: wall2 | S3: wall2 | U3: wall3 | V3: wall3 | W3: wall3 | Y3: wall4 | Z3: wall4 | AA3: wall4 | AC3: roof | AD3: roof | AE3: roof | AF3: roof | AG3: roof | AH3: roof | AI3: roof1 | AJ3: roof1 | AK3: roof1 | AL3: roof1 | AM3: roof1 | AN3: roof1 | AO3: ceiling1 | AP3: ceiling1 | AQ3: ceiling1 | AR3: floor | AS3: floor | AT3: floor | AU3: wall | AV3: wall | AW3: wall | AX3: wall | AY3: wall | AZ3: wall | BA3: wall | BB3: wall | BC3: wall | BD3: wall | BE3: wall | BF3: wall | BG3: wall1 | BH3: wall1 | BI3: wall1 | BJ3: wall2 | BK3: wall2 | BL3: wall2 | BM3: wall2 | BN3: wall2 | BO3: wall2 | BP3: wall2 | BQ3: wall2 | BR3: wall2 | BS3: wall2 | BT3: wall2 | BU3: wall2 | BV3: wall3 | BW3: wall3 | BX3: wall3 | BY3: wall3 | BZ3: wall3 | CA3: wall3 | CB3: wall3 | CC3: wall3 | CD3: wall3 | CE3: wall3 | CF3: wall3 | CG3: wall3 | CH3: wall4 | CI3: wall4 | CJ3: wall4 | CK3: wall4 | CL3: wall4 | CM3: wall4 | CN3: wall4 | CO3: wall4 | CP3: wall4 | CQ3: wall4 | CR3: wall4 | CS3: wall4
A4: Subgruppe | AU4: win1 | AV4: win1 | AW4: win1 | AX4: win1 | AY4: win2 | AZ4: win2 | BA4: win2 | BB4: win2 | BC4: win3 | BD4: win3 | BE4: win3 | BF4: win3 | BG4: win4 | BH4: win4 | BI4: win4 | BJ4: win1 | BK4: win1 | BL4: win1 | BM4: win2 | BN4: win2 | BO4: win2 | BP4: win3 | BQ4: win3 | BR4: win3 | BS4: win4 | BT4: win4 | BU4: win4 | BV4: win1 | BW4: win1 | BX4: win1 | BY4: win2 | BZ4: win2 | CA4: win2 | CB4: win3 | CC4: win3 | CD4: win3 | CE4: win4 | CF4: win4 | CG4: win4 | CH4: win1 | CI4: win1 | CJ4: win1 | CK4: win2 | CL4: win2 | CM4: win2 | CN4: win3 | CO4: win3 | CP4: win3 | CQ4: win4 | CR4: win4 | CS4: win4
A5: Fragentext | C5: Geben Sie den Raum einen Namen | G5: Raumfläche | H5: Raumhöhe | I5: gewünsche Raumtemperatur | K5: Decke grenzt an | L5: Fußboden grenzt an | M5: Gesamtlänge der Außenwände | O5: Modernisierungsjahr | AC5: Dachfläche vorhanden? | AD5: Breite | AE5: Höhe | AF5: Modernisierungsjahr | AG5: Falls ein Kniestock vorhanden ist, geben Sie dessen Höhe an | AH5: Falls eine Dachgaube vorhanden ist, geben Sie die Länge an | AU5: Geben Sie die Abmaße des ersten Fenstertyps an, Breite | AV5: Höhe | AW5: Abweichendes Einbaujahr | AX5: Anzahl identischer Fenster im Raum | AY5: Geben Sie die Abmaße des ersten Fenstertyps an, Breite | AZ5: Höhe | BA5: Abweichendes Einbaujahr | BB5: Anzahl identischer Fenster im Raum | BC5: Geben Sie die Abmaße des ersten Fenstertyps an, Breite | BD5: Höhe | BE5: Abweichendes Einbaujahr | BF5: Anzahl identischer Fenster im Raum
A6: Hilfstext | AD6: Bei mehreren Dachflächen bitte summieren | AE6: Bei mehreren Dachflächen bitte nicht summieren | AG6: Der Kniestock oder Drempel beschreibt im Dachbereich die Höhe der Wand zwischen Fußboden und Beginn des Dachs.
A7: Antworttyp | B7: Intern | C7: Freitext | D7: Radio Button | E7: Freitext Real | F7: Freitext Real | G7: Freitext | H7: Freitext | I7: Freitext | J7: Intern | K7: Dropdown | L7: Dropdown | M7: Freitext | N7: Freitext | O7: Dropdown | Q7: Freitext | R7: Freitext | S7: Freitext | U7: Freitext | V7: Freitext | W7: Freitext | Y7: Freitext | Z7: Freitext | AA7: Freitext | AC7: toggle switch | AD7: Freitext | AE7: Freitext | AF7: Dropdown | AG7: Freitext | AH7: Freitext | AI7: Freitext | AJ7: Freitext | AK7: Freitext | AL7: Freitext | AM7: Freitext | AN7: Freitext | AO7: Freitext | AP7: Freitext | AQ7: Freitext | AR7: Freitext | AS7: Freitext | AT7: Freitext | AU7: Freitext | AV7: Freitext | AW7: Dropdown | AX7: Freitext | AY7: Freitext | AZ7: Freitext | BA7: Dropdown | BB7: Freitext | BC7: Freitext | BD7: Freitext | BE7: Dropdown | BF7: Freitext
A8: Filter | E8: B_R#_floor_rect=True | F8: B_R#_floor_rect=True | AD8: B_roof_exist | AE8: B_roof_exist | AF8: B_roof_exist | AG8: B_roof_exist | AH8: B_roof_exist | AR8: wenn TYP_R#_floor=unbeheizt/Erdreich oder TYP_R#_floor=teils-teils | AS8: wenn TYP_R#_floor=unbeheizt/Erdreich oder TYP_R#_floor=teils-teils | AT8: wenn TYP_R#_floor=Außenluft oder TYP_R#_floor=teils-teils
A9: Einheit | G9: m² | H9: m | I9: °C | M9: m | N9: m | Q9: m | R9: m | S9: cm | U9: m | V9: m | W9: cm | Y9: m | Z9: m | AA9: cm | AD9: m | AE9: m | AG9: m | AH9: m | AI9: m | AJ9: m | AK9: cm | AL9: m | AM9: m | AN9: cm | AO9: m | AP9: m | AQ9: cm | AR9: m | AS9: m | AT9: cm | AU9: cm | AV9: cm | AY9: cm | AZ9: cm | BC9: cm | BD9: cm | BH9: cm | BI9: cm | BK9: cm | BL9: cm | BN9: cm | BO9: cm | BQ9: cm | BR9: cm | BT9: cm | BU9: cm | BW9: cm | BX9: cm | BZ9: cm | CA9: cm | CC9: cm | CD9: cm | CF9: cm | CG9: cm | CI9: cm | CJ9: cm | CL9: cm | CM9: cm | CO9: cm | CP9: cm | CR9: cm | CS9: cm | CU9: cm | CV9: cm | CX9: cm | CY9: cm | DA9: cm | DB9: cm | DD9: cm | DE9: cm | DG9: cm | DH9: cm | DJ9: cm | DK9: cm | DM9: cm | DN9: cm | DP9: cm | DQ9: cm | DV9: mm | DW9: mm | DX9: mm | EB9: mm | EC9: mm | ED9: mm | EE9: mm | EI9: mm | EJ9: mm | EK9: mm | EL9: mm | EP9: mm | EQ9: mm | ER9: mm | ES9: mm | EW9: mm | EX9: mm | EY9: mm | EZ9: mm
A10: Datentyp | B10: String | C10: String | D10: Boolean | E10: Real | F10: Real | G10: Real | H10: Real | I10: Integer | J10: Integer | K10: String | L10: String | M10: Real | N10: Real | O10: Integer | Q10: Real | R10: Real | S10: Real | U10: Real | V10: Real | W10: Real | Y10: Real | Z10: Real | AA10: Real | AC10: Boolean | AD10: Real | AE10: Real | AF10: Integer | AG10: Real | AH10: Real | AI10: Real | AJ10: Real | AK10: Real | AL10: Real | AM10: Real | AN10: Real | AO10: Real | AP10: Real | AQ10: Real | AU10: Real | AV10: Real | AW10: Integer | AX10: Integer | AY10: Real | AZ10: Real | BA10: Integer | BB10: Integer | BC10: Real | BD10: Real | BE10: Integer | BF10: Integer
A11: Pflichtfeld | C11: 1 | D11: 1 | G11: 1 | H11: 1 | K11: 1 | L11: 1 | M11: 1 | AC11: 1 | AD11: 0 | AE11: 0 | AF11: 0 | AG11: 0 | AH11: 0 | AU11: 1 | AV11: 1 | AW11: 0 | AX11: 0 | AY11: 1 | AZ11: 1 | BA11: 0 | BB11: 0 | BC11: 1 | BD11: 1 | BE11: 0 | BF11: 0
A12: Nachkommastellen | G12: 1 | H12: 2 | I12: 0 | M12: 1 | AD12: 1 | AE12: 1 | AG12: 1 | AH12: 1 | AU12: 0 | AV12: 0 | AX12: 0 | AY12: 0 | AZ12: 0 | BB12: 0 | BC12: 0 | BD12: 0 | BF12: 0
A13: Wertebereich min | E13: 1 | F13: 1 | G13: 1 | H13: 1 | I13: 10 | M13: 1 | N13: 2 | Q13: 1 | R13: 2 | S13: 1 | U13: 1 | V13: 2 | W13: 1 | Y13: 1 | Z13: 2 | AA13: 1 | AD13: 1 | AE13: 1 | AG13: 0 | AH13: 0 | AI13: 1 | AJ13: 1 | AK13: 1 | AL13: 1 | AM13: 1 | AN13: 1 | AO13: 1 | AP13: 1 | AQ13: 1 | AR13: 1 | AS13: 1 | AT13: 1 | AU13: 20 | AV13: 20 | AX13: 1 | AY13: 20 | AZ13: 20 | BB13: 1 | BC13: 20 | BD13: 20 | BF13: 1
A14: Wertebereich max | E14: 20 | F14: 20 | G14: 100 | H14: 5 | I14: 30 | M14: 20 | N14: 5 | Q14: 20 | R14: 5 | S14: 30 | U14: 20 | V14: 5 | W14: 30 | Y14: 20 | Z14: 5 | AA14: 30 | AD14: 10 | AE14: 4 | AG14: 3 | AH14: 10 | AI14: 10 | AJ14: 10 | AK14: 30 | AL14: 10 | AM14: 10 | AN14: 30 | AO14: 30 | AP14: 30 | AQ14: 30 | AR14: 20 | AS14: 20 | AT14: 30 | AU14: 400 | AV14: =$H$16 -> L_hei | AX14: 10 | AY14: 400 | AZ14: =$H$16 -> L_hei | BB14: 10 | BC14: 400 | BD14: =$H$16 -> L_hei | BF14: 10
A15: Defaultwert | H15: 2.5 | I15: 20 | K15: unbeheizt | L15: unbeheizt | N15: =H16 -> L_hei | O15: =Frontend_allg_OLD!F17 -> 1969 - 1978 | R15: =H16 -> L_hei | S15: 0 | V15: =H16 -> L_hei | W15: 0 | Z15: =H16 -> L_hei | AA15: 0 | AC15: 0 | AD15: 0 | AE15: 0 | AF15: =Frontend_allg_OLD!F17 -> 1969 - 1978 | AG15: 0 | AH15: 0 | AK15: 0 | AN15: 0 | AO15: 0 | AP15: 0 | AQ15: 0 | AR15: 0 | AS15: 0 | AT15: 0 | AW15: =Frontend_allg_OLD!$F$17 -> 1969 - 1978 | AX15: 1 | BA15: =Frontend_allg_OLD!$F$17 -> 1969 - 1978 | BB15: 1 | BE15: =Frontend_allg_OLD!$F$17 -> 1969 - 1978 | BF15: 1
A16: Variablenname | B16: ID_R# | C16: TXT_R#_name | D16: B_R#_floor_rect | E16: L_R#_len | F16: L_R#_wid | G16: A_floor | H16: L_hei | I16: T_air_set | J16: T_air_norm | K16: TYP_V_above | L16: TYP_V_below | M16: L_wall_tot | N16: L_R#_wall1_hei | O16: YEAR_wall_ins | Q16: L_R#_wall2_len | R16: L_R#_wall2_hei | S16: L_R#_wall2_ins_thick | U16: L_R#_wall3_len | V16: L_R#_wall3_hei | W16: L_R#_wall3_ins_thick | Y16: L_R#_wall4_len | Z16: L_R#_wall4_hei | AA16: L_R#_wall4_ins_thick | AC16: B_roof_exist | AD16: L_roof_wid | AE16: L_roof_hei | AF16: YEAR_roof_modern | AG16: L_roof_knee_hei | AH16: L_roof_dormer_wid | AI16: L_R#_roof2_len | AJ16: L_R#_roof2_hei | AK16: L_R#_roof2_ins_thick | AL16: L_R#_roof3_len | AM16: L_R#_roof3_hei | AN16: L_R#_roof3_ins_thick | AR16: L_R#_floor_length_unheated | AS16: L_R#_floor_width_unheated | AT16: L_R#_floor_ins_thick_amb | AU16: ="L_"&AU3&"_"&AU4&"_wid" -> L_wall_win1_wid | AV16: ="L_"&AV3&"_"&AV4&"_hei" -> L_wall_win1_hei | AW16: ="YEAR_"&AW3&"_"&AW4 -> YEAR_wall_win1 | AX16: ="NO_"&AX3&"_"&AX4 -> NO_wall_win1 | AY16: ="L_"&AY3&"_"&AY4&"_wid" -> L_wall_win2_wid | AZ16: ="L_"&AZ3&"_"&AZ4&"_hei" -> L_wall_win2_hei | BA16: ="YEAR_"&BA3&"_"&BA4 -> YEAR_wall_win2 | BB16: ="NO_"&BB3&"_"&BB4 -> NO_wall_win2 | BC16: ="L_"&BC3&"_"&BC4&"_wid" -> L_wall_win3_wid | BD16: ="L_"&BD3&"_"&BD4&"_hei" -> L_wall_win3_hei | BE16: ="YEAR_"&BE3&"_"&BE4 -> YEAR_wall_win3 | BF16: ="NO_"&BF3&"_"&BF4 -> NO_wall_win3 | BG16: ="L_R#_"&BG3&"_"&BG4&"_wid" -> L_R#_wall1_win4_wid | BH16: ="L_R#_"&BH3&"_"&BH4&"_hei" -> L_R#_wall1_win4_hei | BI16: ="NO_R#_"&BI3&"_"&BI4&"_bj" -> NO_R#_wall1_win4_bj
B17: ID_R1 | C17: =Frontend_allg_OLD!BB17 -> Sonstige | D17: Ja | G17: 11.54 | H17: 2.83 | I17: 20 | J17: 20 | K17: unbeheizt | L17: unbeheizt | M17: 3.95 | N17: =$H$17 -> 2.83 | P17: Außenluft | Q17: 2.92 | R17: =$H$17 -> 2.83 | T17: Außenluft | Z17: =$H$17 -> 2.83 | AC17: Nein | AO17: 3.95 | AP17: 2.92 | AQ17: 6 | AR17: 3.95 | AS17: 2.92 | AU17: 123 | AV17: 125 | AW17: 2003 - 2008 | AX17: 1 | BB17: 1 | BF17: 1 | BJ17: 123 | BK17: 125 | BL17: 2003 - 2008 | DU17: Flachheizkörper | DV17: Senkrecht_profiliert | DW17: 11 | DX17: 600 | DY17: 1100 | DZ17: 65
B18: ID_R2 | C18: =Frontend_allg_OLD!BC17 -> Schlafzimmer | D18: Ja | G18: 16 | H18: 2.83 | I18: 20 | J18: 20 | K18: unbeheizt | L18: unbeheizt | M18: 3.97 | N18: =$H$17 -> 2.83 | P18: Außenluft | Q18: 4.03 | R18: =$H$17 -> 2.83 | T18: Außenluft | Z18: =$H$17 -> 2.83 | AC18: Nein | AO18: 4.03 | AP18: 3.97 | AQ18: 6 | AR18: =SQRT(20.28) -> 4.5033321 | AS18: 4.03 | AT18: 3.97 | AU18: 147.5 | AV18: 125 | AX18: 1 | BB18: 1 | BF18: 1 | DU18: Flachheizkörper | DV18: Senkrecht_profiliert | DW18: 33 | DX18: 600 | DY18: 1000 | DZ18: 155
B19: ID_R3 | C19: =Frontend_allg_OLD!BD17 -> Sonstige | D19: Ja | G19: 10.4 | H19: 2.83 | I19: 20 | J19: 20 | K19: unbeheizt | L19: unbeheizt | M19: 2.5 | N19: =$H$17 -> 2.83 | P19: Außenluft | Z19: =$H$17 -> 2.83 | AC19: Nein | AO19: 2.5 | AP19: 4.17 | AQ19: 6 | AR19: 2.5 | AS19: 4.17 | AU19: 122.5 | AV19: 125 | AX19: 1 | BB19: 1 | BF19: 1 | DU19: Flachheizkörper | DV19: Senkrecht_profiliert | DW19: 11 | DX19: 600 | DY19: 1100 | DZ19: 65
B20: aus Frontend_allg Raumbezeichnung übernehmen | C20: aus Frontend_allg Raumbezeichnung übernehmen | D20: =IF($D$17="Nein","Bitte geben Sie die Wohnfläche direkt ein","") | E20: m | F20: m | G20: m² | H20: m | I20: °C | J20: °C | M20: m | N20: m | O20: cm | Q20: m | R20: m | S20: cm | U20: m | V20: m | W20: cm | Y20: m | Z20: m | AA20: cm | AD20: m | AE20: m | AF20: cm | AI20: m | AJ20: m | AK20: cm | AL20: m | AM20: m | AN20: cm | AO20: m | AP20: m | AQ20: cm | AR20: m | AS20: m | AT20: cm | AV20: cm | AZ20: cm | BA20: cm | BD20: cm | BE20: cm | BH20: cm | BI20: cm | BK20: cm | BL20: cm | BN20: cm | BO20: cm | BQ20: cm | BR20: cm | BT20: cm | BU20: cm | BW20: cm | BX20: cm | BZ20: cm | CA20: cm | CC20: cm | CD20: cm | CF20: cm | CG20: cm | CI20: cm | CJ20: cm | CL20: cm | CM20: cm | CO20: cm | CP20: cm | CR20: cm | CS20: cm | CU20: cm | CV20: cm | CX20: cm | CY20: cm | DA20: cm | DB20: cm | DD20: cm | DE20: cm | DG20: cm | DH20: cm | DJ20: cm | DK20: cm | DM20: cm | DN20: cm | DP20: cm | DQ20: cm | DV20: mm | DW20: mm | DX20: mm | EB20: mm | EC20: mm | ED20: mm | EE20: mm | EI20: mm | EJ20: mm | EK20: mm | EL20: mm | EP20: mm | EQ20: mm | ER20: mm | ES20: mm | EW20: mm | EX20: mm | EY20: mm | EZ20: mm
D21: E3 sperren, wenn D3="Nein"
D22: F3 sperren, wenn D3="Nein"
A26: Löschen? | C26: >> Name kommt aus list_rooms, aber als Ausgabegröße relevant | D26: >> immer über Grundfläche gehen | E26: >> immer Fläche | F26: >> immer Fläche | J26: >> Vorschlag analog heizreport: nur Solltemperatur abfragen und Info zu Temperatur Wohnräume vs. Badezimmer in Hilfstext | N26: >> Tendenz rauslassen: Zu klären, wie es sich bspw. auf Giebelwände auswirkt, mittelt sich das raus? Wie würden wir sie sonst erfassen? (bei heizreport auch nicht differenziert). Kniestöcke fragen wir separat ab. | P26: Vorschlag: bei Außenwand immer Außenluft ansetzen? Kellerraum =! Schlechtpunkt, aber ggf. AW gegen unbeheizt? | Q26: Löschen, da alle Wände zusammengefasst | AI26: Löschen, da alle Dächer zusammengefasst | AO26: Löschen, da nur eine Decke | AQ26: Angabe Dämmung fehlt uns dann. Ich würde über IWU Tabula bzw. Angabe auf Gebäudeebene gehen (weicht in diesem Fall mit 12 cm von der Raumangabe ab). | BG26: Löschen, da alle Außenwände zusammengefasst | CZ26: Löschen, da alle Dachflächen zusammengefasst
A27: Todo | N27: Anpassen Verweis | O27: Anpassung Berechnung U-Wert: über IWU Tablua anstatt Dämmschichtdicke? Oder Dämmschichtdicke anhand Jahr Modernisierung (Tabelle unten)? Oder EnEV/GEG Vorgaben und anhand Novellen? >> Peter: es gibt Input GEMOD | P27: Anpassen Verweis | AF27: siehe YEAR_wall_modern sowie bzgl. defaultwert: Überarbeiten Verweis auf Wert Gebäude, wenn Modernisierungsjahr für alle Bauteile getrennt abgefragt wird. | AG27: Einbezug Berechnung in DIN12831 klären | AH27: Einbezug Berechnung in DIN12831 klären | AW27: siehe YEAR_wall_ins | AX27: Multiplikator aufnehmen | BB27: Multiplikator aufnehmen | BF27: Multiplikator aufnehmen
BF28: ggf. 4. Fenstertyp ergänzen?

Sheet IN_build
A1: Bezeichnung | B1: Gruppe | C1: Subgruppe | D1: Variable | E1: Fragentext | F1: Hilfstext | G1: Antworttyp | H1: Filter | I1: Einheit | J1: Datentyp | K1: Pflichtfeld | L1: Nachkommastellen | M1: min Wert | N1: max Wert | O1: Wert intern | P1: Wert | Q1: EXIST | R1: YEAR_intern | S1: YEAR | T1: L_ins_intern [cm] | U1: L_ins [cm]
A2: Standort | B2: build | D2: NO_build_plz | E2: Standort des Gebäudes (PLZ) | G2: Freifeld | J2: Integer | K2: 1 | P2: 67435
A3: Gebäudetyp | B3: build | D3: TYP_build | E3: Das Gebäude ist ein… | G3: Radio Button + Grafik | J3: String | K3: 1 | P3: Ein- oder Zweifamilienhaus
A4: Baujahr des Gebäudes | B4: build | D4: TYP_roof | E4: Dachform | G4: Radio Button + Grafik | J4: String | K4: 1 | P4: steil | W4: geneigt: 25°, steil: 40°, sehr steil: 55°
B5: build | D5: YEAR_build_bj | E5: Baujahr | G5: Dropdown | J5: Integer | K5: 1 | P5: 1979 - 1983
B6: build | C6: san | E6: Wurde eines der folgenden Bauteile nachträglich gedämmt / ausgetauscht? ... und ist das Modernisierungsjahr ... Dämmstärke (Freifeld Integer, cm)
B7: build | C7: san | D7: _build_wall_san | E7: Außenwand | G7: siehe Mockups | K7: 0 | Q7: Nein | R7: {=_xlfn.IFS(AND(RIGHT($P$5,4)<="1978",$Q$7="Ja"),Daten!$M$65,AND(RIGHT($P$5,4)>"1978",$Q$7="Ja"),Daten!$M$66,$Q$7="Nein",$P$5)} -> 1979 - 1983 | S7: =$R7 -> 1979 - 1983 | T7: {=IF(Q7="Ja",_xlfn.XLOOKUP(1, (UWert_Mod[Bauteil]=E7)*(UWert_Mod[Modernisierungsjahr]=S7), UWert_Mod[d_ins]),0)} -> 0 | U7: =$T7 -> 0
B8: build | C8: san | D8: _build_win_san | E8: Fenster | G8: siehe Mockups | K8: 0 | Q8: Nein | R8: {=_xlfn.IFS(AND(RIGHT($P$5,4)<="1978",$Q$8="Ja"),Daten!$M$66,AND(RIGHT($P$5,4)>"1978",$Q$8="Ja"),U_Werte_IWU!$D$78,$Q$8="Nein",$P$5)} -> 1979 - 1983 | S8: ab 2023
B9: build | C9: san | D9: _build_roof_san | E9: Dach | G9: siehe Mockups | K9: 0 | Q9: Nein | R9: {=_xlfn.IFS(AND(RIGHT($P$5,4)<="1978",$Q$9="Ja"),Daten!$M$65,AND(RIGHT($P$5,4)>"1978",$Q$9="Ja"),Daten!$M$66,$Q$9="Nein",$P$5)} -> 1979 - 1983 | S9: ab 2023 | T9: {=IF(Q9="Ja",_xlfn.XLOOKUP(1, (UWert_Mod[Bauteil]=E9)*(UWert_Mod[Modernisierungsjahr]=S9), UWert_Mod[d_ins]),0)} -> 0 | U9: =$T9 -> 0
B10: build | C10: san | D10: _build_botceil_san | E10: Fußboden | G10: siehe Mockups | K10: 0 | Q10: Nein | R10: {=_xlfn.IFS(AND(RIGHT($P$5,4)<="1978",$Q$10="Ja"),Daten!$M$77,AND(RIGHT($P$5,4)>"1978",$Q$10="Ja"),Daten!$M$78,$Q$10="Nein",$P$5)} -> 1979 - 1983 | S10: 2003 - 2008 | T10: {=IF(Q10="Ja",_xlfn.XLOOKUP(1, (UWert_Mod[Bauteil]=E10)*(UWert_Mod[Modernisierungsjahr]=S10), UWert_Mod[d_ins]),0)} -> 0 | U10: =$T10 -> 0
B11: build | C11: san | D11: _build_topceil_san | E11: Decke | G11: siehe Mockups | K11: 0 | Q11: Nein | R11: {=_xlfn.IFS(AND(RIGHT($P$5,4)<="1978",$Q$11="Ja"),Daten!$M$65,AND(RIGHT($P$5,4)>"1978",$Q$11="Ja"),Daten!$M$66,$Q$11="Nein",$P$5)} -> 1979 - 1983 | S11: =$R11 -> 1979 - 1983 | T11: {=IF(Q11="Ja",_xlfn.XLOOKUP(1, (UWert_Mod[Bauteil]=E11)*(UWert_Mod[Modernisierungsjahr]=S11), UWert_Mod[d_ins]),0)} -> 0 | U11: =$T11 -> 0
B12: build | D12: EXIST_build_eff | E12: Ist Ihnen die Effizienzklasse bekannt? | G12: Dropdown | K12: 0 | O12: Nicht bekannt | P12: =$O$12 -> Nicht bekannt
A13: Denkmalschutz | B13: build | D13: EXIST_build_denkmal | E13: Das Gebäude steht unter Denkmalschutz | G13: toggle switch | K13: 1 | O13: Nein | P13: =$O$13 -> Nein
A14: Wärmeübergabe | B14: build | D14: TYP_build_rad | E14: Wie werden die Räume erwärmt? | G14: Radio Button + Grafik | K14: 1 | P14: Heizkörper
B15: build | D15: TYP_distr | E15: Wie wird die Wärme verteilt? | G15: Radio Button | K15: 1 | P15: Zweirohrheizung
B16: build | D16: EXIST_T_VL_set | E16: Ich weiß auf welche Vorlauftemperatur am Auslegungspunkt die Heizung eingestellt ist | G16: toggle switch | J16: Boolean | K16: 1 | P16: Nein
B17: build | D17: T_VL_nom_set | E17: Vorlauftemperatur am Auslegungspunkt | G17: Freifeld | H17: EXIST_T_VL_set | I17: °C | J17: Integer | K17: 1 | M17: 30 | N17: 90
B18: build | D18: EXIST_T_VL_meas | E18: Ich kann im Heizungsraum die Vorlauftemperatur ablesen und die Außentemperatur messen | G18: toggle switch | K18: 1 | P18: Ja
B19: build | D19: T_VL_meas | E19: Bitte tragen Sie die Vorlauftemperatur ein | G19: Freifeld | H19: EXIST_T_VL_meas | I19: °C | J19: Integer | K19: 1 | M19: 30 | N19: 90 | P19: 70
B20: build | D20: T_amb_meas | E20: Bitte tragen Sie die Außentemperatur ein | G20: Freifeld | H20: EXIST_T_VL_meas | I20: °C | J20: Integer | K20: 1 | M20: -20 | N20: 40 | P20: -5
B21: build | D21: INTERN_T_VL_nom_calc | H21: EXIST_T_VL_meas | I21: °C | J21: Integer | P21: =P20*-1.8257+43.457+P20 -> 47.5855
D22: INTERN_EXIST_T_VL_nt | H22: EXIST_T_VL_meas | J22: Boolean | P22: =IF(P16="Ja",P17<=55,IF(P18="Ja",P19<P21,FALSE)) -> FALSE
B25: >>> Filterung EXIST_T_VL_set und EXIST_T_VL_meas in Frontend umsetzen >>>
B26: >>> Filterung Räume / list_rooms in Frontend umsetzen >>>

Sheet IN_rooms
A1: Anmerkung (ifeu) | B1: Bauteil (ifeu intern) | C1: Frage (ifeu intern) | D1: Gruppe | E1: Subgruppe | F1: Variable | G1: Fragentext | H1: Hilfstext | I1: Antworttyp | J1: Filter | K1: Einheit | L1: Datentyp | M1: Pflichtfeld | N1: Nachkommastellen | O1: min Wert | P1: max Wert | Q1: Wert intern | R1: Wert Räume --> | S1: Wert Räume --> | T1: Wert Räume --> | U1: Wert Räume --> | V1: Wert Räume --> | W1: Wert Räume --> | X1: Wert Räume --> | Y1: Wert Räume --> | Z1: Wert Räume --> | AA1: Wert Räume --> | AB1: Wert Räume --> | AC1: Wert Räume --> | AD1: Wert Räume --> | AE1: Wert Räume --> | AF1: Wert Räume -->
C2: Raumindex | F2: ID_R# | I2: Intern | L2: String | R2: 1 | S2: 2 | T2: 3 | U2: 4 | V2: 5 | W2: 6 | X2: 7 | Y2: 8 | Z2: 9 | AA2: 10 | AB2: 11 | AC2: 12 | AD2: 13 | AE2: 14 | AF2: 15
A3: >> Name kommt aus list_rooms, aber als Ausgabegröße relevant | C3: Raumbezeichnung | F3: TXT_room_name | G3: Name des Raums | I3: Ausgabe | L3: String | R3: Sonstige | S3: Sonstige | T3: Sonstige | U3: Sonstige | V3: Sonstige | W3: Sonstige | X3: Sonstige | Y3: Sonstige | Z3: Sonstige | AA3: Sonstige | AB3: Sonstige | AC3: Sonstige | AD3: Sonstige | AE3: Sonstige | AF3: Sonstige
C4: Wohnfläche | F4: A_floor | G4: Raumfläche | I4: Freitext | K4: m² | L4: Real | M4: 1 | N4: 1 | O4: 1 | P4: 100 | R4: 20 | S4: 21 | T4: 22 | U4: 23 | V4: 24 | W4: 25 | X4: 26 | Y4: 27 | Z4: 28 | AA4: 29 | AB4: 30 | AC4: 31 | AD4: 32 | AE4: 33 | AF4: 34
C5: Raumhöhe | F5: L_hei | G5: Raumhöhe | I5: Freitext | K5: m | L5: Real | M5: 1 | N5: 2 | O5: 1 | P5: 5 | Q5: 2.5 | R5: =$Q$5 -> 2.5 | S5: =$Q$5 -> 2.5 | T5: =$Q$5 -> 2.5 | U5: =$Q$5 -> 2.5 | V5: =$Q$5 -> 2.5 | W5: =$Q$5 -> 2.5 | X5: =$Q$5 -> 2.5 | Y5: =$Q$5 -> 2.5 | ... AF5: =$Q$5 -> 2.5
C6: Gewünschte Raumtemperatur | F6: T_air_set | G6: gewünsche Raumtemperatur | H6: Es werden typischerweise 20°C in Wohnräumen und 24°C in Bädern angesetzt. Ihre Eigenen Komforttemperaturen können davon abweichen. | I6: Freitext | K6: °C | L6: Integer | N6: 0 | O6: 10 | P6: 30 | Q6: 20 | R6: =$Q6 -> 20 | S6: =$Q6 -> 20 | T6: =$Q6 -> 20 | U6: =$Q6 -> 20 | V6: =$Q6 -> 20 | W6: =$Q6 -> 20 | X6: =$Q6 -> 20 | Y6: =$Q6 -> 20 | ... AF6: =$Q6 -> 20
B7: Decke | C7: Grenzt an | D7: topceil | F7: TYP_V_above | G7: Decke grenzt an | I7: Dropdown | J7: TYP_roof =! "Flach bzw. Flachdach" | L7: String | M7: 1 | Q7: unbeheizt | R7: =$Q7 -> unbeheizt | S7: =$Q7 -> unbeheizt | T7: =$Q7 -> unbeheizt | U7: =$Q7 -> unbeheizt | V7: =$Q7 -> unbeheizt | W7: =$Q7 -> unbeheizt | X7: =$Q7 -> unbeheizt | Y7: =$Q7 -> unbeheizt | ... AF7: =$Q7 -> unbeheizt
B8: Fußboden | C8: Grenzt an | D8: botceil | F8: TYP_V_below | G8: Fußboden grenzt an | I8: Dropdown | L8: String | M8: 1 | Q8: unbeheizt | R8: =$Q8 -> unbeheizt | S8: =$Q8 -> unbeheizt | T8: =$Q8 -> unbeheizt | U8: =$Q8 -> unbeheizt | V8: =$Q8 -> unbeheizt | W8: =$Q8 -> unbeheizt | X8: =$Q8 -> unbeheizt | Y8: =$Q8 -> unbeheizt | ... AF8: =$Q8 -> unbeheizt
B9: Außenwand | C9: Länge | D9: wall | F9: L_wall_tot | G9: Gesamtlänge der Außenwände | I9: Freitext | K9: m | L9: Real | M9: 1 | N9: 2 | O9: 1 | P9: 20 | R9: 5 | S9: 6 | T9: 7 | U9: 8 | V9: 9 | W9: 10 | X9: 11 | Y9: 12 | Z9: 13 | AA9: 14 | AB9: 15 | AC9: 16 | AD9: 17 | AE9: 18 | AF9: 19
D10: wall | F10: YEAR_wall_ins | G10: Abweichendes Modernisierungsjahr | I10: Dropdown | L10: Integer | M10: 0 | N10: 0 | Q10: =IF(IN_build!Q7="Ja",IN_build!$S$7,IN_build!$P$5) -> 1979 - 1983 | R10: =$Q10 -> 1979 - 1983 | S10: =$Q10 -> 1979 - 1983 | T10: =$Q10 -> 1979 - 1983 | U10: =$Q10 -> 1979 - 1983 | V10: =$Q10 -> 1979 - 1983 | W10: =$Q10 -> 1979 - 1983 | X10: =$Q10 -> 1979 - 1983 | Y10: =$Q10 -> 1979 - 1983 | ... AF10: =$Q10 -> 1979 - 1983
A11: Anpassung Berechnung U-Wert: über IWU Tablua anstatt Dämmschichtdicke? Oder Dämmschichtdicke anhand Jahr Modernisierung (Tabelle unten)? Oder EnEV/GEG Vorgaben und anhand Novellen? >> Peter: es gibt Input GEMOD | B11: Außenwand | C11: Von Gebäude abweichende Dämmschicht? | D11: wall | F11: L_wall_ins | G11: Abweichende Dämmstärke? | I11: Freitext | J11: EXIST_build_wall_san | K11: cm | L11: Real | N11: 2 | O11: 0 | P11: 50 | R11: {=IF(R10=IN_build!$P$5, 0, _xlfn.XLOOKUP(1, (INDIRECT("UWert_Mod[Bauteil]")="Außenwand") * (INDIRECT("UWert_Mod[Modernisierungsjahr]")=R10), INDIRECT("UWert_Mod[d_ins]") ))} -> 0 | S11: {=IF(S10=IN_build!$P$5, 0, _xlfn.XLOOKUP(1, (INDIRECT("UWert_Mod[Bauteil]")="Außenwand") * (INDIRECT("UWert_Mod[Modernisierungsjahr]")=S10), INDIRECT("UWert_Mod[d_ins]") ))} -> 0 | T11: {=IF(T10=IN_build!$P$5, 0, _xlfn.XLOOKUP(1, (INDIRECT("UWert_Mod[Bauteil]")="Außenwand") * (INDIRECT("UWert_Mod[Modernisierungsjahr]")=T10), INDIRECT("UWert_Mod[d_ins]") ))} -> 0 | U11: {=IF(U10=IN_build!$P$5, 0, _xlfn.XLOOKUP(1, (INDIRECT("UWert_Mod[Bauteil]")="Außenwand") * (INDIRECT("UWert_Mod[Modernisierungsjahr]")=U10), INDIRECT("UWert_Mod[d_ins]") ))} -> 0 | V11: {=IF(V10=IN_build!$P$5, 0, _xlfn.XLOOKUP(1, (INDIRECT("UWert_Mod[Bauteil]")="Außenwand") * (INDIRECT("UWert_Mod[Modernisierungsjahr]")=V10), INDIRECT("UWert_Mod[d_ins]") ))} -> 0 | W11: {=IF(W10=IN_build!$P$5, 0, _xlfn.XLOOKUP(1, (INDIRECT("UWert_Mod[Bauteil]")="Außenwand") * (INDIRECT("UWert_Mod[Modernisierungsjahr]")=W10), INDIRECT("UWert_Mod[d_ins]") ))} -> 0 | X11: {=IF(X10=IN_build!$P$5, 0, _xlfn.XLOOKUP(1, (INDIRECT("UWert_Mod[Bauteil]")="Außenwand") * (INDIRECT("UWert_Mod[Modernisierungsjahr]")=X10), INDIRECT("UWert_Mod[d_ins]") ))} -> 0 | Y11: {=IF(Y10=IN_build!$P$5, 0, _xlfn.XLOOKUP(1, (INDIRECT("UWert_Mod[Bauteil]")="Außenwand") * (INDIRECT("UWert_Mod[Modernisierungsjahr]")=Y10), INDIRECT("UWert_Mod[d_ins]") ))} -> 0 | ... AF11: {=IF(AF10=IN_build!$P$5, 0, _xlfn.XLOOKUP(1, (INDIRECT("UWert_Mod[Bauteil]")="Außenwand") * (INDIRECT("UWert_Mod[Modernisierungsjahr]")=AF10), INDIRECT("UWert_Mod[d_ins]") ))} -> 0
A12: Vorschlag: bei Außenwand immer Außenluft ansetzen? Kellerraum =! Schlechtpunkt, aber ggf. AW gegen unbeheizt? | B12: Außenwand Art | D12: intern | F12: INTERN_TYP_wall_grenztan_intern | Q12: Außenluft | R12: =$Q12 -> Außenluft | S12: =$Q12 -> Außenluft | T12: =$Q12 -> Außenluft | U12: =$Q12 -> Außenluft | V12: =$Q12 -> Außenluft | W12: =$Q12 -> Außenluft | X12: =$Q12 -> Außenluft | Y12: =$Q12 -> Außenluft | ... AF12: =$Q12 -> Außenluft
B13: Fenstertyp 1 | C13: Breite | D13: wall | E13: win1 | F13: ="L_"&D13&"_"&E13&"_wid" -> L_wall_win1_wid | G13: Geben Sie die Abmaße des Fenstertyps an, Breite | I13: Freitext | K13: cm | L13: Real | M13: 1 | N13: 0 | O13: 20 | P13: 400
B14: Fenstertyp 1 | C14: Höhe | D14: wall | E14: win1 | F14: ="L_"&D14&"_"&E14&"_hei" -> L_wall_win1_hei | G14: Höhe | I14: Freitext | K14: cm | L14: Real | M14: 1 | N14: 0 | O14: 20 | P14: =$R$5*100 -> 250
A15: siehe YEAR_wall_ins | B15: Fenstertyp 1 | C15: Jahr, in dem die Fenster zuletzt ausgetauscht wurden | D15: wall | E15: win1 | F15: ="YEAR_"&D15&"_"&E15 -> YEAR_wall_win1 | G15: Abweichendes Einbaujahr | I15: Dropdown | L15: Integer | M15: 0 | Q15: =IN_build!$S$8 -> ab 2023 | R15: 2009 - 2022 | S15: 2010 - 2022 | T15: 2011 - 2022 | U15: 2012 - 2022 | V15: 2013 - 2022 | W15: 2014 - 2022 | X15: 2015 - 2022 | Y15: 2016 - 2022 | Z15: 2017 - 2022 | AA15: 2018 - 2022 | AB15: 2019 - 2022 | AC15: 2020 - 2022 | AD15: 2021 - 2022 | AE15: 2022 - 2022 | AF15: 2023 - 2022
A16: Multiplikator aufnehmen | B16: Fenstertyp 1 | C16: Anzahl | D16: wall | E16: win1 | F16: ="NO_"&D16&"_"&E16 -> NO_wall_win1 | G16: Anzahl identischer Fenster im Raum | I16: Freitext | L16: Integer | M16: 0 | N16: 0 | O16: 1 | P16: 10 | Q16: 1 | R16: =$Q16 -> 1 | S16: =$Q16 -> 1 | T16: =$Q16 -> 1 | U16: =$Q16 -> 1 | V16: =$Q16 -> 1 | W16: =$Q16 -> 1 | X16: =$Q16 -> 1 | Y16: =$Q16 -> 1 | ... AF16: =$Q16 -> 1
B17: Fenstertyp 2 | C17: Breite | D17: wall | E17: win2 | F17: ="L_"&D17&"_"&E17&"_wid" -> L_wall_win2_wid | G17: Geben Sie die Abmaße des Fenstertyps an, Breite | I17: Freitext | K17: cm | L17: Real | M17: 1 | N17: 0 | O17: 20 | P17: 400
B18: Fenstertyp 2 | C18: Höhe | D18: wall | E18: win2 | F18: ="L_"&D18&"_"&E18&"_hei" -> L_wall_win2_hei | G18: Höhe | I18: Freitext | K18: cm | L18: Real | M18: 1 | N18: 0 | O18: 20 | P18: =$R$5*100 -> 250
B19: Fenstertyp 2 | C19: Jahr, in dem die Fenster zuletzt ausgetauscht wurden | D19: wall | E19: win2 | F19: ="YEAR_"&D19&"_"&E19 -> YEAR_wall_win2 | G19: Abweichendes Einbaujahr | I19: Dropdown | L19: Integer | M19: 0 | Q19: =IN_build!$S$8 -> ab 2023 | R19: 2009 - 2022 | S19: 2010 - 2022 | T19: 2011 - 2022 | U19: 2012 - 2022 | V19: 2013 - 2022 | W19: 2014 - 2022 | X19: 2015 - 2022 | Y19: 2016 - 2022 | Z19: 2017 - 2022 | AA19: 2018 - 2022 | AB19: 2019 - 2022 | AC19: 2020 - 2022 | AD19: 2021 - 2022 | AE19: 2022 - 2022 | AF19: 2023 - 2022
A20: Multiplikator aufnehmen | B20: Fenstertyp 2 | D20: wall | E20: win2 | F20: ="NO_"&D20&"_"&E20 -> NO_wall_win2 | G20: Anzahl identischer Fenster im Raum | I20: Freitext | L20: Integer | M20: 0 | N20: 0 | O20: 1 | P20: 10 | Q20: 1 | R20: =$Q20 -> 1 | S20: =$Q20 -> 1 | T20: =$Q20 -> 1 | U20: =$Q20 -> 1 | V20: =$Q20 -> 1 | W20: =$Q20 -> 1 | X20: =$Q20 -> 1 | Y20: =$Q20 -> 1 | ... AF20: =$Q20 -> 1
B21: Fenstertyp 3 | C21: Breite | D21: wall | E21: win3 | F21: ="L_"&D21&"_"&E21&"_wid" -> L_wall_win3_wid | G21: Geben Sie die Abmaße des dritten Fenstertyps an, Breite | I21: Freitext | K21: cm | L21: Real | M21: 1 | N21: 0 | O21: 20 | P21: 400
B22: Fenstertyp 3 | C22: Höhe | D22: wall | E22: win3 | F22: ="L_"&D22&"_"&E22&"_hei" -> L_wall_win3_hei | G22: Höhe | I22: Freitext | K22: cm | L22: Real | M22: 1 | N22: 0 | O22: 20 | P22: =$R$5*100 -> 250
B23: Fenstertyp 3 | C23: Jahr, in dem die Fenster zuletzt ausgetauscht wurden | D23: wall | E23: win3 | F23: ="YEAR_"&D23&"_"&E23 -> YEAR_wall_win3 | G23: Abweichendes Einbaujahr | I23: Dropdown | L23: Integer | M23: 0 | Q23: =IN_build!$S$8 -> ab 2023 | R23: =$Q$23 -> ab 2023 | S23: =$Q$23 -> ab 2023 | T23: =$Q$23 -> ab 2023 | U23: =$Q$23 -> ab 2023 | V23: =$Q$23 -> ab 2023 | W23: =$Q$23 -> ab 2023 | X23: =$Q$23 -> ab 2023 | Y23: =$Q$23 -> ab 2023 | ... AF23: =$Q$23 -> ab 2023
A24: Multiplikator aufnehmen | B24: Fenstertyp 3 | C24: Anzahl | D24: wall | E24: win3 | F24: ="NO_"&D24&"_"&E24 -> NO_wall_win3 | G24: Anzahl identischer Fenster im Raum | I24: Freitext | L24: Integer | M24: 0 | N24: 0 | O24: 1 | P24: 10 | Q24: 1 | R24: =$Q24 -> 1 | S24: =$Q24 -> 1 | T24: =$Q24 -> 1 | U24: =$Q24 -> 1 | V24: =$Q24 -> 1 | W24: =$Q24 -> 1 | X24: =$Q24 -> 1 | Y24: =$Q24 -> 1 | ... AF24: =$Q24 -> 1
D25: innerwall | F25: EXIST_innerwall | G25: Innenwände gegen unbeheizt vorhanden? | I25: toggle switch | L25: Boolean | M25: 1 | Q25: Nein | R25: =$Q25 -> Nein | S25: =$Q25 -> Nein | T25: =$Q25 -> Nein | U25: =$Q25 -> Nein | V25: =$Q25 -> Nein | W25: =$Q25 -> Nein | X25: =$Q25 -> Nein | Y25: =$Q25 -> Nein | ... AF25: =$Q25 -> Nein
D26: innerwall | F26: L_innerwall_tot | G26: Gesamtlänge der Innenwände gegen unbeheizte Räume | I26: Freitext | J26: EXIST_innerwall | K26: m | L26: Real | M26: 0 | N26: 2 | O26: 1 | P26: 20
D27: innerwall | F27: L_innerwall_ins | G27: Dämmung vorhanden? | I27: Freitext | J27: EXIST_innerwall | K27: cm | L27: Real | M27: 0 | N27: 0 | O27: 0 | P27: 50 | Q27: 0 | R27: =$Q$27 -> 0 | S27: =$Q$27 -> 0 | T27: =$Q$27 -> 0 | U27: =$Q$27 -> 0 | V27: =$Q$27 -> 0 | W27: =$Q$27 -> 0 | X27: =$Q$27 -> 0 | Y27: =$Q$27 -> 0 | ... AF27: =$Q$27 -> 0
B28: Dachfläche | D28: roof | F28: EXIST_roof | G28: Dachschräge vorhanden? | I28: toggle switch | L28: Boolean | M28: 1 | Q28: =IF(IN_build!$P$4="Flach bzw. Flachdach","Nein","Ja") -> Ja | R28: =$Q$28 -> Ja | S28: =$Q$28 -> Ja | T28: =$Q$28 -> Ja | U28: =$Q$28 -> Ja | V28: =$Q$28 -> Ja | W28: =$Q$28 -> Ja | X28: =$Q$28 -> Ja | Y28: =$Q$28 -> Ja | ... AF28: =$Q$28 -> Ja
B29: Dachfläche | D29: roof | F29: NO_roof_slop | G29: Hat der Raum mehr als 1 Dachschräge? | I29: toggle switch | L29: Boolean | M29: 1 | Q29: Nein | R29: =$Q$29 -> Nein | S29: =$Q$29 -> Nein | T29: =$Q$29 -> Nein | U29: =$Q$29 -> Nein | V29: =$Q$29 -> Nein | W29: =$Q$29 -> Nein | X29: =$Q$29 -> Nein | Y29: =$Q$29 -> Nein | ... AF29: =$Q$29 -> Nein
B30: Dachfläche | C30: Breite | D30: roof | F30: L_roof_wid | G30: Länge | H30: Bei mehreren Dachflächen bitte summieren | I30: Freitext | J30: EXIST_roof | K30: m | L30: Real | M30: 0 | N30: 2 | O30: 1 | R30: 4 | S30: 4 | T30: 4 | U30: 4 | V30: 4 | W30: 4 | X30: 4 | Y30: 4 | Z30: 4 | AA30: 4 | AB30: 4 | AC30: 4 | AD30: 4 | AE30: 4 | AF30: 4
B31: Dachfläche | C31: Höhe | D31: roof | F31: L_roof_hei | G31: Höhe | H31: Bei mehreren Dachflächen bitte nicht summieren | I31: Freitext | J31: EXIST_roof | K31: m | L31: Real | M31: 0 | N31: 2 | O31: 1 | P31: 4 | R31: 3 | S31: 3 | T31: 3 | U31: 3 | V31: 3 | W31: 3 | X31: 3 | Y31: 3 | Z31: 3 | AA31: 3 | AB31: 3 | AC31: 3 | AD31: 3 | AE31: 3 | AF31: 3
D32: topceil | F32: ="L_"&D32&"_"&E32&"_wid" -> L_topceil__wid | G32: Ist eine horizontale Decke vorhanden? Geben Sie bitte Breite und Länge an | I32: Freitext | J32: TYP_roof =/ "Flach bzw. Flachdach" | K32: m | L32: String | M32: 1
D33: topceil | F33: ="L_"&D33&"_"&E33&"_len" -> L_topceil__len | G33: Ist eine horizontale Decke vorhanden? Geben Sie bitte Breite und Länge an | I33: Freitext | J33: TYP_roof =/ "Flach bzw. Flachdach" | K33: m | L33: String | M33: 1
B34: Dachfläche | D34: roof | F34: L_roof_jamb_hei | G34: Falls eine Drempelwand bzw. Kniestock vorhanden ist, geben Sie die Höhe an | I34: Freitext | J34: EXIST_roof | K34: m | L34: Real | M34: 1 | N34: 2 | Q34: 0 | R34: =$Q$34 -> 0 | S34: =$Q$34 -> 0 | T34: =$Q$34 -> 0 | U34: =$Q$34 -> 0 | V34: =$Q$34 -> 0 | W34: =$Q$34 -> 0 | X34: =$Q$34 -> 0 | Y34: =$Q$34 -> 0 | ... AF34: =$Q$34 -> 0
B35: Dachfläche | D35: roof | F35: TYP_jamb_hei | G35: Klopfen Sie gegen die senkrechte Wand unter der Dachschräge. Klingt es hohl? | I35: toggle switch | J35: EXIST_roof | L35: Boolean | M35: 1 | Q35: Ja | R35: Ja | S35: Ja | T35: Ja | U35: Ja | V35: Ja | W35: Ja | X35: Ja | Y35: Ja | Z35: Ja | AA35: Ja | AB35: Ja | AC35: Ja | AD35: Ja | AE35: Ja | AF35: Ja
B36: Dachfläche | D36: intern | F36: EXIST_roof_knee_intern | G36: INTERN - Haben sie einen Kniestock unter der Dachschräge? | I36: toggle switch | J36: EXIST_roof | L36: Boolean | M36: 1 | R36: =IF(R$35="Nein","Ja","Nein") -> Nein | S36: =IF(S$35="Nein","Ja","Nein") -> Nein | T36: =IF(T$35="Nein","Ja","Nein") -> Nein | U36: =IF(U$35="Nein","Ja","Nein") -> Nein | V36: =IF(V$35="Nein","Ja","Nein") -> Nein | W36: =IF(W$35="Nein","Ja","Nein") -> Nein | X36: =IF(X$35="Nein","Ja","Nein") -> Nein | Y36: =IF(Y$35="Nein","Ja","Nein") -> Nein | ... AF36: =IF(AF$35="Nein","Ja","Nein") -> Nein
A37: Einbezug Berechnung in DIN12831 klären | B37: Dachfläche | C37: Höhe | D37: intern | F37: L_roof_knee_hei_intern | G37: INTERN - Falls ein Kniestock vorhanden ist, geben Sie dessen Höhe an | I37: Freitext | J37: EXIST_roof_knee | K37: m | L37: Real | M37: 0 | N37: 2 | O37: 0 | P37: 3 | R37: =IF(R$35="Ja",0,R$34) -> 0 | S37: =IF(S$35="Ja",0,S$34) -> 0 | T37: =IF(T$35="Ja",0,T$34) -> 0 | U37: =IF(U$35="Ja",0,U$34) -> 0 | V37: =IF(V$35="Ja",0,V$34) -> 0 | W37: =IF(W$35="Ja",0,W$34) -> 0 | X37: =IF(X$35="Ja",0,X$34) -> 0 | Y37: =IF(Y$35="Ja",0,Y$34) -> 0 | ... AF37: =IF(AF$35="Ja",0,AF$34) -> 0
B38: Dachfläche | D38: intern | F38: EXIST_roof_jamb_intern | G38: INTERN - Haben sie einen Drempel unter der Dachschräge? | H38: Klopfen sie gegen die senkrechte Wand unter der Dachscrhräge. Klingt es hohl, haben sie einen Drempel. | I38: toggle switch | J38: EXIST_roof | L38: Boolean | M38: 1 | R38: =IF(R$35="Nein","Nein","Ja") -> Ja | S38: =IF(S$35="Nein","Nein","Ja") -> Ja | T38: =IF(T$35="Nein","Nein","Ja") -> Ja | U38: =IF(U$35="Nein","Nein","Ja") -> Ja | V38: =IF(V$35="Nein","Nein","Ja") -> Ja | W38: =IF(W$35="Nein","Nein","Ja") -> Ja | X38: =IF(X$35="Nein","Nein","Ja") -> Ja | Y38: =IF(Y$35="Nein","Nein","Ja") -> Ja | ... AF38: =IF(AF$35="Nein","Nein","Ja") -> Ja
B39: Dachfläche | C39: Höhe | D39: intern | F39: L_roof_jamb_hei_intern | G39: INTERN - Falls ein Drempel vorhanden ist, geben Sie dessen Höhe an | H39: Der Drempel beschreibt im Dachbereich die Höhe der leichten Trennwand zwischen Fußboden und Beginn des Dachs. | I39: Freitext | J39: EXIST_roof_jamb | K39: m | L39: Real | M39: 0 | N39: 2 | O39: 0 | P39: 3 | R39: =IF(R$35="Nein",0,R$34) -> 0 | S39: =IF(S$35="Nein",0,S$34) -> 0 | T39: =IF(T$35="Nein",0,T$34) -> 0 | U39: =IF(U$35="Nein",0,U$34) -> 0 | V39: =IF(V$35="Nein",0,V$34) -> 0 | W39: =IF(W$35="Nein",0,W$34) -> 0 | X39: =IF(X$35="Nein",0,X$34) -> 0 | Y39: =IF(Y$35="Nein",0,Y$34) -> 0 | ... AF39: =IF(AF$35="Nein",0,AF$34) -> 0
B40: Gaube | D40: roof | E40: dormer | F40: EXIST_dormer | G40: Ist eine Gaube in der Dachschräge vorhanden? | I40: toggle switch | L40: Boolean | M40: 1 | Q40: Nein | R40: Ja | S40: Ja | T40: Ja | U40: Ja | V40: Ja | W40: Ja | X40: Ja | Y40: Ja | Z40: Ja | AA40: Ja | AB40: Ja | AC40: Ja | AD40: Ja | AE40: Ja | AF40: Ja
...

Sheet clc_load
A1: Bauteil IWU | B1: Bezeichnung | C1: delete | D1: Gruppe | E1: Subgruppe | F1: Variable | G1: Einheit | H1: Erläuterung | I1: Kommentar | J1: Todo | K1: Intern | L1: Output | M1: Wert Räume -->
D2: Raumindex | F2: ID_R# | M2: =IN_rooms!R2 -> 1 | N2: =IN_rooms!S2 -> 2 | O2: =IN_rooms!T2 -> 3 | P2: =IN_rooms!U2 -> 4 | Q2: =IN_rooms!V2 -> 5 | R2: =IN_rooms!W2 -> 6 | S2: =IN_rooms!X2 -> 7 | T2: =IN_rooms!Y2 -> 8 | ... AA2: =IN_rooms!AF2 -> 15
B3: Gebäudetyp | F3: TYP_build | M3: =IN_build!$P$3 -> Ein- oder Zweifamilienhaus | N3: =IN_build!$P$3 -> Ein- oder Zweifamilienhaus | O3: =IN_build!$P$3 -> Ein- oder Zweifamilienhaus | P3: =IN_build!$P$3 -> Ein- oder Zweifamilienhaus | Q3: =IN_build!$P$3 -> Ein- oder Zweifamilienhaus | R3: =IN_build!$P$3 -> Ein- oder Zweifamilienhaus | S3: =IN_build!$P$3 -> Ein- oder Zweifamilienhaus | T3: =IN_build!$P$3 -> Ein- oder Zweifamilienhaus | ... AA3: =IN_build!$P$3 -> Ein- oder Zweifamilienhaus
B4: Baujahr | F4: YEAR_build_bj | M4: =IN_build!$P$5 -> 1979 - 1983 | N4: =IN_build!$P$5 -> 1979 - 1983 | O4: =IN_build!$P$5 -> 1979 - 1983 | P4: =IN_build!$P$5 -> 1979 - 1983 | Q4: =IN_build!$P$5 -> 1979 - 1983 | R4: =IN_build!$P$5 -> 1979 - 1983 | S4: =IN_build!$P$5 -> 1979 - 1983 | T4: =IN_build!$P$5 -> 1979 - 1983 | ... AA4: =IN_build!$P$5 -> 1979 - 1983
B5: Raumbezeichnung | F5: TXT_room_name | M5: =IN_rooms!R3 -> Sonstige | N5: =IN_rooms!S3 -> Sonstige | O5: =IN_rooms!T3 -> Sonstige | P5: =IN_rooms!U3 -> Sonstige | Q5: =IN_rooms!V3 -> Sonstige | R5: =IN_rooms!W3 -> Sonstige | S5: =IN_rooms!X3 -> Sonstige | T5: =IN_rooms!Y3 -> Sonstige | ... AA5: =IN_rooms!AF3 -> Sonstige
A6: Luftwechsel | B6: Volumen | F6: V_room | G6: m³ | M6: =IN_rooms!R$4*IN_rooms!R$5 -> 50 | N6: =IN_rooms!S$4*IN_rooms!S$5 -> 52.5 | O6: =IN_rooms!T$4*IN_rooms!T$5 -> 55 | P6: =IN_rooms!U$4*IN_rooms!U$5 -> 57.5 | Q6: =IN_rooms!V$4*IN_rooms!V$5 -> 60 | R6: =IN_rooms!W$4*IN_rooms!W$5 -> 62.5 | S6: =IN_rooms!X$4*IN_rooms!X$5 -> 65 | T6: =IN_rooms!Y$4*IN_rooms!Y$5 -> 67.5 | ... AA6: =IN_rooms!AF$4*IN_rooms!AF$5 -> 85
A7: Luftwechsel | B7: Luftwechselrate ni | F7: freq_room_vent | G7: 1/h | I7: JM270425: gibt es hier keine Abhängigkeit? | M7: 0.5 | N7: 0.5 | O7: 0.5 | P7: 0.5 | Q7: 0.5 | R7: 0.5 | S7: 0.5 | T7: 0.5 | U7: 0.5 | V7: 0.5 | W7: 0.5 | X7: 0.5 | Y7: 0.5 | Z7: 0.5 | AA7: 0.5
B8: Wärmebrückenkoeffizient ∆U,TB | F8: qdot_build_conn_trans | G8: W/(mK) | M8: =IF(AND(M$16<=U_GEG_A.7!$C$10, M$28<=AVERAGE(U_GEG_A.7!$C$21:$C$22, M$34<=U_GEG_A.7!$C$21,M$39<=U_GEG_A.7!$C$25), M$45<=U_GEG_A.7!$C$11, M$63<=U_GEG_A.7!$C$12, M$69<=U_GEG_A.7!$C$12), 0.05,0.1) -> 0.1 | N8: =IF(AND(N$16<=U_GEG_A.7!$C$10, N$28<=AVERAGE(U_GEG_A.7!$C$21:$C$22, N$34<=U_GEG_A.7!$C$21,N$39<=U_GEG_A.7!$C$25), N$45<=U_GEG_A.7!$C$11, N$63<=U_GEG_A.7!$C$12, N$69<=U_GEG_A.7!$C$12), 0.05,0.1) -> 0.1 | O8: =IF(AND(O$16<=U_GEG_A.7!$C$10, O$28<=AVERAGE(U_GEG_A.7!$C$21:$C$22, O$34<=U_GEG_A.7!$C$21,O$39<=U_GEG_A.7!$C$25), O$45<=U_GEG_A.7!$C$11, O$63<=U_GEG_A.7!$C$12, O$69<=U_GEG_A.7!$C$12), 0.05,0.1) -> 0.1 | P8: =IF(AND(P$16<=U_GEG_A.7!$C$10, P$28<=AVERAGE(U_GEG_A.7!$C$21:$C$22, P$34<=U_GEG_A.7!$C$21,P$39<=U_GEG_A.7!$C$25), P$45<=U_GEG_A.7!$C$11, P$63<=U_GEG_A.7!$C$12, P$69<=U_GEG_A.7!$C$12), 0.05,0.1) -> 0.1 | Q8: =IF(AND(Q$16<=U_GEG_A.7!$C$10, Q$28<=AVERAGE(U_GEG_A.7!$C$21:$C$22, Q$34<=U_GEG_A.7!$C$21,Q$39<=U_GEG_A.7!$C$25), Q$45<=U_GEG_A.7!$C$11, Q$63<=U_GEG_A.7!$C$12, Q$69<=U_GEG_A.7!$C$12), 0.05,0.1) -> 0.1 | R8: =IF(AND(R$16<=U_GEG_A.7!$C$10, R$28<=AVERAGE(U_GEG_A.7!$C$21:$C$22, R$34<=U_GEG_A.7!$C$21,R$39<=U_GEG_A.7!$C$25), R$45<=U_GEG_A.7!$C$11, R$63<=U_GEG_A.7!$C$12, R$69<=U_GEG_A.7!$C$12), 0.05,0.1) -> 0.1 | S8: =IF(AND(S$16<=U_GEG_A.7!$C$10, S$28<=AVERAGE(U_GEG_A.7!$C$21:$C$22, S$34<=U_GEG_A.7!$C$21,S$39<=U_GEG_A.7!$C$25), S$45<=U_GEG_A.7!$C$11, S$63<=U_GEG_A.7!$C$12, S$69<=U_GEG_A.7!$C$12), 0.05,0.1) -> 0.1 | T8: =IF(AND(T$16<=U_GEG_A.7!$C$10, T$28<=AVERAGE(U_GEG_A.7!$C$21:$C$22, T$34<=U_GEG_A.7!$C$21,T$39<=U_GEG_A.7!$C$25), T$45<=U_GEG_A.7!$C$11, T$63<=U_GEG_A.7!$C$12, T$69<=U_GEG_A.7!$C$12), 0.05,0.1) -> 0.1 | ... AA8: =IF(AND(AA$16<=U_GEG_A.7!$C$10, AA$28<=AVERAGE(U_GEG_A.7!$C$21:$C$22, AA$34<=U_GEG_A.7!$C$21,AA$39<=U_GEG_A.7!$C$25), AA$45<=U_GEG_A.7!$C$11, AA$63<=U_GEG_A.7!$C$12, AA$69<=U_GEG_A.7!$C$12), 0.05,0.1) -> 0.1
B9: ρ*cp pauschal nach 12831 | F9: Q_build_vent_const | G9: Wh/(m³K) | M9: 0.34 | N9: 0.34 | O9: 0.34 | P9: 0.34 | Q9: 0.34 | R9: 0.34 | S9: 0.34 | T9: 0.34 | U9: 0.34 | V9: 0.34 | W9: 0.34 | X9: 0.34 | Y9: 0.34 | Z9: 0.34 | AA9: 0.34
