Workbook
Name Deckenheizung: #REF!
Name DropdownlisteHeizungsrohre: #REF!
Name DropdownlisteHeizungsrohre: #REF!
Name Flachheizkörper: Flachheizkoerper_senkrecht_profiliert[Flachheizkoerper_senkrecht_profiliert]
Name Fußbodenheizung: #REF!
Name Gewinderohr: Tabelle8[[#All],[Gewinderohr_Hoehe]]
Name Gliederheizkröper: Gliederheizkörper[[#All],[Gliederheizkörper]]
Name HeinzungsrohreDatensaetze: #REF!
Name HeinzungsrohreDatensaetze: #REF!
Name Heizkörpertypen: Heizkoerpertyp[Heizkörpertypen]
Name Konvektor: Tabelle12[Konvektor]
Name lambda_ins_thick: PAR!$B$2
Name Log_ÜT_Norm: 49.83
Name p: "INDEX(PAR[Parameter];1)"
Name Rohrheizkörper: Tabelle11[Rohrheizkörper]
Name Rohrradiator: Tabelle10[Rohrradiator]
Name Rohrradiatoren: Tabelle10[Rohrradiator]
Name Stahlrippenohr: Tabelle29[[#Headers],[Stahlrippenrohr_Hoehe]]
Name Stahlrohr: Tabelle28[[#All],[Stahlrohr_Hoehe]]
Name TRL_Ziel: 45
Name TVL_Ziel: 55
Name Wandheizung: #REF!

Sheet PAR
A1: Bezeichnung | B1: Parameter | C1: Einheit | D1: Beschreibung | E1: Kommentar | F1: Bezeichnung | G1: lambda_ins_thick | H1: U_inwall | I1: T_air_norm | J1: T_air_norm_bath | K1: ang_roof_slop | L1: ang_roof_steep | M1: ang_roof_steepr | N1: U_opaque_lim | O1: U_win_lim | P1: r_worst_lim | Q1: NO_round_Qdot | R1: NO_round_Qdot_spez | S1: NO_round_rcover | T1: f_A_wall_wid | U1: f_A_wall_hei | V1: f_A_roof_wid | W1: f_A_roof_hei | X1: f_Vroom_roof | Y1: f_Awall_roof
A2: lambda_ins_thick | B2: 0.04 | C2: W/(mK) | D2: Annahme für lambda Wert der nachträglich aufgebrachten Dämmebene | F2: Parameter | G2: 0.04 | H2: 2 | I2: 20 | J2: 24 | K2: 25 | L2: 40 | M2: 55 | N2: 0.8 | O2: 1.7 | P2: 0.2 | Q2: 100 | R2: 5 | S2: 0.1 | T2: 0.5 | U2: 0.3 | V2: 0.25 | W2: 0.3 | X2: 0.7 | Y2: 1.1
A3: T_air_norm | B3: 20 | C3: °C | D3: Norm-Raumtemperatur Standardraum | F3: Einheit | G3: W/(mK) | H3: W/(m²K) | I3: °C | J3: °C | K3: ° | L3: ° | M3: ° | N3: W/(m²K) | O3: W/(m²K) | P3: % | Q3: W | R3: W/m² | S3: % | T3: m | U3: m | V3: m
A4: T_air_norm_bath | B4: 24 | C4: °C | D4: Norm-Raumtemperatur Badezimmer | F4: Beschreibung | G4: Annahme für lambda Wert der nachträglich aufgebrachten Dämmebene | H4: Pauschaler U-Wert Innenwand | I4: Norm-Raumtemperatur Standardraum | J4: Norm-Raumtemperatur Badezimmer | K4: Dachneigung geneigt | L4: Dachneigung steil | M4: Dachneigung sehr steil | N4: Grenzwert U-Wert für Austauschpotenzial opaker Bauteile | O4: Grenzwert U-Wert für Austauschpotenzial Fenster | P4: Mindestanteil eines Bauteils an der Raumheizlast, für Austauschpotenzial | Q4: Genauigkeit Ausgabe Wärmeleistung | R4: Genaugikeit ausgabe spez. Wärmeleistung | S4: Genauigkeit Ausgabe Heizkörper-Deckungsgrad | T4: Zuschlag Wandlänge zur Berücksichtigung Außenmaße vs. erfasste Innenmaße | U4: Zuschlag Wandhöhe zur Berücksichtigung Außenmaße vs. erfasste Innenmaße | V4: Zuschlag Dachbreite zur Berücksichtigung Außenmaße vs. erfasste Innenmaße | W4: Zuschlag Dachhöhe zur Berücksichtigung Außenmaße vs. erfasste Innenmaße | X4: Abschlag Raumvolumen bei Dachräumen | Y4: Pauschaler Vergrößerungsfaktor der Wandflächen in Dachräumen zur Berücksichtigung der Außenfläche (ggü. erfasster Innenfläche)
F5: Kommentar
F10: =INDEX(PAR[T_air_norm],1) -> 20

Sheet Syntax
A2: Syntax Variablen: Größe | Medium | System | Subsystem | Spezifikation | Spezifikation 2
A3: Kursive Kategorien sind optional
B5: Variable | C5: Bezeichnung | D5: Einheit
A6: (phys.) Größe | B6: A | C6: Fläche | D6: m²
B7: B | C7: Zustandsgröße
B8: EXIST | C8: Merkmal vorhanden
B9: freq | C9: Frequenz | D9: 1/h
B10: ID | C10: Identifikationsnummer
B11: lambda | C11: Wärmeleitfähigkeit | D11: W/(mK)
B12: L | C12: Distanz | D12: m
B13: n | C13: Anzahl / Heizkörperexponent
B14: NO | C14: Nummer
B15: Q | C15: Wärmemenge | D15: Wh
B16: q | C16: spez. Wärmemenge
B17: Qdot | C17: Wärmestrom | D17: W
B18: qdot | C18: spez. Wärmeleistung
B19: R | C19: Wärmedurchgangswiderstand | D19: m²K/W
B20: r | C20: Anteil
B21: S | C21: Status
B22: T | C22: Temperatur | D22: °C
B23: Tdif | C23: Temperaturdifferenz | D23: K
B24: TXT | C24: Text
B25: TYP | C25: Art
B26: STYP | C26: Unterart
B27: U | C27: Wärmedurchgangskoeffizient | D27: W/(m²K)
B28: V | C28: Volumen | D28: m³
B29: Vdot | C29: Volumenstrom | D29: m³/h
B30: YEAR | C30: Jahr | D30: -
A36: System/Subsystem | B36: build | C36: Gebäude
B37: room | C37: Raum
B38: wall | C38: Außenwand
B39: heater | C39: Heizkörper
B40: inwall | C40: Innenwand
B41: heatp | C41: Wärmepumpe
B42: rad | C42: Radiator
B43: win | C43: Fenster
B44: roof | C44: Dach
B45: topceil | C45: Decke
B46: botceil | C46: Boden
B47: ins | C47: Dämmung
...

Sheet IN_build
A1: Bezeichnung | B1: Gruppe | C1: Subgruppe | D1: Variable | E1: Fragentext | F1: Hilfstext | G1: Antworttyp | H1: Filter | I1: Einheit | J1: Datentyp | K1: Pflichtfeld | L1: Nachkommastellen | M1: min Wert | N1: max Wert | O1: Wert intern | P1: Wert | Q1: EXIST | R1: YEAR_eff | S1: YEAR | T1: L_ins_eff [cm] | U1: L_ins [cm]
A2: Standort | B2: build | D2: NO_build_plz | E2: Standort des Gebäudes (PLZ) | G2: Freifeld | J2: Integer | K2: 1
A3: Gebäudetyp | B3: build | D3: TYP_build | E3: Das Gebäude ist ein… | F3: PopUp: Der Gebäudetyp hilft dabei, die Bauteile und ihren Wärmedurchlass besser einzuschätzen. | G3: Radio Button + Grafik | J3: String | K3: 1
B4: build | D4: TYP_roof | E4: Dachform | F4: PopUp: Haben Sie ein sehr flach geneigtes Dach, z.B. ein Pultdach, wählen Sie "Flachdach" statt "geneigt" aus. | G4: Radio Button + Grafik | J4: String | K4: 1
B5: build | D5: YEAR_build_bj | E5: Baujahr | G5: Dropdown | J5: Integer | K5: 1
B6: build | C6: san | E6: Wurde eines der folgenden Bauteile nachträglich gedämmt / ausgetauscht? ... und ist das Modernisierungsjahr ... Dämmstärke (Freifeld Integer, cm)
B7: build | C7: san | D7: _build_wall_san | E7: Außenwand | G7: siehe Mockups | K7: 0 | N7: 40 | Q7: Nein | R7: {=IF(S7="",_xlfn.IFS(AND(RIGHT($P$5,4)<="1978",$Q$7="Ja"),Daten!$M$65,AND(RIGHT($P$5,4)>"1978",$Q$7="Ja"),Daten!$M$66,$Q$7="Nein",$P$5),S7)} -> 0 | T7: {=IF(Q7="Ja",IF(U7="",_xlfn.XLOOKUP(1, (UWert_Mod[Bauteil]=E7)*(UWert_Mod[Modernisierungsjahr]=R7), UWert_Mod[d_ins]),U7),0)} -> 0 | W7: =""
B8: build | C8: san | D8: _build_win_san | E8: Fenster | G8: siehe Mockups | K8: 0 | Q8: Nein | R8: {=IF($Q$8="Ja",_xlfn.IFS(S8<>"",S8,RIGHT($P$5,4)<="1978",Daten!$M$66,RIGHT($P$5,4)>"1978",U_Werte_IWU!$D$78),$P$5)} -> 0
B9: build | C9: san | D9: _build_roof_san | E9: Dach | G9: siehe Mockups | K9: 0 | N9: 40 | Q9: Nein | R9: {=IF(S9="",_xlfn.IFS(AND(RIGHT($P$5,4)<="1978",$Q$9="Ja"),Daten!$M$65,AND(RIGHT($P$5,4)>"1978",$Q$9="Ja"),Daten!$M$66,$Q$9="Nein",$P$5),S9)} -> 0 | T9: {=IF(Q9="Ja",IF(U9="",_xlfn.XLOOKUP(1, (UWert_Mod[Bauteil]=E9)*(UWert_Mod[Modernisierungsjahr]=R9), UWert_Mod[d_ins]),U9),0)} -> 0
B10: build | C10: san | D10: _build_botceil_san | E10: Fußboden | G10: siehe Mockups | K10: 0 | N10: 40 | Q10: Nein | R10: {=IF(S10="",_xlfn.IFS(AND(RIGHT($P$5,4)<="1978",$Q$10="Ja"),Daten!$M$77,AND(RIGHT($P$5,4)>"1978",$Q$10="Ja"),Daten!$M$78,$Q$10="Nein",$P$5),S10)} -> 0 | T10: {=IF(Q10="Ja",IF(U10="",_xlfn.XLOOKUP(1, (UWert_Mod[Bauteil]=E10)*(UWert_Mod[Modernisierungsjahr]=R10), UWert_Mod[d_ins]),U10),0)} -> 0
B11: build | C11: san | D11: _build_topceil_san | E11: Decke | F11: Im Haus am höchsten gelegene Decke eines beheizten Raumes. | G11: siehe Mockups | K11: 0 | N11: 40 | Q11: Nein | R11: {=IF(S11="",_xlfn.IFS(AND(RIGHT($P$5,4)<="1978",$Q$11="Ja"),Daten!$M$65,AND(RIGHT($P$5,4)>"1978",$Q$11="Ja"),Daten!$M$66,$Q$11="Nein",$P$5),S11)} -> 0 | T11: {=IF(Q11="Ja",IF(U11="",_xlfn.XLOOKUP(1, (UWert_Mod[Bauteil]=E11)*(UWert_Mod[Modernisierungsjahr]=R11), UWert_Mod[d_ins]),U11),0)} -> 0
B12: build | D12: EXIST_build_eff | E12: Ist Ihnen die Effizienzklasse bekannt? | F12: PopUp: Die Energieeffizienzklasse des Gebäudes können Sie dem Energieausweis entnehmen. Haben Sie diesen nicht zur Hand, kennen aber den Endenergiebedarf/-verbrauch ihres Gebäudes? In diesem Fall können Sie die Klasse anhand folgender Werte selbst zuordnen: | G12: Dropdown | K12: 0 | O12: Nicht bekannt | P12: =$O$12 -> Nicht bekannt
A13: Denkmalschutz | B13: build | D13: EXIST_build_denkmal | E13: Das Gebäude steht unter Denkmalschutz | G13: toggle switch | K13: 1 | O13: Nein | P13: =$O$13 -> Nein
A14: Wärmeübergabe | B14: build | D14: TYP_build_rad | E14: Wie werden die Räume erwärmt? | F14: PopUp: Zusatzheizungen wie Kaminöfen, Infrarotheizungen, Elektroheizungen oder Klimaanlagen werden bei der Bewertung der Räume nicht mit einbezogen. Vorhandene Zusatzheizungen tragen aber zur Beheizung einzelner Räume bei und helfen so, die Vorlauftemperatur des zentralen Heizsystems abzusenken. Das kann beispielsweise im Badezimmer sinnvoll sein. Direktelektrische Heizungen sollten wegen ihrer begrenzten Effizienz jedoch nur gezielt und auf kleiner Fläche eingesetzt werden. | G14: Radio Button + Grafik | K14: 1
B15: build | D15: TYP_distr | E15: Wie wird die Wärme verteilt? | F15: PopUp: Eine Zweirohrheizung führt das warme Wasser über zwei getrennte Leitungen – den Vorlauf zum Heizkörper und den Rücklauf zurück zur Heizungsanlage. Bei einem Einrohrsystem dagegen durchläuft das Wasser alle Heizkörper nacheinander in einer einzigen Leitung, sodass auch geschlossene Thermostatventile den Durchfluss nicht vollständig stoppen. Erkennen lässt sich ein Einrohrsystem daran, dass das Wasser trotz geschlossener Thermostatventile weiter zum nächsten Heizkörper strömt. | G15: Radio Button | H15: not ODER(P14 = "Nachtspeicherheizung (Stromdirektheizung)"; P14 = "Andere") | K15: 1
B16: build | D16: EXIST_T_VL_set | E16: Ich weiß auf welche Vorlauftemperatur die Heizung am Auslegungspunkt eingestellt ist. | F16: Untertext: Ist Ihnen die für den kältesten Wintertag eingestellte Heizwassertemperatur bekannt? Ansonsten wählen Sie "Nein". PopUp: Die Vorlauftemperatur ist die Temperatur des Heizwassers, das von der Zentralheizung (Wärmepumpe, Gas- oder Pelletheizung, usw.) zu den einzelnen Heizkörpern oder zur Fußbodenheizung fließt. Ist Ihnen diese Temperatur nicht bekannt, wählen Sie "Nein". Je kälter die Außentemperatur, desto wärmer muss das Heizwasser sein. Dieser Zusammenhang wird der Heizung durch die Heizkurve vorgegeben. Daraus ergibt sich die Heizwassertemperatur, die am kältesten Wintertag (Normaußentemperatur), der am Gebäudestandort zu erwarten ist, benötigt wird (Auslegungspunkt). In vielen Häusern ist die Vorlauftemperatur höher eingestellt, als eigentlich nötig. Das heißt: Auch wenn Ihre Heizung derzeit mit hohen Temperaturen läuft, kann Ihr Gebäude trotzdem für eine Wärmepumpe geeignet sein. | G16: toggle switch | H16: not EXIST_T_VL_meas OR not TYP_build == "Mehrfamilienhaus" | J16: Boolean | K16: 1 | O16: Nein | P16: =$O$16 -> Nein
B17: build | D17: T_VL_nom_set | E17: Vorlauftemperatur am Auslegungspunkt | G17: Freifeld | H17: EXIST_T_VL_set | I17: °C | J17: Integer | K17: 1 | M17: 30 | N17: 90
B18: build | D18: EXIST_T_VL_meas | E18: Ich kann im Heizungsraum die Vorlauftemperatur ablesen und die Außentemperatur messen | F18: Untertext: Lesen Sie die Vorlauftemperatur Ihrer Heizung bei kaltem Wetter ab (über mindestens zwei Tage hinweg unter 5°C) und notieren Sie dazu auch die Außentemperatur am Standort Ihres Gebäudes. PopUp: Anhand der beiden Temperaturwerte kann die Vorlauftemperatur am Auslegungspunkt abgeschätzt werden. Dies ist jedoch nur bei ausreichend kalten Außentemperaturen möglich. Sie können die Außentemperatur falls möglich an Ihrer Heizung ablesen. Sollte Ihnen keine vor Ort gemessene Außentemperatur vorliegen, nutzen Sie die Temperaturmessungen der nächstgelegenen Wetterstation zum gleichen Zeitpunkt. In vielen Häusern ist die Vorlauftemperatur höher eingestellt, als eigentlich nötig. Das heißt: Auch wenn Ihre Heizung derzeit mit hohen Temperaturen läuft, kann Ihr Gebäude trotzdem für eine Wärmepumpe geeignet sein. | G18: toggle switch | H18: not EXIST_T_VL_set OR not TYP_build == "Mehrfamilienhaus" | K18: 1 | O18: Nein | P18: =$O$18 -> Nein
B19: build | D19: T_VL_meas | E19: Vorlauftemperatur | G19: Freifeld | H19: EXIST_T_VL_meas | I19: °C | J19: Integer | K19: 1 | M19: 30 | N19: 90
B20: build | D20: T_amb_meas | E20: bei einer Außentemperatur von: | G20: Freifeld | H20: EXIST_T_VL_meas | I20: °C | J20: Integer | K20: 1 | M20: -20 | N20: 5
B21: build | D21: INTERN_T_VL_nom_calc | H21: EXIST_T_VL_meas | I21: °C | J21: Integer | P21: =P20*-1.8257+43.457+P20 -> 43.457
D22: INTERN_EXIST_T_VL_nt | H22: EXIST_T_VL_meas | J22: Boolean | P22: =IF(P16="Ja",P17<=55,IF(P18="Ja",P19<P21,FALSE)) -> FALSE

Sheet IN_rooms
B1: Bauteil | C1: Frage (ifeu intern) | D1: Gruppe | E1: Subgruppe | F1: Variable | G1: Fragentext | H1: Hilfstext | I1: Antworttyp | J1: Filter | K1: Einheit | L1: Datentyp | M1: Pflichtfeld | N1: Nachkommastellen | O1: min Wert | P1: max Wert | Q1: Wert intern | R1: Wert Räume --> | S1: Wert Räume --> | T1: Wert Räume --> | U1: Wert Räume --> | V1: Wert Räume --> | W1: Wert Räume --> | X1: Wert Räume --> | Y1: Wert Räume --> | Z1: Wert Räume --> | AA1: Wert Räume --> | AB1: Wert Räume --> | AC1: Wert Räume --> | AD1: Wert Räume --> | AE1: Wert Räume --> | AF1: Wert Räume -->
F2: ID_R# | I2: Intern | L2: String | R2: 1 | S2: 2 | T2: 3 | U2: 4 | V2: 5 | W2: 6 | X2: 7 | Y2: 8 | Z2: 9 | AA2: 10 | AB2: 11 | AC2: 12 | AD2: 13 | AE2: 14 | AF2: 15
F3: TXT_room_name | G3: Name des Raumes | I3: Ausgabe | L3: String | AB3: ="" | AC3: ="" | AD3: ="" | AE3: ="" | AF3: =""
F4: A_floor | G4: Grundfläche des Raumes | H4: PopUp: Gemeint ist die Grundfläche des Fußbodens, nicht die Wohnfläche. Diese berücksichtigt Flächen unter Dachschrägen nicht vollständig. | I4: Freitext | K4: m² | L4: Real | M4: 1 | N4: 1 | O4: 1 | P4: 100
F5: L_hei | G5: Raumhöhe | I5: Freitext | K5: m | L5: Real | M5: 1 | N5: 2 | O5: 1 | P5: 5 | Q5: 2.5
F6: T_air_set | G6: gewünsche Raumtemperatur | H6: Es werden typischerweise 20°C in Wohnräumen und 24°C in Bädern angesetzt. Ihre eigenen Komforttemperaturen können davon abweichen. Es handelt sich um ein Badezimmer? Überprüfen Sie den Raum im Nachgang noch einmal bei 20 °C Raumtemperatur. Sollte die Heizfläche dann ausreichen, genügt es zumeist, dass an sehr kalten Tagen ein Infrarotstrahler oder ein Elektroheizkörper zusätzliche Wärme spendet. | I6: Freitext | K6: °C | L6: Integer | N6: 0 | O6: 10 | P6: 30 | Q6: 20
B7: Decke | D7: topceil | F7: TYP_V_above | G7: Decke grenzt an | H7: Hiermit ist die horizontale Decke des Raumes gemeint. Befindet sich über dieser Decke ein kalter Dachraum, wählen Sie "unbeheizt". | I7: Dropdown | J7: TYP_roof =! "Flach bzw. Flachdach" | L7: String | M7: 1 | Q7: unbeheizt
B8: Fußboden | D8: botceil | F8: TYP_V_below | G8: Fußboden grenzt an | I8: Dropdown | L8: String | M8: 1 | Q8: unbeheizt
B9: Außenwand | D9: wall | F9: L_wall_tot | G9: Gesamtlänge der Außenwände | H9: Berücksichtigen Sie nur Wände, die direkten Kontakt zur Außenluft haben oder ans Erdreich grenzen. Kniestöcke oder Drempelwände werden bei den Dachflächen erfasst. | I9: Freitext | K9: m | L9: Real | M9: 1 | N9: 2 | O9: 0 | P9: 20
D10: wall | F10: UI_YEAR_wall_ins | G10: Abweichendes Modernisierungsjahr | I10: Dropdown | L10: Integer | M10: 0 | N10: 0
B11: Außenwand | D11: wall | F11: UI_L_wall_ins | G11: Abweichende Dämmstärke? | H11: PopUp: Falls nur ein Teil der Außenwand gedämmt wurde (bspw. nur Nordseite), können Sie für ein genaueres Ergebnis die mittlere Dämmstärke angeben. | I11: Freitext | J11: EXIST_build_wall_san | K11: cm | L11: Real | N11: 2 | O11: 0 | P11: 50
B12: Außenwand Art | D12: intern | F12: INTERN_TYP_wall_grenztan_intern | Q12: Außenluft
B13: Fenstertyp 1 | D13: wall | E13: win1 | F13: ="L_"&D13&"_"&E13&"_wid" -> L_wall_win1_wid | G13: Geben Sie die Abmaße des Fenstertyps an, Breite | H13: Untertext: Geben Sie die Abmaße des ersten Fenstertyps an. Außentüren bitte ebenfalls hier erfassen. | I13: Freitext | K13: m | L13: Real | M13: 0 | N13: 0 | O13: 0.2 | P13: 4
B14: Fenstertyp 1 | D14: wall | E14: win1 | F14: ="L_"&D14&"_"&E14&"_hei" -> L_wall_win1_hei | G14: Höhe | I14: Freitext | K14: m | L14: Real | M14: 0 | N14: 0 | O14: 0.2 | P14: 2.5
B15: Fenstertyp 1 | D15: wall | E15: win1 | F15: ="YEAR_"&D15&"_"&E15 -> YEAR_wall_win1 | G15: Baujahr | I15: Dropdown | L15: Integer | M15: 0
B16: Fenstertyp 1 | D16: wall | E16: win1 | F16: ="NO_"&D16&"_"&E16 -> NO_wall_win1 | G16: Anzahl | H16: Anzahl identischer Fenster | I16: Freitext | L16: Integer | M16: 0 | N16: 0 | O16: 0 | P16: 10 | Q16: 1
B17: Fenstertyp 2 | D17: wall | E17: win2 | F17: ="L_"&D17&"_"&E17&"_wid" -> L_wall_win2_wid | G17: Geben Sie die Abmaße des Fenstertyps an, Breite | I17: Freitext | K17: m | L17: Real | M17: 1 | N17: 0 | O17: 0.2 | P17: 4
B18: Fenstertyp 2 | D18: wall | E18: win2 | F18: ="L_"&D18&"_"&E18&"_hei" -> L_wall_win2_hei | G18: Höhe | I18: Freitext | K18: m | L18: Real | M18: 1 | N18: 0 | O18: 0.2 | P18: 2.5
B19: Fenstertyp 2 | D19: wall | E19: win2 | F19: ="YEAR_"&D19&"_"&E19 -> YEAR_wall_win2 | G19: Baujahr | I19: Dropdown | L19: Integer | M19: 0
B20: Fenstertyp 2 | D20: wall | E20: win2 | F20: ="NO_"&D20&"_"&E20 -> NO_wall_win2 | G20: Anzahl | H20: Anzahl identischer Fenster | I20: Freitext | L20: Integer | M20: 0 | N20: 0 | O20: 0 | P20: 10 | Q20: 1
B21: Fenstertyp 3 | D21: wall | E21: win3 | F21: ="L_"&D21&"_"&E21&"_wid" -> L_wall_win3_wid | G21: Geben Sie die Abmaße des dritten Fenstertyps an, Breite | I21: Freitext | K21: m | L21: Real | M21: 1 | N21: 0 | O21: 0.2 | P21: 4
B22: Fenstertyp 3 | D22: wall | E22: win3 | F22: ="L_"&D22&"_"&E22&"_hei" -> L_wall_win3_hei | G22: Höhe | I22: Freitext | K22: m | L22: Real | M22: 1 | N22: 0 | O22: 0.2 | P22: 2.5
B23: Fenstertyp 3 | D23: wall | E23: win3 | F23: ="YEAR_"&D23&"_"&E23 -> YEAR_wall_win3 | G23: Baujahr | I23: Dropdown | L23: Integer | M23: 0
B24: Fenstertyp 3 | D24: wall | E24: win3 | F24: ="NO_"&D24&"_"&E24 -> NO_wall_win3 | G24: Anzahl | H24: Anzahl identischer Fenster | I24: Freitext | L24: Integer | M24: 0 | N24: 0 | O24: 0 | P24: 10 | Q24: 1
D25: innerwall | F25: EXIST_innerwall | G25: Innenwände zu unbeheiztem Raum vorhanden? | H25: z. B. angrenzend an Garage, Kellerraum oder Treppenhaus | I25: toggle switch | L25: Boolean | M25: 1 | Q25: Nein
D26: innerwall | F26: L_innerwall_tot | G26: Gesamtlänge der Innenwände gegen unbeheizte Räume | I26: Freitext | J26: EXIST_innerwall | K26: m | L26: Real | M26: 0 | N26: 2 | O26: 1 | P26: 20
D27: innerwall | F27: L_innerwall_ins | G27: Dämmung vorhanden? | I27: Freitext | J27: EXIST_innerwall | K27: cm | L27: Real | M27: 0 | N27: 0 | O27: 0 | P27: 50 | Q27: 0
B28: Dachfläche | D28: roof | F28: EXIST_roof | G28: Vorhandene Dachflächen? | H28: PopUp: Haben Sie mehr als zwei oder nicht identische Dachflächen im Raum, wählen Sie bitte "komplexe Dachfläche". Gauben werden separat erfasst. | I28: Radio Button | J28: TYP_roof =/ "Flach bzw. Flachdach" | L28: String | M28: 1 | Q28: Keine
B29: Dachfläche | D29: roof
B30: Dachfläche | D30: roof | F30: L_roof_wid | G30: Länge | I30: Freitext | J30: (EXIST_roof == "Eine" OR EXIST_roof == "Zwei (symmetrisch)") AND TYP_roof =/ "Flach bzw. Flachdach" | K30: m | L30: Real | M30: 0 | N30: 2 | O30: 1
B31: Dachfläche | D31: roof | F31: L_roof_hei | G31: Höhe | I31: {=_xlfn.IFS( IN_rooms!R$28="Keine",IN_rooms!R$4, IN_rooms!R$28="Komplex",IN_rooms!R$85, IN_rooms!R$28="Flachdach",0, TRUE,IN_rooms!R$32*IN_rooms!R$30)} -> 0 | J31: {=_xlfn.IFS( IN_rooms!S$28="Keine",IN_rooms!S$4, IN_rooms!S$28="Komplex",IN_rooms!S$85, IN_rooms!S$28="Flachdach",0, TRUE,IN_rooms!S$32*IN_rooms!S$30)} -> 0 | K31: m | L31: Real | M31: 0 | N31: 2 | O31: 1 | P31: 6
D32: topceil | F32: ="L_"&D32&"_"&E32&"_wid" -> L_topceil__wid | G32: Ist eine horizontale Decke vorhanden? Geben Sie bitte die Breite an | H32: Lassen Sie das Feld leer, wenn keine horizontale Decke vorhanden ist. | I32: =IF(AND(IN_build!$P$4="Flach bzw. Flachdach",IN_rooms!R28="Ja"),0,clc_load!I$31) -> 0 | J32: (EXIST_roof == "Eine" OR EXIST_roof == "Zwei (symmetrisch)") AND TYP_roof =/ "Flach bzw. Flachdach" | K32: m | L32: String | M32: 1
D33: topceil | F33: n_wall_Giebel | G33: Geben Sie die Anzahl der Giebelwände an. | H33: Ist keine gegen Außenluft grenzende Giebelwand vorhanden, bitte 0 eingeben. | I33: Freitext | J33: (EXIST_roof =/ "Keine" OR EXIST_roof =/ "Flachdach") AND TYP_roof =/ "Flach bzw. Flachdach" | L33: Integer | M33: 1 | O33: 0 | P33: 2 | Q33: 1
B34: Dachfläche | D34: roof | F34: L_roof_jamb_hei | G34: Falls eine Drempelwand bzw. Kniestock vorhanden ist, geben Sie die Höhe an | H34: PopUp: Ein Drempel ist eine senkrechte, leichte Trennwand zwischen Dachschräge und Fußboden, die nicht Teil der Außenwand ist - dahinter befidet sich meist ein Hohlraum. Ein Kniestock beschreibt eine senkrechte Wand zwischen Dachschräge und Fußboden und gehört zur Außenwand des Hauses. | I34: Freitext | J34: (EXIST_roof =/ "Keine" OR EXIST_roof =/ "Flachdach") AND TYP_roof =/ "Flach bzw. Flachdach" | K34: m | L34: Real | M34: 1 | N34: 2
B35: Dachfläche | D35: roof | F35: TYP_jamb_hei | G35: Klopfen Sie gegen die senkrechte Wand unter der Dachschräge. Klingt es hohl? | H35: PopUp: Klingt es hohl, haben Sie wahrscheinlich eine Drempelwand. Diese hat andere Auswirkungen auf die Wärmeverluste als ein Kniestock. | I35: toggle switch | J35: (EXIST_roof =/ "Keine" OR EXIST_roof =/ "Flachdach") AND TYP_roof =/ "Flach bzw. Flachdach" AND L_roof_jamb_hei > 0 | L35: Boolean | M35: 1 | Q35: Ja
B36: Dachfläche | D36: intern | F36: EXIST_roof_knee_eff | G36: INTERN - Haben sie einen Kniestock unter der Dachschräge? | I36: toggle switch | L36: Boolean | M36: 1 | R36: =IF(R$35="Nein","Ja","Nein") -> Nein | S36: =IF(S$35="Nein","Ja","Nein") -> Nein | T36: =IF(T$35="Nein","Ja","Nein") -> Nein | U36: =IF(U$35="Nein","Ja","Nein") -> Nein | V36: =IF(V$35="Nein","Ja","Nein") -> Nein | W36: =IF(W$35="Nein","Ja","Nein") -> Nein | X36: =IF(X$35="Nein","Ja","Nein") -> Nein | Y36: =IF(Y$35="Nein","Ja","Nein") -> Nein | ... AF36: =IF(AF$35="Nein","Ja","Nein") -> Nein
B37: Dachfläche | D37: intern | F37: L_roof_knee_hei_eff | G37: INTERN - Falls ein Kniestock vorhanden ist, geben Sie dessen Höhe an | I37: Freitext | K37: m | L37: Real | M37: 0 | N37: 2 | O37: 0 | P37: 6 | R37: =IF(R$35="Ja",0,R$34) -> 0 | S37: =IF(S$35="Ja",0,S$34) -> 0 | T37: =IF(T$35="Ja",0,T$34) -> 0 | U37: =IF(U$35="Ja",0,U$34) -> 0 | V37: =IF(V$35="Ja",0,V$34) -> 0 | W37: =IF(W$35="Ja",0,W$34) -> 0 | X37: =IF(X$35="Ja",0,X$34) -> 0 | Y37: =IF(Y$35="Ja",0,Y$34) -> 0 | ... AF37: =IF(AF$35="Ja",0,AF$34) -> 0
B38: Dachfläche | D38: intern | F38: EXIST_roof_jamb_eff | G38: INTERN - Haben sie einen Drempel unter der Dachschräge? | H38: Klopfen Sie gegen die senkrechte Wand unter der Dachschräge. Klingt es hohl, haben Sie vermutlich einen Drempel. | I38: toggle switch | L38: Boolean | M38: 1 | R38: =IF(R$35="Nein","Nein","Ja") -> Ja | S38: =IF(S$35="Nein","Nein","Ja") -> Ja | T38: =IF(T$35="Nein","Nein","Ja") -> Ja | U38: =IF(U$35="Nein","Nein","Ja") -> Ja | V38: =IF(V$35="Nein","Nein","Ja") -> Ja | W38: =IF(W$35="Nein","Nein","Ja") -> Ja | X38: =IF(X$35="Nein","Nein","Ja") -> Ja | Y38: =IF(Y$35="Nein","Nein","Ja") -> Ja | ... AF38: =IF(AF$35="Nein","Nein","Ja") -> Ja
B39: Dachfläche | D39: intern | F39: L_roof_jamb_hei_eff | G39: INTERN - Falls ein Drempel vorhanden ist, geben Sie dessen Höhe an | H39: Der Drempel beschreibt im Dachbereich die Höhe der leichten Trennwand zwischen Fußboden und Beginn des Dachs. | I39: Freitext | K39: m | L39: Real | M39: 0 | N39: 2 | O39: 0 | P39: 3 | R39: =IF(R$35="Nein",0,R$34) -> 0 | S39: =IF(S$35="Nein",0,S$34) -> 0 | T39: =IF(T$35="Nein",0,T$34) -> 0 | U39: =IF(U$35="Nein",0,U$34) -> 0 | V39: =IF(V$35="Nein",0,V$34) -> 0 | W39: =IF(W$35="Nein",0,W$34) -> 0 | X39: =IF(X$35="Nein",0,X$34) -> 0 | Y39: =IF(Y$35="Nein",0,Y$34) -> 0 | ... AF39: =IF(AF$35="Nein",0,AF$34) -> 0
B40: Gaube | D40: roof | E40: dormer | F40: EXIST_dormer | G40: Ist eine Gaube in der Dachschräge vorhanden? | I40: toggle switch | L40: Boolean | M40: 1
...

Sheet clc_load
A1: Bauteil IWU | B1: Bezeichnung | C1: Gruppe | D1: Subgruppe | E1: Variable | F1: Einheit | G1: Erläuterung | H1: Kommentar | I1: Wert Räume -->
C2: Raumindex | E2: ID_R# | I2: =IN_rooms!R2 -> 1 | J2: =IN_rooms!S2 -> 2 | K2: =IN_rooms!T2 -> 3 | L2: =IN_rooms!U2 -> 4 | M2: =IN_rooms!V2 -> 5 | N2: =IN_rooms!W2 -> 6 | O2: =IN_rooms!X2 -> 7 | P2: =IN_rooms!Y2 -> 8 | ... W2: =IN_rooms!AF2 -> 15
B3: Gebäudetyp | E3: TYP_build | I3: =IN_build!$P$3 -> 0 | J3: =IN_build!$P$3 -> 0 | K3: =IN_build!$P$3 -> 0 | L3: =IN_build!$P$3 -> 0 | M3: =IN_build!$P$3 -> 0 | N3: =IN_build!$P$3 -> 0 | O3: =IN_build!$P$3 -> 0 | P3: =IN_build!$P$3 -> 0 | ... W3: =IN_build!$P$3 -> 0
B4: Baujahr | E4: YEAR_build_bj | I4: =IN_build!$P$5 -> 0 | J4: =IN_build!$P$5 -> 0 | K4: =IN_build!$P$5 -> 0 | L4: =IN_build!$P$5 -> 0 | M4: =IN_build!$P$5 -> 0 | N4: =IN_build!$P$5 -> 0 | O4: =IN_build!$P$5 -> 0 | P4: =IN_build!$P$5 -> 0 | ... W4: =IN_build!$P$5 -> 0
B5: Raumbezeichnung | E5: TXT_room_name | I5: =IN_rooms!R3 -> 0 | J5: =IN_rooms!S3 -> 0 | K5: =IN_rooms!T3 -> 0 | L5: =IN_rooms!U3 -> 0 | M5: =IN_rooms!V3 -> 0 | N5: =IN_rooms!W3 -> 0 | O5: =IN_rooms!X3 -> 0 | P5: =IN_rooms!Y3 -> 0 | ... W5: =IN_rooms!AF3
A6: Luftwechsel | B6: Volumen | E6: V_room | F6: m³ | I6: =IF(I$26>0,HLOOKUP("f_Vroom_roof",PAR!$F$1:$Y$5,2,FALSE)*IN_rooms!R$4*IN_rooms!R$5+I$25,IN_rooms!R$4*IN_rooms!R$5) -> 0 | J6: =IF(J$26>0,HLOOKUP("f_Vroom_roof",PAR!$F$1:$Y$5,2,FALSE)*IN_rooms!S$4*IN_rooms!S$5+J$25,IN_rooms!S$4*IN_rooms!S$5) -> 0 | K6: =IF(K$26>0,HLOOKUP("f_Vroom_roof",PAR!$F$1:$Y$5,2,FALSE)*IN_rooms!T$4*IN_rooms!T$5+K$25,IN_rooms!T$4*IN_rooms!T$5) -> 0 | L6: =IF(L$26>0,HLOOKUP("f_Vroom_roof",PAR!$F$1:$Y$5,2,FALSE)*IN_rooms!U$4*IN_rooms!U$5+L$25,IN_rooms!U$4*IN_rooms!U$5) -> 0 | M6: =IF(M$26>0,HLOOKUP("f_Vroom_roof",PAR!$F$1:$Y$5,2,FALSE)*IN_rooms!V$4*IN_rooms!V$5+M$25,IN_rooms!V$4*IN_rooms!V$5) -> 0 | N6: =IF(N$26>0,HLOOKUP("f_Vroom_roof",PAR!$F$1:$Y$5,2,FALSE)*IN_rooms!W$4*IN_rooms!W$5+N$25,IN_rooms!W$4*IN_rooms!W$5) -> 0 | O6: =IF(O$26>0,HLOOKUP("f_Vroom_roof",PAR!$F$1:$Y$5,2,FALSE)*IN_rooms!X$4*IN_rooms!X$5+O$25,IN_rooms!X$4*IN_rooms!X$5) -> 0 | P6: =IF(P$26>0,HLOOKUP("f_Vroom_roof",PAR!$F$1:$Y$5,2,FALSE)*IN_rooms!Y$4*IN_rooms!Y$5+P$25,IN_rooms!Y$4*IN_rooms!Y$5) -> 0 | ... W6: =IF(W$26>0,HLOOKUP("f_Vroom_roof",PAR!$F$1:$Y$5,2,FALSE)*IN_rooms!AF$4*IN_rooms!AF$5+W$25,IN_rooms!AF$4*IN_rooms!AF$5) -> 0
A7: Luftwechsel | B7: Luftwechselrate ni | E7: freq_room_vent | F7: 1/h | I7: =0.5 -> 0.5 | J7: =0.5 -> 0.5 | K7: =0.5 -> 0.5 | L7: =0.5 -> 0.5 | M7: =0.5 -> 0.5 | N7: =0.5 -> 0.5 | O7: =0.5 -> 0.5 | P7: =0.5 -> 0.5 | ... W7: =0.5 -> 0.5
B8: Wärmebrückenkoeffizient ∆U,TB | E8: qdot_build_conn_trans | F8: W/(mK) | I8: =IF(AND(I$16<=U_GEG_A.7!$C$10, I$28<=AVERAGE(U_GEG_A.7!$C$21:$C$22, I$34<=U_GEG_A.7!$C$21,I$39<=U_GEG_A.7!$C$25), I$45<=U_GEG_A.7!$C$11, I$63<=U_GEG_A.7!$C$12, I$69<=U_GEG_A.7!$C$12), 0.05,0.1) -> #NUM! | J8: =IF(AND(J$16<=U_GEG_A.7!$C$10, J$28<=AVERAGE(U_GEG_A.7!$C$21:$C$22, J$34<=U_GEG_A.7!$C$21,J$39<=U_GEG_A.7!$C$25), J$45<=U_GEG_A.7!$C$11, J$63<=U_GEG_A.7!$C$12, J$69<=U_GEG_A.7!$C$12), 0.05,0.1) -> #NUM! | K8: =IF(AND(K$16<=U_GEG_A.7!$C$10, K$28<=AVERAGE(U_GEG_A.7!$C$21:$C$22, K$34<=U_GEG_A.7!$C$21,K$39<=U_GEG_A.7!$C$25), K$45<=U_GEG_A.7!$C$11, K$63<=U_GEG_A.7!$C$12, K$69<=U_GEG_A.7!$C$12), 0.05,0.1) -> #NUM! | L8: =IF(AND(L$16<=U_GEG_A.7!$C$10, L$28<=AVERAGE(U_GEG_A.7!$C$21:$C$22, L$34<=U_GEG_A.7!$C$21,L$39<=U_GEG_A.7!$C$25), L$45<=U_GEG_A.7!$C$11, L$63<=U_GEG_A.7!$C$12, L$69<=U_GEG_A.7!$C$12), 0.05,0.1) -> #NUM! | M8: =IF(AND(M$16<=U_GEG_A.7!$C$10, M$28<=AVERAGE(U_GEG_A.7!$C$21:$C$22, M$34<=U_GEG_A.7!$C$21,M$39<=U_GEG_A.7!$C$25), M$45<=U_GEG_A.7!$C$11, M$63<=U_GEG_A.7!$C$12, M$69<=U_GEG_A.7!$C$12), 0.05,0.1) -> #NUM! | N8: =IF(AND(N$16<=U_GEG_A.7!$C$10, N$28<=AVERAGE(U_GEG_A.7!$C$21:$C$22, N$34<=U_GEG_A.7!$C$21,N$39<=U_GEG_A.7!$C$25), N$45<=U_GEG_A.7!$C$11, N$63<=U_GEG_A.7!$C$12, N$69<=U_GEG_A.7!$C$12), 0.05,0.1) -> #NUM! | O8: =IF(AND(O$16<=U_GEG_A.7!$C$10, O$28<=AVERAGE(U_GEG_A.7!$C$21:$C$22, O$34<=U_GEG_A.7!$C$21,O$39<=U_GEG_A.7!$C$25), O$45<=U_GEG_A.7!$C$11, O$63<=U_GEG_A.7!$C$12, O$69<=U_GEG_A.7!$C$12), 0.05,0.1) -> #NUM! | P8: =IF(AND(P$16<=U_GEG_A.7!$C$10, P$28<=AVERAGE(U_GEG_A.7!$C$21:$C$22, P$34<=U_GEG_A.7!$C$21,P$39<=U_GEG_A.7!$C$25), P$45<=U_GEG_A.7!$C$11, P$63<=U_GEG_A.7!$C$12, P$69<=U_GEG_A.7!$C$12), 0.05,0.1) -> #NUM! | ... W8: =IF(AND(W$16<=U_GEG_A.7!$C$10, W$28<=AVERAGE(U_GEG_A.7!$C$21:$C$22, W$34<=U_GEG_A.7!$C$21,W$39<=U_GEG_A.7!$C$25), W$45<=U_GEG_A.7!$C$11, W$63<=U_GEG_A.7!$C$12, W$69<=U_GEG_A.7!$C$12), 0.05,0.1) -> #NUM!
B9: ρ*cp pauschal nach 12831 | E9: Q_build_vent_const | F9: Wh/(m³K) | I9: =0.34 -> 0.34 | J9: =0.34 -> 0.34 | K9: =0.34 -> 0.34 | L9: =0.34 -> 0.34 | M9: =0.34 -> 0.34 | N9: =0.34 -> 0.34 | O9: =0.34 -> 0.34 | P9: =0.34 -> 0.34 | ... W9: =0.34 -> 0.34
B10: Berechnungs-Raumtemperatur | E10: T_room_heated | F10: °C | I10: =IF(IN_rooms!R$6<>20,IN_rooms!R$6,20) -> 0 | J10: =IF(IN_rooms!S$6<>20,IN_rooms!S$6,20) -> 0 | K10: =IF(IN_rooms!T$6<>20,IN_rooms!T$6,20) -> 0 | L10: =IF(IN_rooms!U$6<>20,IN_rooms!U$6,20) -> 0 | M10: =IF(IN_rooms!V$6<>20,IN_rooms!V$6,20) -> 0 | N10: =IF(IN_rooms!W$6<>20,IN_rooms!W$6,20) -> 0 | O10: =IF(IN_rooms!X$6<>20,IN_rooms!X$6,20) -> 0 | P10: =IF(IN_rooms!Y$6<>20,IN_rooms!Y$6,20) -> 0 | ... W10: =IF(IN_rooms!AF$6<>20,IN_rooms!AF$6,20) -> 0
A11: Luftwechsel | B11: Mindes-Luftvolumenstrom qv,min | E11: Vdot_room | F11: m³/h | I11: =I$7*I$6 -> 0 | J11: =J$7*J$6 -> 0 | K11: =K$7*K$6 -> 0 | L11: =L$7*L$6 -> 0 | M11: =M$7*M$6 -> 0 | N11: =N$7*N$6 -> 0 | O11: =O$7*O$6 -> 0 | P11: =P$7*P$6 -> 0 | ... W11: =W$7*W$6 -> 0
A12: Luftwechsel | B12: Heizlast Ventilation [W] | E12: Qdot_room_vent | F12: W | I12: =I$9*I$11*(I$10-Normaußentemperatur_12831!$B$6) -> 0 | J12: =J$9*J$11*(J$10-Normaußentemperatur_12831!$B$6) -> 0 | K12: =K$9*K$11*(K$10-Normaußentemperatur_12831!$B$6) -> 0 | L12: =L$9*L$11*(L$10-Normaußentemperatur_12831!$B$6) -> 0 | M12: =M$9*M$11*(M$10-Normaußentemperatur_12831!$B$6) -> 0 | N12: =N$9*N$11*(N$10-Normaußentemperatur_12831!$B$6) -> 0 | O12: =O$9*O$11*(O$10-Normaußentemperatur_12831!$B$6) -> 0 | P12: =P$9*P$11*(P$10-Normaußentemperatur_12831!$B$6) -> 0 | ... W12: =W$9*W$11*(W$10-Normaußentemperatur_12831!$B$6) -> 0
A13: Luftwechsel | B13: Anteil an Raumheizlast | E13: r_Qdot_room_vent | F13: % | I13: =I$12/I$72 -> #NUM! | J13: =J$12/J$72 -> #NUM! | K13: =K$12/K$72 -> #NUM! | L13: =L$12/L$72 -> #NUM! | M13: =M$12/M$72 -> #NUM! | N13: =N$12/N$72 -> #NUM! | O13: =O$12/O$72 -> #NUM! | P13: =P$12/P$72 -> #NUM! | ... W13: =W$12/W$72 -> #NUM!
A14: Außenwand | B14: Fläche [m²] | C14: wall | E14: A_wall | F14: m² | I14: {=IF( OR(IN_rooms!R$28="Keine",IN_rooms!R$28="Flachdach",IN_rooms!R$31=0,IN_rooms!R$30=0,IN_build!$P$4="Flach bzw. Flachdach"), ((IN_rooms!R$9+HLOOKUP("f_A_wall_wid",PAR!$F$1:$Y$5,2,FALSE))*(IN_rooms!R$5+HLOOKUP("f_A_wall_hei",PAR!$F$1:$Y$5,2,FALSE))-(I$42+I$48+I$54))*(IN_rooms!R$9>0), _xlfn.LET( _xlpm.komplex,IN_rooms!R$28="Komplex", _xlpm.b_ceil,IN_rooms!R$32, _xlpm.L_wall,(IN_rooms!R$9+HLOOKUP("f_A_wall_wid",PAR!$F$1:$Y$5,2,FALSE))*(IN_rooms!R$9>0), _xlpm.n_giebel,IF(_xlpm.L_wall=0,0,IN_rooms!R33), _xlpm.h_knee,IN_rooms!R$34, _xlpm.h_roof,IN_rooms!R$31, _xlpm.is_jamb,IN_rooms!R$35="Ja", _xlpm.h_room,IN_rooms!R$5+HLOOKUP("f_A_wall_hei",PAR!$F$1:$Y$5,2,FALSE), _xlpm.alpha,_xlfn.IFS( IN_build!$P$4="geneigt",25, IN_build!$P$4="steil",40, IN_build!$P$4="sehr steil",55), _xlpm.A_win,(I$42+I$48+I$54), _xlpm.A_knee,MAX(0,IF(_xlpm.is_jamb,0,IF(_xlpm.komplex,I$26*(_xlpm.h_knee*SIN(_xlpm.alpha*PI()/180))/(_xlpm.h_room-_xlpm.h_knee),_xlpm.h_knee*IN_rooms!R$30))), _xlpm.A_no_slop,_xlpm.L_wall*_xlpm.h_room, _xlpm.A_big_rect,_xlpm.h_room*_xlpm.b_ceil, _xlpm.A_triangle,1/4*_xlpm.h_roof^2*SIN(2*_xlpm.alpha*PI()/180), _xlpm.A_small_rect,_xlpm.h_knee*_xlpm.h_roof*COS(_xlpm.alpha*PI()/180), _xlpm.A_triangle_jamb,1/2*_xlpm.h_knee^2*TAN(_xlpm.alpha*PI()/180), _xlpm.A_slop_tot,_xlpm.A_triangle+_xlpm.A_small_rect+IF(_xlpm.is_jamb,_xlpm.A_triangle_jamb,0), _xlpm.giebel_0,_xlpm.n_giebel=0, _xlpm.giebel_1_slop_1,AND(IN_rooms!R$28="Eine",_xlpm.n_giebel=1), _xlpm.giebel_2_slop_1,AND(IN_rooms!R$28="Eine",_xlpm.n_giebel=2), _xlpm.giebel_1_slop_2,AND(IN_rooms!R$28="Zwei (symmetrisch)",_xlpm.n_giebel=1), _xlpm.giebel_2_slop_2,AND(IN_rooms!R$28="Zwei (symmetrisch)",_xlpm.n_giebel=2), IF(_xlpm.komplex, MAX(MIN(_xlfn.IFS( _xlpm.giebel_0,_xlpm.L_wall*_xlpm.h_room, _xlpm.is_jamb,_xlpm.h_room^2/TAN(_xlpm.alpha*PI()/180), NOT(_xlpm.is_jamb),_xlpm.L_wall * (_xlpm.h_knee + 0.5 * (_xlpm.h_room - _xlpm.h_knee)), TRUE,_xlpm.A_no_slop),_xlpm.A_no_slop)+_xlpm.A_knee-_xlpm.A_win,0)*HLOOKUP("f_Awall_roof",PAR!$F$1:$Y$5,2,FALSE), MAX(MIN(_xlfn.IFS( _xlpm.giebel_0,_xlpm.A_no_slop, _xlpm.giebel_1_slop_1,_xlpm.A_big_rect+_xlpm.A_slop_tot, _xlpm.giebel_2_slop_1,2*(_xlpm.A_big_rect+_xlpm.A_slop_tot), _xlpm.giebel_1_slop_2,_xlpm.A_big_rect+2*_xlpm.A_slop_tot, _xlpm.giebel_2_slop_2,2*(_xlpm.A_big_rect+2*_xlpm.A_slop_tot), TRUE,_xlpm.A_no_slop),_xlpm.A_no_slop)+_xlpm.A_knee-_xlpm.A_win,0)*HLOOKUP("f_Awall_roof",PAR!$F$1:$Y$5,2,FALSE) )))} -> 0 | J14: {=IF( OR(IN_rooms!S$28="Keine",IN_rooms!S$28="Flachdach",IN_rooms!S$31=0,IN_rooms!S$30=0,IN_build!$P$4="Flach bzw. Flachdach"), ((IN_rooms!S$9+HLOOKUP("f_A_wall_wid",PAR!$F$1:$Y$5,2,FALSE))*(IN_rooms!S$5+HLOOKUP("f_A_wall_hei",PAR!$F$1:$Y$5,2,FALSE))-(J$42+J$48+J$54))*(IN_rooms!S$9>0), _xlfn.LET( _xlpm.komplex,IN_rooms!S$28="Komplex", _xlpm.b_ceil,IN_rooms!S$32, _xlpm.L_wall,(IN_rooms!S$9+HLOOKUP("f_A_wall_wid",PAR!$F$1:$Y$5,2,FALSE))*(IN_rooms!S$9>0), _xlpm.n_giebel,IF(_xlpm.L_wall=0,0,IN_rooms!S33), _xlpm.h_knee,IN_rooms!S$34, _xlpm.h_roof,IN_rooms!S$31, _xlpm.is_jamb,IN_rooms!S$35="Ja", _xlpm.h_room,IN_rooms!S$5+HLOOKUP("f_A_wall_hei",PAR!$F$1:$Y$5,2,FALSE), _xlpm.alpha,_xlfn.IFS( IN_build!$P$4="geneigt",25, IN_build!$P$4="steil",40, IN_build!$P$4="sehr steil",55), _xlpm.A_win,(J$42+J$48+J$54), _xlpm.A_knee,MAX(0,IF(_xlpm.is_jamb,0,IF(_xlpm.komplex,J$26*(_xlpm.h_knee*SIN(_xlpm.alpha*PI()/180))/(_xlpm.h_room-_xlpm.h_knee),_xlpm.h_knee*IN_rooms!S$30))), _xlpm.A_no_slop,_xlpm.L_wall*_xlpm.h_room, _xlpm.A_big_rect,_xlpm.h_room*_xlpm.b_ceil, _xlpm.A_triangle,1/4*_xlpm.h_roof^2*SIN(2*_xlpm.alpha*PI()/180), _xlpm.A_small_rect,_xlpm.h_knee*_xlpm.h_roof*COS(_xlpm.alpha*PI()/180), _xlpm.A_triangle_jamb,1/2*_xlpm.h_knee^2*TAN(_xlpm.alpha*PI()/180), _xlpm.A_slop_tot,_xlpm.A_triangle+_xlpm.A_small_rect+IF(_xlpm.is_jamb,_xlpm.A_triangle_jamb,0), _xlpm.giebel_0,_xlpm.n_giebel=0, _xlpm.giebel_1_slop_1,AND(IN_rooms!S$28="Eine",_xlpm.n_giebel=1), _xlpm.giebel_2_slop_1,AND(IN_rooms!S$28="Eine",_xlpm.n_giebel=2), _xlpm.giebel_1_slop_2,AND(IN_rooms!S$28="Zwei (symmetrisch)",_xlpm.n_giebel=1), _xlpm.giebel_2_slop_2,AND(IN_rooms!S$28="Zwei (symmetrisch)",_xlpm.n_giebel=2), IF(_xlpm.komplex, MAX(MIN(_xlfn.IFS( _xlpm.giebel_0,_xlpm.L_wall*_xlpm.h_room, _xlpm.is_jamb,_xlpm.h_room^2/TAN(_xlpm.alpha*PI()/180), NOT(_xlpm.is_jamb),_xlpm.L_wall * (_xlpm.h_knee + 0.5 * (_xlpm.h_room - _xlpm.h_knee)), TRUE,_xlpm.A_no_slop),_xlpm.A_no_slop)+_xlpm.A_knee-_xlpm.A_win,0)*HLOOKUP("f_Awall_roof",PAR!$F$1:$Y$5,2,FALSE), MAX(MIN(_xlfn.IFS( _xlpm.giebel_0,_xlpm.A_no_slop, _xlpm.giebel_1_slop_1,_xlpm.A_big_rect+_xlpm.A_slop_tot, _xlpm.giebel_2_slop_1,2*(_xlpm.A_big_rect+_xlpm.A_slop_tot), _xlpm.giebel_1_slop_2,_xlpm.A_big_rect+2*_xlpm.A_slop_tot, _xlpm.giebel_2_slop_2,2*(_xlpm.A_big_rect+2*_xlpm.A_slop_tot), TRUE,_xlpm.A_no_slop),_xlpm.A_no_slop)+_xlpm.A_knee-_xlpm.A_win,0)*HLOOKUP("f_Awall_roof",PAR!$F$1:$Y$5,2,FALSE) )))} -> 0 | K14: {=IF( OR(IN_rooms!T$28="Keine",IN_rooms!T$28="Flachdach",IN_rooms!T$31=0,IN_rooms!T$30=0,IN_build!$P$4="Flach bzw. Flachdach"), ((IN_rooms!T$9+HLOOKUP("f_A_wall_wid",PAR!$F$1:$Y$5,2,FALSE))*(IN_rooms!T$5+HLOOKUP("f_A_wall_hei",PAR!$F$1:$Y$5,2,FALSE))-(K$42+K$48+K$54))*(IN_rooms!T$9>0), _xlfn.LET( _xlpm.komplex,IN_rooms!T$28="Komplex", _xlpm.b_ceil,IN_rooms!T$32, _xlpm.L_wall,(IN_rooms!T$9+HLOOKUP("f_A_wall_wid",PAR!$F$1:$Y$5,2,FALSE))*(IN_rooms!T$9>0), _xlpm.n_giebel,IF(_xlpm.L_wall=0,0,IN_rooms!T33), _xlpm.h_knee,IN_rooms!T$34, _xlpm.h_roof,IN_rooms!T$31, _xlpm.is_jamb,IN_rooms!T$35="Ja", _xlpm.h_room,IN_rooms!T$5+HLOOKUP("f_A_wall_hei",PAR!$F$1:$Y$5,2,FALSE), _xlpm.alpha,_xlfn.IFS( IN_build!$P$4="geneigt",25, IN_build!$P$4="steil",40, IN_build!$P$4="sehr steil",55), _xlpm.A_win,(K$42+K$48+K$54), _xlpm.A_knee,MAX(0,IF(_xlpm.is_jamb,0,IF(_xlpm.komplex,K$26*(_xlpm.h_knee*SIN(_xlpm.alpha*PI()/180))/(_xlpm.h_room-_xlpm.h_knee),_xlpm.h_knee*IN_rooms!T$30))), _xlpm.A_no_slop,_xlpm.L_wall*_xlpm.h_room, _xlpm.A_big_rect,_xlpm.h_room*_xlpm.b_ceil, _xlpm.A_triangle,1/4*_xlpm.h_roof^2*SIN(2*_xlpm.alpha*PI()/180), _xlpm.A_small_rect,_xlpm.h_knee*_xlpm.h_roof*COS(_xlpm.alpha*PI()/180), _xlpm.A_triangle_jamb,1/2*_xlpm.h_knee^2*TAN(_xlpm.alpha*PI()/180), _xlpm.A_slop_tot,_xlpm.A_triangle+_xlpm.A_small_rect+IF(_xlpm.is_jamb,_xlpm.A_triangle_jamb,0), _xlpm.giebel_0,_xlpm.n_giebel=0, _xlpm.giebel_1_slop_1,AND(IN_rooms!T$28="Eine",_xlpm.n_giebel=1), _xlpm.giebel_2_slop_1,AND(IN_rooms!T$28="Eine",_xlpm.n_giebel=2), _xlpm.giebel_1_slop_2,AND(IN_rooms!T$28="Zwei (symmetrisch)",_xlpm.n_giebel=1), _xlpm.giebel_2_slop_2,AND(IN_rooms!T$28="Zwei (symmetrisch)",_xlpm.n_giebel=2), IF(_xlpm.komplex, MAX(MIN(_xlfn.IFS( _xlpm.giebel_0,_xlpm.L_wall*_xlpm.h_room, _xlpm.is_jamb,_xlpm.h_room^2/TAN(_xlpm.alpha*PI()/180), NOT(_xlpm.is_jamb),_xlpm.L_wall * (_xlpm.h_knee + 0.5 * (_xlpm.h_room - _xlpm.h_knee)), TRUE,_xlpm.A_no_slop),_xlpm.A_no_slop)+_xlpm.A_knee-_xlpm.A_win,0)*HLOOKUP("f_Awall_roof",PAR!$F$1:$Y$5,2,FALSE), MAX(MIN(_xlfn.IFS( _xlpm.giebel_0,_xlpm.A_no_slop, _xlpm.giebel_1_slop_1,_xlpm.A_big_rect+_xlpm.A_slop_tot, _xlpm.giebel_2_slop_1,2*(_xlpm.A_big_rect+_xlpm.A_slop_tot), _xlpm.giebel_1_slop_2,_xlpm.A_big_rect+2*_xlpm.A_slop_tot, _xlpm.giebel_2_slop_2,2*(_xlpm.A_big_rect+2*_xlpm.A_slop_tot), TRUE,_xlpm.A_no_slop),_xlpm.A_no_slop)+_xlpm.A_knee-_xlpm.A_win,0)*HLOOKUP("f_Awall_roof",PAR!$F$1:$Y$5,2,FALSE) )))} -> 0 | L14: {=IF( OR(IN_rooms!U$28="Keine",IN_rooms!U$28="Flachdach",IN_rooms!U$31=0,IN_rooms!U$30=0,IN_build!$P$4="Flach bzw. Flachdach"), ((IN_rooms!U$9+HLOOKUP("f_A_wall_wid",PAR!$F$1:$Y$5,2,FALSE))*(IN_rooms!U$5+HLOOKUP("f_A_wall_hei",PAR!$F$1:$Y$5,2,FALSE))-(L$42+L$48+L$54))*(IN_rooms!U$9>0), _xlfn.LET( _xlpm.komplex,IN_rooms!U$28="Komplex", _xlpm.b_ceil,IN_rooms!U$32, _xlpm.L_wall,(IN_rooms!U$9+HLOOKUP("f_A_wall_wid",PAR!$F$1:$Y$5,2,FALSE))*(IN_rooms!U$9>0), _xlpm.n_giebel,IF(_xlpm.L_wall=0,0,IN_rooms!U33), _xlpm.h_knee,IN_rooms!U$34, _xlpm.h_roof,IN_rooms!U$31, _xlpm.is_jamb,IN_rooms!U$35="Ja", _xlpm.h_room,IN_rooms!U$5+HLOOKUP("f_A_wall_hei",PAR!$F$1:$Y$5,2,FALSE), _xlpm.alpha,_xlfn.IFS( IN_build!$P$4="geneigt",25, IN_build!$P$4="steil",40, IN_build!$P$4="sehr steil",55), _xlpm.A_win,(L$42+L$48+L$54), _xlpm.A_knee,MAX(0,IF(_xlpm.is_jamb,0,IF(_xlpm.komplex,L$26*(_xlpm.h_knee*SIN(_xlpm.alpha*PI()/180))/(_xlpm.h_room-_xlpm.h_knee),_xlpm.h_knee*IN_rooms!U$30))), _xlpm.A_no_slop,_xlpm.L_wall*_xlpm.h_room, _xlpm.A_big_rect,_xlpm.h_room*_xlpm.b_ceil, _xlpm.A_triangle,1/4*_xlpm.h_roof^2*SIN(2*_xlpm.alpha*PI()/180), _xlpm.A_small_rect,_xlpm.h_knee*_xlpm.h_roof*COS(_xlpm.alpha*PI()/180), _xlpm.A_triangle_jamb,1/2*_xlpm.h_knee^2*TAN(_xlpm.alpha*PI()/180), _xlpm.A_slop_tot,_xlpm.A_triangle+_xlpm.A_small_rect+IF(_xlpm.is_jamb,_xlpm.A_triangle_jamb,0), _xlpm.giebel_0,_xlpm.n_giebel=0, _xlpm.giebel_1_slop_1,AND(IN_rooms!U$28="Eine",_xlpm.n_giebel=1), _xlpm.giebel_2_slop_1,AND(IN_rooms!U$28="Eine",_xlpm.n_giebel=2), _xlpm.giebel_1_slop_2,AND(IN_rooms!U$28="Zwei (symmetrisch)",_xlpm.n_giebel=1), _xlpm.giebel_2_slop_2,AND(IN_rooms!U$28="Zwei (symmetrisch)",_xlpm.n_giebel=2), IF(_xlpm.komplex, MAX(MIN(_xlfn.IFS( _xlpm.giebel_0,_xlpm.L_wall*_xlpm.h_room, _xlpm.is_jamb,_xlpm.h_room^2/TAN(_xlpm.alpha*PI()/180), NOT(_xlpm.is_jamb),_xlpm.L_wall * (_xlpm.h_knee + 0.5 * (_xlpm.h_room - _xlpm.h_knee)), TRUE,_xlpm.A_no_slop),_xlpm.A_no_slop)+_xlpm.A_knee-_xlpm.A_win,0)*HLOOKUP("f_Awall_roof",PAR!$F$1:$Y$5,2,FALSE), MAX(MIN(_xlfn.IFS( _xlpm.giebel_0,_xlpm.A_no_slop, _xlpm.giebel_1_slop_1,_xlpm.A_big_rect+_xlpm.A_slop_tot, _xlpm.giebel_2_slop_1,2*(_xlpm.A_big_rect+_xlpm.A_slop_tot), _xlpm.giebel_1_slop_2,_xlpm.A_big_rect+2*_xlpm.A_slop_tot, _xlpm.giebel_2_slop_2,2*(_xlpm.A_big_rect+2*_xlpm.A_slop_tot), TRUE,_xlpm.A_no_slop),_xlpm.A_no_slop)+_xlpm.A_knee-_xlpm.A_win,0)*HLOOKUP("f_Awall_roof",PAR!$F$1:$Y$5,2,FALSE) )))} -> 0 | M14: {=IF( OR(IN_rooms!V$28="Keine",IN_rooms!V$28="Flachdach",IN_rooms!V$31=0,IN_rooms!V$30=0,IN_build!$P$4="Flach bzw. Flachdach"), ((IN_rooms!V$9+HLOOKUP("f_A_wall_wid",PAR!$F$1:$Y$5,2,FALSE))*(IN_rooms!V$5+HLOOKUP("f_A_wall_hei",PAR!$F$1:$Y$5,2,FALSE))-(M$42+M$48+M$54))*(IN_rooms!V$9>0), _xlfn.LET( _xlpm.komplex,IN_rooms!V$28="Komplex", _xlpm.b_ceil,IN_rooms!V$32, _xlpm.L_wall,(IN_rooms!V$9+HLOOKUP("f_A_wall_wid",PAR!$F$1:$Y$5,2,FALSE))*(IN_rooms!V$9>0), _xlpm.n_giebel,IF(_xlpm.L_wall=0,0,IN_rooms!V33), _xlpm.h_knee,IN_rooms!V$34, _xlpm.h_roof,IN_rooms!V$31, _xlpm.is_jamb,IN_rooms!V$35="Ja", _xlpm.h_room,IN_rooms!V$5+HLOOKUP("f_A_wall_hei",PAR!$F$1:$Y$5,2,FALSE), _xlpm.alpha,_xlfn.IFS( IN_build!$P$4="geneigt",25, IN_build!$P$4="steil",40, IN_build!$P$4="sehr steil",55), _xlpm.A_win,(M$42+M$48+M$54), _xlpm.A_knee,MAX(0,IF(_xlpm.is_jamb,0,IF(_xlpm.komplex,M$26*(_xlpm.h_knee*SIN(_xlpm.alpha*PI()/180))/(_xlpm.h_room-_xlpm.h_knee),_xlpm.h_knee*IN_rooms!V$30))), _xlpm.A_no_slop,_xlpm.L_wall*_xlpm.h_room, _xlpm.A_big_rect,_xlpm.h_room*_xlpm.b_ceil, _xlpm.A_triangle,1/4*_xlpm.h_roof^2*SIN(2*_xlpm.alpha*PI()/180), _xlpm.A_small_rect,_xlpm.h_knee*_xlpm.h_roof*COS(_xlpm.alpha*PI()/180), _xlpm.A_triangle_jamb,1/2*_xlpm.h_knee^2*TAN(_xlpm.alpha*PI()/180), _xlpm.A_slop_tot,_xlpm.A_triangle+_xlpm.A_small_rect+IF(_xlpm.is_jamb,_xlpm.A_triangle_jamb,0), _xlpm.giebel_0,_xlpm.n_giebel=0, _xlpm.giebel_1_slop_1,AND(IN_rooms!V$28="Eine",_xlpm.n_giebel=1), _xlpm.giebel_2_slop_1,AND(IN_rooms!V$28="Eine",_xlpm.n_giebel=2), _xlpm.giebel_1_slop_2,AND(IN_rooms!V$28="Zwei (symmetrisch)",_xlpm.n_giebel=1), _xlpm.giebel_2_slop_2,AND(IN_rooms!V$28="Zwei (symmetrisch)",_xlpm.n_giebel=2), IF(_xlpm.komplex, MAX(MIN(_xlfn.IFS( _xlpm.giebel_0,_xlpm.L_wall*_xlpm.h_room, _xlpm.is_jamb,_xlpm.h_room^2/TAN(_xlpm.alpha*PI()/180), NOT(_xlpm.is_jamb),_xlpm.L_wall * (_xlpm.h_knee + 0.5 * (_xlpm.h_room - _xlpm.h_knee)), TRUE,_xlpm.A_no_slop),_xlpm.A_no_slop)+_xlpm.A_knee-_xlpm.A_win,0)*HLOOKUP("f_Awall_roof",PAR!$F$1:$Y$5,2,FALSE), MAX(MIN(_xlfn.IFS( _xlpm.giebel_0,_xlpm.A_no_slop, _xlpm.giebel_1_slop_1,_xlpm.A_big_rect+_xlpm.A_slop_tot, _xlpm.giebel_2_slop_1,2*(_xlpm.A_big_rect+_xlpm.A_slop_tot), _xlpm.giebel_1_slop_2,_xlpm.A_big_rect+2*_xlpm.A_slop_tot, _xlpm.giebel_2_slop_2,2*(_xlpm.A_big_rect+2*_xlpm.A_slop_tot), TRUE,_xlpm.A_no_slop),_xlpm.A_no_slop)+_xlpm.A_knee-_xlpm.A_win,0)*HLOOKUP("f_Awall_roof",PAR!$F$1:$Y$5,2,FALSE) )))} -> 0 | N14: {=IF( OR(IN_rooms!W$28="Keine",IN_rooms!W$28="Flachdach",IN_rooms!W$31=0,IN_rooms!W$30=0,IN_build!$P$4="Flach bzw. Flachdach"), ((IN_rooms!W$9+HLOOKUP("f_A_wall_wid",PAR!$F$1:$Y$5,2,FALSE))*(IN_rooms!W$5+HLOOKUP("f_A_wall_hei",PAR!$F$1:$Y$5,2,FALSE))-(N$42+N$48+N$54))*(IN_rooms!W$9>0), _xlfn.LET( _xlpm.komplex,IN_rooms!W$28="Komplex", _xlpm.b_ceil,IN_rooms!W$32, _xlpm.L_wall,(IN_rooms!W$9+HLOOKUP("f_A_wall_wid",PAR!$F$1:$Y$5,2,FALSE))*(IN_rooms!W$9>0), _xlpm.n_giebel,IF(_xlpm.L_wall=0,0,IN_rooms!W33), _xlpm.h_knee,IN_rooms!W$34, _xlpm.h_roof,IN_rooms!W$31, _xlpm.is_jamb,IN_rooms!W$35="Ja", _xlpm.h_room,IN_rooms!W$5+HLOOKUP("f_A_wall_hei",PAR!$F$1:$Y$5,2,FALSE), _xlpm.alpha,_xlfn.IFS( IN_build!$P$4="geneigt",25, IN_build!$P$4="steil",40, IN_build!$P$4="sehr steil",55), _xlpm.A_win,(N$42+N$48+N$54), _xlpm.A_knee,MAX(0,IF(_xlpm.is_jamb,0,IF(_xlpm.komplex,N$26*(_xlpm.h_knee*SIN(_xlpm.alpha*PI()/180))/(_xlpm.h_room-_xlpm.h_knee),_xlpm.h_knee*IN_rooms!W$30))), _xlpm.A_no_slop,_xlpm.L_wall*_xlpm.h_room, _xlpm.A_big_rect,_xlpm.h_room*_xlpm.b_ceil, _xlpm.A_triangle,1/4*_xlpm.h_roof^2*SIN(2*_xlpm.alpha*PI()/180), _xlpm.A_small_rect,_xlpm.h_knee*_xlpm.h_roof*COS(_xlpm.alpha*PI()/180), _xlpm.A_triangle_jamb,1/2*_xlpm.h_knee^2*TAN(_xlpm.alpha*PI()/180), _xlpm.A_slop_tot,_xlpm.A_triangle+_xlpm.A_small_rect+IF(_xlpm.is_jamb,_xlpm.A_triangle_jamb,0), _xlpm.giebel_0,_xlpm.n_giebel=0, _xlpm.giebel_1_slop_1,AND(IN_rooms!W$28="Eine",_xlpm.n_giebel=1), _xlpm.giebel_2_slop_1,AND(IN_rooms!W$28="Eine",_xlpm.n_giebel=2), _xlpm.giebel_1_slop_2,AND(IN_rooms!W$28="Zwei (symmetrisch)",_xlpm.n_giebel=1), _xlpm.giebel_2_slop_2,AND(IN_rooms!W$28="Zwei (symmetrisch)",_xlpm.n_giebel=2), IF(_xlpm.komplex, MAX(MIN(_xlfn.IFS( _xlpm.giebel_0,_xlpm.L_wall*_xlpm.h_room, _xlpm.is_jamb,_xlpm.h_room^2/TAN(_xlpm.alpha*PI()/180), NOT(_xlpm.is_jamb),_xlpm.L_wall * (_xlpm.h_knee + 0.5 * (_xlpm.h_room - _xlpm.h_knee)), TRUE,_xlpm.A_no_slop),_xlpm.A_no_slop)+_xlpm.A_knee-_xlpm.A_win,0)*HLOOKUP("f_Awall_roof",PAR!$F$1:$Y$5,2,FALSE), MAX(MIN(_xlfn.IFS( _xlpm.giebel_0,_xlpm.A_no_slop, _xlpm.giebel_1_slop_1,_xlpm.A_big_rect+_xlpm.A_slop_tot, _xlpm.giebel_2_slop_1,2*(_xlpm.A_big_rect+_xlpm.A_slop_tot), _xlpm.giebel_1_slop_2,_xlpm.A_big_rect+2*_xlpm.A_slop_tot, _xlpm.giebel_2_slop_2,2*(_xlpm.A_big_rect+2*_xlpm.A_slop_tot), TRUE,_xlpm.A_no_slop),_xlpm.A_no_slop)+_xlpm.A_knee-_xlpm.A_win,0)*HLOOKUP("f_Awall_roof",PAR!$F$1:$Y$5,2,FALSE) )))} -> 0 | O14: {=IF( OR(IN_rooms!X$28="Keine",IN_rooms!X$28="Flachdach",IN_rooms!X$31=0,IN_rooms!X$30=0,IN_build!$P$4="Flach bzw. Flachdach"), ((IN_rooms!X$9+HLOOKUP("f_A_wall_wid",PAR!$F$1:$Y$5,2,FALSE))*(IN_rooms!X$5+HLOOKUP("f_A_wall_hei",PAR!$F$1:$Y$5,2,FALSE))-(O$42+O$48+O$54))*(IN_rooms!X$9>0), _xlfn.LET( _xlpm.komplex,IN_rooms!X$28="Komplex", _xlpm.b_ceil,IN_rooms!X$32, _xlpm.L_wall,(IN_rooms!X$9+HLOOKUP("f_A_wall_wid",PAR!$F$1:$Y$5,2,FALSE))*(IN_rooms!X$9>0), _xlpm.n_giebel,IF(_xlpm.L_wall=0,0,IN_rooms!X33), _xlpm.h_knee,IN_rooms!X$34, _xlpm.h_roof,IN_rooms!X$31, _xlpm.is_jamb,IN_rooms!X$35="Ja", _xlpm.h_room,IN_rooms!X$5+HLOOKUP("f_A_wall_hei",PAR!$F$1:$Y$5,2,FALSE), _xlpm.alpha,_xlfn.IFS( IN_build!$P$4="geneigt",25, IN_build!$P$4="steil",40, IN_build!$P$4="sehr steil",55), _xlpm.A_win,(O$42+O$48+O$54), _xlpm.A_knee,MAX(0,IF(_xlpm.is_jamb,0,IF(_xlpm.komplex,O$26*(_xlpm.h_knee*SIN(_xlpm.alpha*PI()/180))/(_xlpm.h_room-_xlpm.h_knee),_xlpm.h_knee*IN_rooms!X$30))), _xlpm.A_no_slop,_xlpm.L_wall*_xlpm.h_room, _xlpm.A_big_rect,_xlpm.h_room*_xlpm.b_ceil, _xlpm.A_triangle,1/4*_xlpm.h_roof^2*SIN(2*_xlpm.alpha*PI()/180), _xlpm.A_small_rect,_xlpm.h_knee*_xlpm.h_roof*COS(_xlpm.alpha*PI()/180), _xlpm.A_triangle_jamb,1/2*_xlpm.h_knee^2*TAN(_xlpm.alpha*PI()/180), _xlpm.A_slop_tot,_xlpm.A_triangle+_xlpm.A_small_rect+IF(_xlpm.is_jamb,_xlpm.A_triangle_jamb,0), _xlpm.giebel_0,_xlpm.n_giebel=0, _xlpm.giebel_1_slop_1,AND(IN_rooms!X$28="Eine",_xlpm.n_giebel=1), _xlpm.giebel_2_slop_1,AND(IN_rooms!X$28="Eine",_xlpm.n_giebel=2), _xlpm.giebel_1_slop_2,AND(IN_rooms!X$28="Zwei (symmetrisch)",_xlpm.n_giebel=1), _xlpm.giebel_2_slop_2,AND(IN_rooms!X$28="Zwei (symmetrisch)",_xlpm.n_giebel=2), IF(_xlpm.komplex, MAX(MIN(_xlfn.IFS( _xlpm.giebel_0,_xlpm.L_wall*_xlpm.h_room, _xlpm.is_jamb,_xlpm.h_room^2/TAN(_xlpm.alpha*PI()/180), NOT(_xlpm.is_jamb),_xlpm.L_wall * (_xlpm.h_knee + 0.5 * (_xlpm.h_room - _xlpm.h_knee)), TRUE,_xlpm.A_no_slop),_xlpm.A_no_slop)+_xlpm.A_knee-_xlpm.A_win,0)*HLOOKUP("f_Awall_roof",PAR!$F$1:$Y$5,2,FALSE), MAX(MIN(_xlfn.IFS( _xlpm.giebel_0,_xlpm.A_no_slop, _xlpm.giebel_1_slop_1,_xlpm.A_big_rect+_xlpm.A_slop_tot, _xlpm.giebel_2_slop_1,2*(_xlpm.A_big_rect+_xlpm.A_slop_tot), _xlpm.giebel_1_slop_2,_xlpm.A_big_rect+2*_xlpm.A_slop_tot, _xlpm.giebel_2_slop_2,2*(_xlpm.A_big_rect+2*_xlpm.A_slop_tot), TRUE,_xlpm.A_no_slop),_xlpm.A_no_slop)+_xlpm.A_knee-_xlpm.A_win,0)*HLOOKUP("f_Awall_roof",PAR!$F$1:$Y$5,2,FALSE) )))} -> 0 | P14: {=IF( OR(IN_rooms!Y$28="Keine",IN_rooms!Y$28="Flachdach",IN_rooms!Y$31=0,IN_rooms!Y$30=0,IN_build!$P$4="Flach bzw. Flachdach"), ((IN_rooms!Y$9+HLOOKUP("f_A_wall_wid",PAR!$F$1:$Y$5,2,FALSE))*(IN_rooms!Y$5+HLOOKUP("f_A_wall_hei",PAR!$F$1:$Y$5,2,FALSE))-(P$42+P$48+P$54))*(IN_rooms!Y$9>0), _xlfn.LET( _xlpm.komplex,IN_rooms!Y$28="Komplex", _xlpm.b_ceil,IN_rooms!Y$32, _xlpm.L_wall,(IN_rooms!Y$9+HLOOKUP("f_A_wall_wid",PAR!$F$1:$Y$5,2,FALSE))*(IN_rooms!Y$9>0), _xlpm.n_giebel,IF(_xlpm.L_wall=0,0,IN_rooms!Y33), _xlpm.h_knee,IN_rooms!Y$34, _xlpm.h_roof,IN_rooms!Y$31, _xlpm.is_jamb,IN_rooms!Y$35="Ja", _xlpm.h_room,IN_rooms!Y$5+HLOOKUP("f_A_wall_hei",PAR!$F$1:$Y$5,2,FALSE), _xlpm.alpha,_xlfn.IFS( IN_build!$P$4="geneigt",25, IN_build!$P$4="steil",40, IN_build!$P$4="sehr steil",55), _xlpm.A_win,(P$42+P$48+P$54), _xlpm.A_knee,MAX(0,IF(_xlpm.is_jamb,0,IF(_xlpm.komplex,P$26*(_xlpm.h_knee*SIN(_xlpm.alpha*PI()/180))/(_xlpm.h_room-_xlpm.h_knee),_xlpm.h_knee*IN_rooms!Y$30))), _xlpm.A_no_slop,_xlpm.L_wall*_xlpm.h_room, _xlpm.A_big_rect,_xlpm.h_room*_xlpm.b_ceil, _xlpm.A_triangle,1/4*_xlpm.h_roof^2*SIN(2*_xlpm.alpha*PI()/180), _xlpm.A_small_rect,_xlpm.h_knee*_xlpm.h_roof*COS(_xlpm.alpha*PI()/180), _xlpm.A_triangle_jamb,1/2*_xlpm.h_knee^2*TAN(_xlpm.alpha*PI()/180), _xlpm.A_slop_tot,_xlpm.A_triangle+_xlpm.A_small_rect+IF(_xlpm.is_jamb,_xlpm.A_triangle_jamb,0), _xlpm.giebel_0,_xlpm.n_giebel=0, _xlpm.giebel_1_slop_1,AND(IN_rooms!Y$28="Eine",_xlpm.n_giebel=1), _xlpm.giebel_2_slop_1,AND(IN_rooms!Y$28="Eine",_xlpm.n_giebel=2), _xlpm.giebel_1_slop_2,AND(IN_rooms!Y$28="Zwei (symmetrisch)",_xlpm.n_giebel=1), _xlpm.giebel_2_slop_2,AND(IN_rooms!Y$28="Zwei (symmetrisch)",_xlpm.n_giebel=2), IF(_xlpm.komplex, MAX(MIN(_xlfn.IFS( _xlpm.giebel_0,_xlpm.L_wall*_xlpm.h_room, _xlpm.is_jamb,_xlpm.h_room^2/TAN(_xlpm.alpha*PI()/180), NOT(_xlpm.is_jamb),_xlpm.L_wall * (_xlpm.h_knee + 0.5 * (_xlpm.h_room - _xlpm.h_knee)), TRUE,_xlpm.A_no_slop),_xlpm.A_no_slop)+_xlpm.A_knee-_xlpm.A_win,0)*HLOOKUP("f_Awall_roof",PAR!$F$1:$Y$5,2,FALSE), MAX(MIN(_xlfn.IFS( _xlpm.giebel_0,_xlpm.A_no_slop, _xlpm.giebel_1_slop_1,_xlpm.A_big_rect+_xlpm.A_slop_tot, _xlpm.giebel_2_slop_1,2*(_xlpm.A_big_rect+_xlpm.A_slop_tot), _xlpm.giebel_1_slop_2,_xlpm.A_big_rect+2*_xlpm.A_slop_tot, _xlpm.giebel_2_slop_2,2*(_xlpm.A_big_rect+2*_xlpm.A_slop_tot), TRUE,_xlpm.A_no_slop),_xlpm.A_no_slop)+_xlpm.A_knee-_xlpm.A_win,0)*HLOOKUP("f_Awall_roof",PAR!$F$1:$Y$5,2,FALSE) )))} -> 0 | ... W14: {=IF( OR(IN_rooms!AF$28="Keine",IN_rooms!AF$28="Flachdach",IN_rooms!AF$31=0,IN_rooms!AF$30=0,IN_build!$P$4="Flach bzw. Flachdach"), ((IN_rooms!AF$9+HLOOKUP("f_A_wall_wid",PAR!$F$1:$Y$5,2,FALSE))*(IN_rooms!AF$5+HLOOKUP("f_A_wall_hei",PAR!$F$1:$Y$5,2,FALSE))-(W$42+W$48+W$54))*(IN_rooms!AF$9>0), _xlfn.LET( _xlpm.komplex,IN_rooms!AF$28="Komplex", _xlpm.b_ceil,IN_rooms!AF$32, _xlpm.L_wall,(IN_rooms!AF$9+HLOOKUP("f_A_wall_wid",PAR!$F$1:$Y$5,2,FALSE))*(IN_rooms!AF$9>0), _xlpm.n_giebel,IF(_xlpm.L_wall=0,0,IN_rooms!AF33), _xlpm.h_knee,IN_rooms!AF$34, _xlpm.h_roof,IN_rooms!AF$31, _xlpm.is_jamb,IN_rooms!AF$35="Ja", _xlpm.h_room,IN_rooms!AF$5+HLOOKUP("f_A_wall_hei",PAR!$F$1:$Y$5,2,FALSE), _xlpm.alpha,_xlfn.IFS( IN_build!$P$4="geneigt",25, IN_build!$P$4="steil",40, IN_build!$P$4="sehr steil",55), _xlpm.A_win,(W$42+W$48+W$54), _xlpm.A_knee,MAX(0,IF(_xlpm.is_jamb,0,IF(_xlpm.komplex,W$26*(_xlpm.h_knee*SIN(_xlpm.alpha*PI()/180))/(_xlpm.h_room-_xlpm.h_knee),_xlpm.h_knee*IN_rooms!AF$30))), _xlpm.A_no_slop,_xlpm.L_wall*_xlpm.h_room, _xlpm.A_big_rect,_xlpm.h_room*_xlpm.b_ceil, _xlpm.A_triangle,1/4*_xlpm.h_roof^2*SIN(2*_xlpm.alpha*PI()/180), _xlpm.A_small_rect,_xlpm.h_knee*_xlpm.h_roof*COS(_xlpm.alpha*PI()/180), _xlpm.A_triangle_jamb,1/2*_xlpm.h_knee^2*TAN(_xlpm.alpha*PI()/180), _xlpm.A_slop_tot,_xlpm.A_triangle+_xlpm.A_small_rect+IF(_xlpm.is_jamb,_xlpm.A_triangle_jamb,0), _xlpm.giebel_0,_xlpm.n_giebel=0, _xlpm.giebel_1_slop_1,AND(IN_rooms!AF$28="Eine",_xlpm.n_giebel=1), _xlpm.giebel_2_slop_1,AND(IN_rooms!AF$28="Eine",_xlpm.n_giebel=2), _xlpm.giebel_1_slop_2,AND(IN_rooms!AF$28="Zwei (symmetrisch)",_xlpm.n_giebel=1), _xlpm.giebel_2_slop_2,AND(IN_rooms!AF$28="Zwei (symmetrisch)",_xlpm.n_giebel=2), IF(_xlpm.komplex, MAX(MIN(_xlfn.IFS( _xlpm.giebel_0,_xlpm.L_wall*_xlpm.h_room, _xlpm.is_jamb,_xlpm.h_room^2/TAN(_xlpm.alpha*PI()/180), NOT(_xlpm.is_jamb),_xlpm.L_wall * (_xlpm.h_knee + 0.5 * (_xlpm.h_room - _xlpm.h_knee)), TRUE,_xlpm.A_no_slop),_xlpm.A_no_slop)+_xlpm.A_knee-_xlpm.A_win,0)*HLOOKUP("f_Awall_roof",PAR!$F$1:$Y$5,2,FALSE), MAX(MIN(_xlfn.IFS( _xlpm.giebel_0,_xlpm.A_no_slop, _xlpm.giebel_1_slop_1,_xlpm.A_big_rect+_xlpm.A_slop_tot, _xlpm.giebel_2_slop_1,2*(_xlpm.A_big_rect+_xlpm.A_slop_tot), _xlpm.giebel_1_slop_2,_xlpm.A_big_rect+2*_xlpm.A_slop_tot, _xlpm.giebel_2_slop_2,2*(_xlpm.A_big_rect+2*_xlpm.A_slop_tot), TRUE,_xlpm.A_no_slop),_xlpm.A_no_slop)+_xlpm.A_knee-_xlpm.A_win,0)*HLOOKUP("f_Awall_roof",PAR!$F$1:$Y$5,2,FALSE) )))} -> 0
A15: Außenwand | B15: U-Wert_IWU | C15: wall | E15: U_wall_bj | F15: W/m²K | I15: {=IF(I14=0,0,_xlfn.AGGREGATE(15,6,U_Werte_IWU!$F$30:$F$297/((U_Werte_IWU!$E$30:$E$297=LEFT($A$14,9))*(U_Werte_IWU!$D$30:$D$297=clc_load!I4)*(U_Werte_IWU!$C$30:$C$297=clc_load!I3)),1))} -> 0 | J15: {=IF(J14=0,0,_xlfn.AGGREGATE(15,6,U_Werte_IWU!$F$30:$F$297/((U_Werte_IWU!$E$30:$E$297=LEFT($A$14,9))*(U_Werte_IWU!$D$30:$D$297=clc_load!J4)*(U_Werte_IWU!$C$30:$C$297=clc_load!J3)),1))} -> 0 | K15: {=IF(K14=0,0,_xlfn.AGGREGATE(15,6,U_Werte_IWU!$F$30:$F$297/((U_Werte_IWU!$E$30:$E$297=LEFT($A$14,9))*(U_Werte_IWU!$D$30:$D$297=clc_load!K4)*(U_Werte_IWU!$C$30:$C$297=clc_load!K3)),1))} -> 0 | L15: {=IF(L14=0,0,_xlfn.AGGREGATE(15,6,U_Werte_IWU!$F$30:$F$297/((U_Werte_IWU!$E$30:$E$297=LEFT($A$14,9))*(U_Werte_IWU!$D$30:$D$297=clc_load!L4)*(U_Werte_IWU!$C$30:$C$297=clc_load!L3)),1))} -> 0 | M15: {=IF(M14=0,0,_xlfn.AGGREGATE(15,6,U_Werte_IWU!$F$30:$F$297/((U_Werte_IWU!$E$30:$E$297=LEFT($A$14,9))*(U_Werte_IWU!$D$30:$D$297=clc_load!M4)*(U_Werte_IWU!$C$30:$C$297=clc_load!M3)),1))} -> 0 | N15: {=IF(N14=0,0,_xlfn.AGGREGATE(15,6,U_Werte_IWU!$F$30:$F$297/((U_Werte_IWU!$E$30:$E$297=LEFT($A$14,9))*(U_Werte_IWU!$D$30:$D$297=clc_load!N4)*(U_Werte_IWU!$C$30:$C$297=clc_load!N3)),1))} -> 0 | O15: {=IF(O14=0,0,_xlfn.AGGREGATE(15,6,U_Werte_IWU!$F$30:$F$297/((U_Werte_IWU!$E$30:$E$297=LEFT($A$14,9))*(U_Werte_IWU!$D$30:$D$297=clc_load!O4)*(U_Werte_IWU!$C$30:$C$297=clc_load!O3)),1))} -> 0 | P15: {=IF(P14=0,0,_xlfn.AGGREGATE(15,6,U_Werte_IWU!$F$30:$F$297/((U_Werte_IWU!$E$30:$E$297=LEFT($A$14,9))*(U_Werte_IWU!$D$30:$D$297=clc_load!P4)*(U_Werte_IWU!$C$30:$C$297=clc_load!P3)),1))} -> 0 | ... W15: {=IF(W14=0,0,_xlfn.AGGREGATE(15,6,U_Werte_IWU!$F$30:$F$297/((U_Werte_IWU!$E$30:$E$297=LEFT($A$14,9))*(U_Werte_IWU!$D$30:$D$297=clc_load!W4)*(U_Werte_IWU!$C$30:$C$297=clc_load!W3)),1))} -> 0
A16: Außenwand | B16: U-Wert_Berechnung | C16: wall | E16: U_wall_calc | F16: W/m²K | I16: {=_xlfn.LET( _xlpm.U_no_ins, _xlfn.XLOOKUP(1, (INDIRECT("UWert_Mod[Bauteil]")=$A$16)* (INDIRECT("UWert_Mod[Modernisierungsjahr]")="1983 - 1994"), INDIRECT("UWert_Mod[U_no_ins]")), _xlpm.U_IWU, I$15, _xlpm.d_ins,IN_rooms!R$75, IF(_xlpm.d_ins>0,1/(1/_xlpm.U_no_ins+_xlpm.d_ins*0.01/INDEX(INDIRECT("PAR[lambda_ins_thick]"), 1)),_xlpm.U_IWU))} -> 0 | J16: {=_xlfn.LET( _xlpm.U_no_ins, _xlfn.XLOOKUP(1, (INDIRECT("UWert_Mod[Bauteil]")=$A$16)* (INDIRECT("UWert_Mod[Modernisierungsjahr]")="1983 - 1994"), INDIRECT("UWert_Mod[U_no_ins]")), _xlpm.U_IWU, J$15, _xlpm.d_ins,IN_rooms!S$75, IF(_xlpm.d_ins>0,1/(1/_xlpm.U_no_ins+_xlpm.d_ins*0.01/INDEX(INDIRECT("PAR[lambda_ins_thick]"), 1)),_xlpm.U_IWU))} -> 0 | K16: {=_xlfn.LET( _xlpm.U_no_ins, _xlfn.XLOOKUP(1, (INDIRECT("UWert_Mod[Bauteil]")=$A$16)* (INDIRECT("UWert_Mod[Modernisierungsjahr]")="1983 - 1994"), INDIRECT("UWert_Mod[U_no_ins]")), _xlpm.U_IWU, K$15, _xlpm.d_ins,IN_rooms!T$75, IF(_xlpm.d_ins>0,1/(1/_xlpm.U_no_ins+_xlpm.d_ins*0.01/INDEX(INDIRECT("PAR[lambda_ins_thick]"), 1)),_xlpm.U_IWU))} -> 0 | L16: {=_xlfn.LET( _xlpm.U_no_ins, _xlfn.XLOOKUP(1, (INDIRECT("UWert_Mod[Bauteil]")=$A$16)* (INDIRECT("UWert_Mod[Modernisierungsjahr]")="1983 - 1994"), INDIRECT("UWert_Mod[U_no_ins]")), _xlpm.U_IWU, L$15, _xlpm.d_ins,IN_rooms!U$75, IF(_xlpm.d_ins>0,1/(1/_xlpm.U_no_ins+_xlpm.d_ins*0.01/INDEX(INDIRECT("PAR[lambda_ins_thick]"), 1)),_xlpm.U_IWU))} -> 0 | M16: {=_xlfn.LET( _xlpm.U_no_ins, _xlfn.XLOOKUP(1, (INDIRECT("UWert_Mod[Bauteil]")=$A$16)* (INDIRECT("UWert_Mod[Modernisierungsjahr]")="1983 - 1994"), INDIRECT("UWert_Mod[U_no_ins]")), _xlpm.U_IWU, M$15, _xlpm.d_ins,IN_rooms!V$75, IF(_xlpm.d_ins>0,1/(1/_xlpm.U_no_ins+_xlpm.d_ins*0.01/INDEX(INDIRECT("PAR[lambda_ins_thick]"), 1)),_xlpm.U_IWU))} -> 0 | N16: {=_xlfn.LET( _xlpm.U_no_ins, _xlfn.XLOOKUP(1, (INDIRECT("UWert_Mod[Bauteil]")=$A$16)* (INDIRECT("UWert_Mod[Modernisierungsjahr]")="1983 - 1994"), INDIRECT("UWert_Mod[U_no_ins]")), _xlpm.U_IWU, N$15, _xlpm.d_ins,IN_rooms!W$75, IF(_xlpm.d_ins>0,1/(1/_xlpm.U_no_ins+_xlpm.d_ins*0.01/INDEX(INDIRECT("PAR[lambda_ins_thick]"), 1)),_xlpm.U_IWU))} -> 0 | O16: {=_xlfn.LET( _xlpm.U_no_ins, _xlfn.XLOOKUP(1, (INDIRECT("UWert_Mod[Bauteil]")=$A$16)* (INDIRECT("UWert_Mod[Modernisierungsjahr]")="1983 - 1994"), INDIRECT("UWert_Mod[U_no_ins]")), _xlpm.U_IWU, O$15, _xlpm.d_ins,IN_rooms!X$75, IF(_xlpm.d_ins>0,1/(1/_xlpm.U_no_ins+_xlpm.d_ins*0.01/INDEX(INDIRECT("PAR[lambda_ins_thick]"), 1)),_xlpm.U_IWU))} -> 0 | P16: {=_xlfn.LET( _xlpm.U_no_ins, _xlfn.XLOOKUP(1, (INDIRECT("UWert_Mod[Bauteil]")=$A$16)* (INDIRECT("UWert_Mod[Modernisierungsjahr]")="1983 - 1994"), INDIRECT("UWert_Mod[U_no_ins]")), _xlpm.U_IWU, P$15, _xlpm.d_ins,IN_rooms!Y$75, IF(_xlpm.d_ins>0,1/(1/_xlpm.U_no_ins+_xlpm.d_ins*0.01/INDEX(INDIRECT("PAR[lambda_ins_thick]"), 1)),_xlpm.U_IWU))} -> 0 | ... W16: {=_xlfn.LET( _xlpm.U_no_ins, _xlfn.XLOOKUP(1, (INDIRECT("UWert_Mod[Bauteil]")=$A$16)* (INDIRECT("UWert_Mod[Modernisierungsjahr]")="1983 - 1994"), INDIRECT("UWert_Mod[U_no_ins]")), _xlpm.U_IWU, W$15, _xlpm.d_ins,IN_rooms!AF$75, IF(_xlpm.d_ins>0,1/(1/_xlpm.U_no_ins+_xlpm.d_ins*0.01/INDEX(INDIRECT("PAR[lambda_ins_thick]"), 1)),_xlpm.U_IWU))} -> 0
A17: Außenwand | B17: Heizlast Transmission | C17: wall | E17: Qdot_wall_trans | F17: W | I17: =IF(I14=0,0,I14*(I16+I$8)*_xlfn.XLOOKUP(IN_rooms!R12,Daten!$E$106:$E$109,Daten!$F$106:$F$109,"FEHLER",0,1)*(I$10-Normaußentemperatur_12831!$B$6)) -> 0 | J17: =IF(J14=0,0,J14*(J16+J$8)*_xlfn.XLOOKUP(IN_rooms!S12,Daten!$E$106:$E$109,Daten!$F$106:$F$109,"FEHLER",0,1)*(J$10-Normaußentemperatur_12831!$B$6)) -> 0 | K17: =IF(K14=0,0,K14*(K16+K$8)*_xlfn.XLOOKUP(IN_rooms!T12,Daten!$E$106:$E$109,Daten!$F$106:$F$109,"FEHLER",0,1)*(K$10-Normaußentemperatur_12831!$B$6)) -> 0 | L17: =IF(L14=0,0,L14*(L16+L$8)*_xlfn.XLOOKUP(IN_rooms!U12,Daten!$E$106:$E$109,Daten!$F$106:$F$109,"FEHLER",0,1)*(L$10-Normaußentemperatur_12831!$B$6)) -> 0 | M17: =IF(M14=0,0,M14*(M16+M$8)*_xlfn.XLOOKUP(IN_rooms!V12,Daten!$E$106:$E$109,Daten!$F$106:$F$109,"FEHLER",0,1)*(M$10-Normaußentemperatur_12831!$B$6)) -> 0 | N17: =IF(N14=0,0,N14*(N16+N$8)*_xlfn.XLOOKUP(IN_rooms!W12,Daten!$E$106:$E$109,Daten!$F$106:$F$109,"FEHLER",0,1)*(N$10-Normaußentemperatur_12831!$B$6)) -> 0 | O17: =IF(O14=0,0,O14*(O16+O$8)*_xlfn.XLOOKUP(IN_rooms!X12,Daten!$E$106:$E$109,Daten!$F$106:$F$109,"FEHLER",0,1)*(O$10-Normaußentemperatur_12831!$B$6)) -> 0 | P17: =IF(P14=0,0,P14*(P16+P$8)*_xlfn.XLOOKUP(IN_rooms!Y12,Daten!$E$106:$E$109,Daten!$F$106:$F$109,"FEHLER",0,1)*(P$10-Normaußentemperatur_12831!$B$6)) -> 0 | ... W17: =IF(W14=0,0,W14*(W16+W$8)*_xlfn.XLOOKUP(IN_rooms!AF12,Daten!$E$106:$E$109,Daten!$F$106:$F$109,"FEHLER",0,1)*(W$10-Normaußentemperatur_12831!$B$6)) -> 0
A18: Außenwand | B18: Anteil an Raumheizlast | C18: wall | E18: r_Qdot_wall_trans | F18: % | I18: =I$17/I$72 -> #NUM! | J18: =J$17/J$72 -> #NUM! | K18: =K$17/K$72 -> #NUM! | L18: =L$17/L$72 -> #NUM! | M18: =M$17/M$72 -> #NUM! | N18: =N$17/N$72 -> #NUM! | O18: =O$17/O$72 -> #NUM! | P18: =P$17/P$72 -> #NUM! | ... W18: =W$17/W$72 -> #NUM!
