Workbook
Name Anbieter1: Eingabe_Angebotswerte!$E$9
Name Anbieter2: Eingabe_Angebotswerte!$F$9
Name Anbieter3: Eingabe_Angebotswerte!$G$9
Name Anbieter4: Eingabe_Angebotswerte!$H$9
Name Anbieter5: Eingabe_Angebotswerte!$I$9
Name AntrArtList: Listen!$B$8:$B$10
Name Antriebsart1: Eingabe_Angebotswerte!$E$7
Name Antriebsart2: Eingabe_Angebotswerte!$F$7
Name Antriebsart3: Eingabe_Angebotswerte!$G$7
Name Antriebsart4: Eingabe_Angebotswerte!$H$7
Name Antriebsart5: Eingabe_Angebotswerte!$I$7
Name Batterie_THG: Grunddaten!$G$42
Name Batterie1: Eingabe_Angebotswerte!$E$21
Name Batterie2: Eingabe_Angebotswerte!$F$21
Name Batterie3: Eingabe_Angebotswerte!$G$21
Name Batterie4: Eingabe_Angebotswerte!$H$21
Name Batterie5: Eingabe_Angebotswerte!$I$21
Name CO2_1: Eingabe_Angebotswerte!$E$17
Name CO2_2: Eingabe_Angebotswerte!$F$17
Name CO2_3: Eingabe_Angebotswerte!$G$17
Name CO2_4: Eingabe_Angebotswerte!$H$17
Name CO2_5: Eingabe_Angebotswerte!$I$17
Name CO2List: Emissionsfaktoren!$B$26:$D$29
Name Datum: Input_Projekt!$C$11
Name EnEinheitList: Listen!$B$20:$D$23
Name Energie1: Eingabe_Angebotswerte!$E$8
Name Energie2: Eingabe_Angebotswerte!$F$8
Name Energie3: Eingabe_Angebotswerte!$G$8
Name Energie4: Eingabe_Angebotswerte!$H$8
Name Energie5: Eingabe_Angebotswerte!$I$8
Name EnKostList: Grunddaten!$B$24:$G$29
Name EnList1: Erg.Pkw_1!$F$5:$F$8
Name EnList2: Erg.Pkw_2!$F$5:$F$8
Name EnList3: Erg.Pkw_3!$F$5:$F$8
Name EnList4: Erg.Pkw_4!$F$5:$F$8
Name EnList5: Erg.Pkw_5!$F$5:$F$8
Name EnUmrechList: Emissionsfaktoren!$B$16:$E$18
Name Fahrleistung: Input_Projekt!$C$15
Name FinArt: Input_Projekt!$C$17
Name FinArtList: Listen!$B$3:$D$5
Name Gesamtpreis1: Eingabe_Angebotswerte!$E$13
Name Gesamtpreis2: Eingabe_Angebotswerte!$F$13
Name Gesamtpreis3: Eingabe_Angebotswerte!$G$13
Name Gesamtpreis4: Eingabe_Angebotswerte!$H$13
Name Gesamtpreis5: Eingabe_Angebotswerte!$I$13
Name Haltedauer: Input_Projekt!$C$19
Name Hersteller1: Eingabe_Angebotswerte!$E$10
Name Hersteller2: Eingabe_Angebotswerte!$F$10
Name Hersteller3: Eingabe_Angebotswerte!$G$10
Name Hersteller4: Eingabe_Angebotswerte!$H$10
Name Hersteller5: Eingabe_Angebotswerte!$I$10
Name KaufpreisRech: Input_Projekt!$C$21
Name KaufpreisRechList: Listen!$B$26:$B$27
Name Kost_NOX: Grunddaten!$G$37
Name Kost_Partikel: Grunddaten!$G$38
Name Kost_THG: Grunddaten!$G$35
Name KostTHGList: Listen!$B$34:$B$35
Name KostTHGVorgabe: Input_Projekt!$C$24
Name LeasSondZahl1: Eingabe_Angebotswerte!$E$14
Name LeasSondZahl2: Eingabe_Angebotswerte!$F$14

Sheet Anleitung
B2: Lebenszykluskosten-Rechner für Pkw - beispielhaft mit Daten befüllt | J2: Version 1.2 - 10.01.2024
B5: Mit dem vorliegenden Excel-Tool können die Lebenszykluskosten von Pkw berechnet werden. Das Tool wurde vom ifeu entwickelt mit Unterstützung der DBU sowie der Bundesländer Berlin und Brandenburg. Das Tool richtet sich in erster Linie an Personen im Beschaffungsprozess, kann aber auch anderen Nutzergruppen wie Fachexperten, OEMs oder Autohäusern dienlich sein. Bei komplexen Beschaffungen wird die Zusammenarbeit mit Fachexperten empfohlen, die beim Befüllen der gefragten Daten unterstützen. Der hier vorliegende LZK-Rechner ist noch nicht Bestandteil der Landesvorschriften. Alle Kosten sind in EUR brutto (nach Steuern) einzugeben.
B7: Vorgehen
F9: Geben Sie die übergeordneten Informationen zu Ihrem Beschaffungsfall ein. Hier können Informationen wie die erwartete jährliche Laufleistung, die Art der Beschaffung (Kauf/Leasing) und weitere Informationen eingegeben werden.
F11: Fügen Sie die abgefragten Daten aus den Angeboten für alle Pkw ein. Die Datenabfrage wird der Ausschreibung beigefügt und umfasst u.a. den Preis, Verbrauchs- und Emissionsangaben und die Batteriegröße.
F15: Das Tool prüft bei Eingabe, ob die für die Lebenszykluskosten-Berechnung benötigten Werte der angebotenen Fahrzeuge Ihrer Beschaffungsvorschrift entsprechen. Abweichungen werden durch eine rote Markierung im Tabellenblatt "Eingabe_Angebotswerte" gekennzeichnet. Ggf. müssen Sie die voreingestellen Mindestanforderungen mit Ihren spezifischen Anforderungen abgleichen.
F18: Informieren Sie sich über die zur Berechnung verwendeten Energie- und Umweltkosten und ändern Sie diese ggf. entsprechend aktueller Vorgaben.
F20: Vergleichen Sie die Lebenszykluskosten der verschiedenen Angebote im Tabellenformat und in einer Vergleichsgrafik. Das Ranking der Angebote wird hier direkt angezeigt.
F24: Als Teilergebnis der Lebenszykluskosten werden hier ausschließlich die externen Umweltkosten dargestellt und entsprechend verglichen.
F28: Pro Pkw-Angebot finden Sie hier eine Ergebnisübersicht, die als PDF gespeichert/gedruckt werden kann.
B32: Im Tabellenblatt "Quellen" finden Sie Quellenangaben zu verwendeten Werten und Annahmen.
B34: Bedienung
D36: Eingabefelder: Hier sind die Werte aus den Angeboten einzugeben.
D38: Hier liegen Default-Werte vor, die für die Berechnungen verwendet werden. Es können auch eigene Daten eingegeben werden.
B41: bitte wählen | D41: Auswahlfelder: Durch Anklicken erscheint ein Dropdown-Menü.
B43: i | D43: Kommentarfelder mit Hilfestellungen zur Dateneingabe, Quellenangaben etc. Die Kommentarfelder befinden sich am linken Rand.
B46: Das Excel-Tool ist ohne Passwort geschützt. Der Blattschutz kann unter "Überprüfen -> Blattschutz aufheben" aufgehoben werden. Das Tool kann grundsätzlich nach eigenen Bedürfnissen angepasst werden. Es ist jedoch zu berücksichtigen, dass dadurch Berechnungsfehler entstehen können.
B48: Hinweise zum Tool
B50: Das ifeu - Institut für Energie- und Umweltforschung Heidelberg gGmbH übernimmt keine Haftung für die Richtigkeit der Berechnungen.
B52: Kontakt
B54: Julia Pelzeter - Fachbereich Mobilität
B55: ifeu - Institut für Energie- und Umweltforschung Heidelberg gGmbH, Wilckensstraße 3, 69120 Heidelberg
B56: Büro Berlin: Reinhardtstraße 50, 10117 Berlin
B57: Tel.: +49 (0) 30 284 45 78-23 | julia.pelzeter@ifeu.de

Sheet Input_Projekt
B2: DATENEINGABE Pkw-Beschaffungsprojekt | I2: zurück zu "Anleitung"
B4: Allgemeine Angaben (durch Beschaffer*in einzugeben)
B6: Projekt
B9: Unternehmen/öffentliche Einrichtung
B10: Zuständige Person
B11: Bearbeitungsdatum
A13: i | B13: Fahrzeugsegment
B15: Jahresfahrleistung pro Pkw | D15: km/Jahr
B17: Art der Beschaffung
B19: Haltedauer | D19: Jahre
A21: i | B21: Berücksichtigung des Fahrzeugpreises in der Lebenszykluskosten-Berechnung
A24: i | B24: CO2-Kosten | D24: EUR/t CO2eq | E24: Eigener Wert: | F24: =Grunddaten!E35 -> 0 | G24: EUR/t CO2eq
B26: Ladeverhalten Elektroauto
B28: Ergänzende Angaben für Elektrofahrzeuge: | D28: Eigenen Wert nutzen | J28: Anteil eff.
A29: i | B29: Anteil Strom aus eigener Ladestation | C29: 50 | E29: % | J29: =IF(ISNUMBER(D29),D29,C29) -> 50
B30: Anteil Strom an öffentlichen Säulen geladen | C30: =100-J29 -> 50

Sheet Eingabe_Angebotswerte
C2: DATENEINGABE Fahrzeugangaben -> wie von den Herstellern abgefragt | K2: zurück zu "Anleitung"
C4: Daten zur Lebenszykluskosten-Berechnung
C6: Angebotsnummer | E6: 1 | F6: 2 | G6: 3 | H6: 4 | I6: 5
C7: Antriebsart
C8: Energieträger | L8: =IF(J22>0,"FEHLER - bitte treffenden Energieträger wählen","")
C9: Anbieter
C10: Fahrzeughersteller | L10: WICHTIG !
C11: Modell | K11: Beim Kopieren immer nur Werte einfügen
C12: Zusatzinfos (Ausstattungslinie o.ä.) | K12: (Rechtsklick -> Werte einfügen)
C13: =IF(ISBLANK(FinArt), "Art der Beschaffung wählen in:", VLOOKUP(FinArt,FinArtList,3,FALSE)) -> Art der Beschaffung wählen in: | D13: =IF(ISBLANK(FinArt), "Input_Projekt", VLOOKUP(FinArt,FinArtList,2,FALSE)) -> Input_Projekt
C14: Leasingsonderzahlung (brutto) | D14: EUR | J14: *
B15: WLTP -Typprüfwerte | C15: Energieverbrauch | D15: l/100km
D16: kWh/100km
C17: CO2 | D17: g/km
C18: NOX (Stickoxide) | D18: mg/km | L18: =IF(SUM(J22:J23)>0,"FEHLER: Bitte alle Werte füllen","")
C19: Partikel | D19: mg/km
C20: Rein elektrische Reichweite | D20: km
C21: Batteriegröße brutto | D21: kWh
D22: Check Energieträger | E22: =IF(AND(OR(Energie1="nicht verfügbar",COUNTIF(EnList1,Energie1)<>1),Antriebsart1<>0),1,0) -> 0 | F22: =IF(AND(OR(Energie2="nicht verfügbar",COUNTIF(EnList2,Energie2)<>1),Antriebsart2<>0),1,0) -> 0 | G22: =IF(AND(OR(Energie3="nicht verfügbar",COUNTIF(EnList3,Energie3)<>1),Antriebsart3<>0),1,0) -> 0 | H22: =IF(AND(OR(Energie4="nicht verfügbar",COUNTIF(EnList4,Energie4)<>1),Antriebsart4<>0),1,0) -> 0 | I22: =IF(AND(OR(Energie5="nicht verfügbar",COUNTIF(EnList5,Energie5)<>1),Antriebsart5<>0),1,0) -> 0 | J22: =SUM(E22:I22) -> 0
D23: Check Werte gefüllt | E23: =IF(OR(AND(COUNT(E15:E21)<7,Antriebsart1="Plug-In-Hybrid (PHEV)"),AND(COUNT(E16,E21)<2,Antriebsart1="Vollelektrisch (BEV)"),AND(COUNT(E15,E17:E19)<4,Antriebsart1="Verbrenner")),1,0) -> 0 | F23: =IF(OR(AND(COUNT(F15:F21)<7,Antriebsart2="Plug-In-Hybrid (PHEV)"),AND(COUNT(F16,F21)<2,Antriebsart2="Vollelektrisch (BEV)"),AND(COUNT(F15,F17:F19)<4,Antriebsart2="Verbrenner")),1,0) -> 0 | G23: =IF(OR(AND(COUNT(G15:G21)<7,Antriebsart3="Plug-In-Hybrid (PHEV)"),AND(COUNT(G16,G21)<2,Antriebsart3="Vollelektrisch (BEV)"),AND(COUNT(G15,G17:G19)<4,Antriebsart3="Verbrenner")),1,0) -> 0 | H23: =IF(OR(AND(COUNT(H15:H21)<7,Antriebsart4="Plug-In-Hybrid (PHEV)"),AND(COUNT(H16,H21)<2,Antriebsart4="Vollelektrisch (BEV)"),AND(COUNT(H15,H17:H19)<4,Antriebsart4="Verbrenner")),1,0) -> 0 | I23: =IF(OR(AND(COUNT(I15:I21)<7,Antriebsart5="Plug-In-Hybrid (PHEV)"),AND(COUNT(I16,I21)<2,Antriebsart5="Vollelektrisch (BEV)"),AND(COUNT(I15,I17:I19)<4,Antriebsart5="Verbrenner")),1,0) -> 0 | J23: =SUM(E23:I23) -> 0
E24: Bei den umrahmten Werten wird geprüft, ob sie Ihrer Beschaffungsvorschrift entsprechen. Ggf. müssen Sie die voreingestellen Mindestanforderungen mit Ihren spezifischen Anforderungen abgleichen (Tabellenblatt "Grunddaten").
E25: Felder mit abweichenden Werten werden rot gekennzeichnet. Das entsprechende Angebot ist von der Wertung auszuschließen.
C28: Hinweis: Es sollten nur Pkw aus der gleichen Ausschreibung mit gleichem Nutzen (z.B. Nutzlast, Sitzplätze etc.) verglichen werden.

Sheet Ergebnisse_LZK
B1: Hinweis: mit >Datei > Drucken können Sie das Ergebnis dieser Seite einfach drucken
A2: i | B2: RESULTATE PKW | D2: =IF(I26>0,"Resultate ungültig - Eingabewerte fehlen !","") | J2: zurück zu "Anleitung"
B4: Projektinfos
B6: Projekt | C6: =IF(Projektname_Z1=0,"",Projektname_Z1)
C7: =IF(Projektname_Z2=0,"",Projektname_Z2)
C8: =IF(Projektname_Z3=0,"",Projektname_Z3)
B9: Unternehmen/öffentliche Einrichtung | C9: =IF(Unternehmen=0,"",Unternehmen)
B10: Zuständige Person | C10: =IF(Zustaendig=0,"",Zustaendig)
B11: Bearbeitungsdatum | C11: =IF(Datum=0,"",Datum)
E12: Jahresfahrleistung pro Pkw | F12: =Fahrleistung -> 0 | G12: km/Jahr
E13: Haltedauer | F13: =Haltedauer -> 0 | G13: Jahre
B15: Lebenszykluskosten
B16: Angebotsnummer | D16: 1 | E16: 2 | F16: 3 | G16: 4 | H16: 5
D17: =CONCATENATE(Erg.Pkw_1!$C$10," ",Erg.Pkw_1!$C$11," ",Erg.Pkw_1!$C$13," ",Erg.Pkw_1!$C$14) | E17: =CONCATENATE(Erg.Pkw_2!$C$10," ",Erg.Pkw_2!$C$11," ",Erg.Pkw_2!$C$13," ",Erg.Pkw_2!$C$14) | F17: =CONCATENATE(Erg.Pkw_3!$C$10," ",Erg.Pkw_3!$C$11," ",Erg.Pkw_3!$C$13," ",Erg.Pkw_3!$C$14) | G17: =CONCATENATE(Erg.Pkw_4!$C$10," ",Erg.Pkw_4!$C$11," ",Erg.Pkw_4!$C$13," ",Erg.Pkw_4!$C$14) | H17: =CONCATENATE(Erg.Pkw_5!$C$10," ",Erg.Pkw_5!$C$11," ",Erg.Pkw_5!$C$13," ",Erg.Pkw_5!$C$14)
B18: Kaufpreis | C18: EUR | D18: =IF(FinArt="Kauf",Gesamtpreis1,"") | E18: =IF(FinArt="Kauf",Gesamtpreis2,"") | F18: =IF(FinArt="Kauf",Gesamtpreis3,"") | G18: =IF(FinArt="Kauf",Gesamtpreis4,"") | H18: =IF(FinArt="Kauf",Gesamtpreis5,"")
A19: i | B19: =IF(FinArt="Kauf",KaufpreisRech,"Fahrzeugkosten (Leasingrate/Miete)") -> Fahrzeugkosten (Leasingrate/Miete) | C19: EUR | D19: =Erg.Pkw_1!$C$54+Erg.Pkw_1!$C$55 -> 0 | E19: =Erg.Pkw_2!$C$54+Erg.Pkw_2!$C$55 -> 0 | F19: =Erg.Pkw_3!$C$54+Erg.Pkw_3!$C$55 -> 0 | G19: =Erg.Pkw_4!$C$54+Erg.Pkw_4!$C$55 -> 0 | H19: =Erg.Pkw_5!$C$54+Erg.Pkw_5!$C$55 -> 0
B20: Energiekosten | C20: EUR | D20: =Erg.Pkw_1!$C$56 -> 0 | E20: =Erg.Pkw_2!$C$56 -> 0 | F20: =Erg.Pkw_3!$C$56 -> 0 | G20: =Erg.Pkw_4!$C$56 -> 0 | H20: =Erg.Pkw_5!$C$56 -> 0
A21: i | B21: Externe Umweltkosten (Betrieb) | C21: EUR | D21: =Erg.Pkw_1!$C$57 -> 0 | E21: =Erg.Pkw_2!$C$57 -> 0 | F21: =Erg.Pkw_3!$C$57 -> 0 | G21: =Erg.Pkw_4!$C$57 -> 0 | H21: =Erg.Pkw_5!$C$57 -> 0
B22: Externe Umweltkosten THG (Vorkette) | C22: EUR | D22: =Erg.Pkw_1!C41*Haltedauer -> 0 | E22: =Erg.Pkw_2!C41*Haltedauer -> 0 | F22: =Erg.Pkw_3!C41*Haltedauer -> 0 | G22: =Erg.Pkw_4!C41*Haltedauer -> 0 | H22: =Erg.Pkw_5!C41*Haltedauer -> 0
B23: Externe Umweltkosten Herstellung (Batterie) | C23: EUR | D23: =Erg.Pkw_1!$C$59 -> #DIV/0! | E23: =Erg.Pkw_2!$C$59 -> #DIV/0! | F23: =Erg.Pkw_3!$C$59 -> #DIV/0! | G23: =Erg.Pkw_4!$C$59 -> #DIV/0! | H23: =Erg.Pkw_5!$C$59 -> #DIV/0!
B24: Total | C24: EUR | D24: =IF(SUM(D19:D23)=0,"",SUM(D19:D23)) -> #DIV/0! | E24: =IF(SUM(E19:E23)=0,"",SUM(E19:E23)) -> #DIV/0! | F24: =IF(SUM(F19:F23)=0,"",SUM(F19:F23)) -> #DIV/0! | G24: =IF(SUM(G19:G23)=0,"",SUM(G19:G23)) -> #DIV/0! | H24: =IF(SUM(H19:H23)=0,"",SUM(H19:H23)) -> #DIV/0!
B25: Rangfolge nach Lebenszykluskosten | D25: =IFERROR(_xlfn.RANK.EQ(D24,$D$24:$H$24,1),"") | E25: =IFERROR(_xlfn.RANK.EQ(E24,$D$24:$H$24,1),"") | F25: =IFERROR(_xlfn.RANK.EQ(F24,$D$24:$H$24,1),"") | G25: =IFERROR(_xlfn.RANK.EQ(G24,$D$24:$H$24,1),"") | H25: =IFERROR(_xlfn.RANK.EQ(H24,$D$24:$H$24,1),"")
B26: Übersicht: Treibhausgasemissionen | C26: Check Werte gefüllt | D26: =IF(AND(COUNTIF(D19:D23,0)>0,Antriebsart1="Plug-In-Hybrid (PHEV)"),1,IF(AND(COUNTIF(D19:D23,0)>1,Antriebsart1<>0),1,0)) -> 0 | E26: =IF(AND(COUNTIF(E19:E23,0)>0,Antriebsart2="Plug-In-Hybrid (PHEV)"),1,IF(AND(COUNTIF(E19:E23,0)>1,Antriebsart2<>0),1,0)) -> 0 | F26: =IF(AND(COUNTIF(F19:F23,0)>0,Antriebsart3="Plug-In-Hybrid (PHEV)"),1,IF(AND(COUNTIF(F19:F23,0)>1,Antriebsart3<>0),1,0)) -> 0 | G26: =IF(AND(COUNTIF(G19:G23,0)>0,Antriebsart4="Plug-In-Hybrid (PHEV)"),1,IF(AND(COUNTIF(G19:G23,0)>1,Antriebsart4<>0),1,0)) -> 0 | H26: =IF(AND(COUNTIF(H19:H23,0)>0,Antriebsart5="Plug-In-Hybrid (PHEV)"),1,IF(AND(COUNTIF(H19:H23,0)>1,Antriebsart5<>0),1,0)) -> 0 | I26: =SUM(D26:H26)+Eingabe_Angebotswerte!J22+Eingabe_Angebotswerte!J23 -> 0
B27: Treibhausgasemissionen Herstellung (Batterie) (Scope 3) | C27: t CO2eq | D27: =Erg.Pkw_1!$C$62 -> #DIV/0! | E27: =Erg.Pkw_2!$C$62 -> #DIV/0! | F27: =Erg.Pkw_3!$C$62 -> #DIV/0! | G27: =Erg.Pkw_4!$C$62 -> #DIV/0! | H27: =Erg.Pkw_5!$C$62 -> #DIV/0!
B28: Treibhausgasemissionen Betrieb (Scope 1 und 2) | C28: t CO2eq | D28: =Erg.Pkw_1!$C$63 -> 0 | E28: =Erg.Pkw_2!$C$63 -> 0 | F28: =Erg.Pkw_3!$C$63 -> 0 | G28: =Erg.Pkw_4!$C$63 -> 0 | H28: =Erg.Pkw_5!$C$63 -> 0
B30: Lebenszykluskosten Diagramm
B32: =D25 | C32: =E25 | D32: =F25 | F32: =G25 | G32: =H25

Sheet Ergebnisse_Umweltkosten
B1: Hinweis: mit >Datei > Drucken können Sie das Ergebnis dieser Seite einfach drucken
A2: i | B2: RESULTATE PKW | D2: =IF(I24>0,"Resultate ungültig - Eingabewerte fehlen !","") | J2: zurück zu "Anleitung"
B4: Projektinfos
B6: Projekt | C6: =IF(Projektname_Z1=0,"",Projektname_Z1)
C7: =IF(Projektname_Z2=0,"",Projektname_Z2)
C8: =IF(Projektname_Z3=0,"",Projektname_Z3)
B9: Unternehmen/öffentliche Einrichtung | C9: =IF(Unternehmen=0,"",Unternehmen)
B10: Zuständige Person | C10: =IF(Zustaendig=0,"",Zustaendig)
B11: Bearbeitungsdatum | C11: =IF(Datum=0,"",Datum)
E12: Jahresfahrleistung pro Pkw | F12: =Fahrleistung -> 0 | G12: km/Jahr
E13: Haltedauer | F13: =Haltedauer -> 0 | G13: Jahre
B15: Lebenszykluskosten
B16: Angebotsnummer | D16: 1 | E16: 2 | F16: 3 | G16: 4 | H16: 5
D17: =CONCATENATE(Erg.Pkw_1!$C$10," ",Erg.Pkw_1!$C$11," ",Erg.Pkw_1!$C$13," ",Erg.Pkw_1!$C$14) | E17: =CONCATENATE(Erg.Pkw_2!$C$10," ",Erg.Pkw_2!$C$11," ",Erg.Pkw_2!$C$13," ",Erg.Pkw_2!$C$14) | F17: =CONCATENATE(Erg.Pkw_3!$C$10," ",Erg.Pkw_3!$C$11," ",Erg.Pkw_3!$C$13," ",Erg.Pkw_3!$C$14) | G17: =CONCATENATE(Erg.Pkw_4!$C$10," ",Erg.Pkw_4!$C$11," ",Erg.Pkw_4!$C$13," ",Erg.Pkw_4!$C$14) | H17: =CONCATENATE(Erg.Pkw_5!$C$10," ",Erg.Pkw_5!$C$11," ",Erg.Pkw_5!$C$13," ",Erg.Pkw_5!$C$14)
A18: i | B18: Externe Umweltkosten THG (Betrieb) | C18: EUR | D18: =Erg.Pkw_1!$C$57-D19 -> 0 | E18: =Erg.Pkw_2!$C$57-E19 -> 0 | F18: =Erg.Pkw_3!$C$57-F19 -> 0 | G18: =Erg.Pkw_4!$C$57-G19 -> 0 | H18: =Erg.Pkw_5!$C$57-H19 -> 0
B19: Externe Umweltk. Luftschadstoffe (Betrieb) | C19: EUR | D19: =(Erg.Pkw_1!$C$35+Erg.Pkw_1!$C$36)*Haltedauer -> 0 | E19: =(Erg.Pkw_2!$C$35+Erg.Pkw_2!$C$36)*Haltedauer -> 0 | F19: =(Erg.Pkw_3!$C$35+Erg.Pkw_3!$C$36)*Haltedauer -> 0 | G19: =(Erg.Pkw_4!$C$35+Erg.Pkw_4!$C$36)*Haltedauer -> 0 | H19: =(Erg.Pkw_5!$C$35+Erg.Pkw_5!$C$36)*Haltedauer -> 0
B20: Externe Umweltkosten THG (Vorkette) | C20: EUR | D20: =Erg.Pkw_1!C41*Haltedauer -> 0 | E20: =Erg.Pkw_2!C41*Haltedauer -> 0 | F20: =Erg.Pkw_3!C41*Haltedauer -> 0 | G20: =Erg.Pkw_4!C41*Haltedauer -> 0 | H20: =Erg.Pkw_5!C41*Haltedauer -> 0
B21: Externe Umweltkosten Herstellung (Batterie) | C21: EUR | D21: =Erg.Pkw_1!$C$59 -> #DIV/0! | E21: =Erg.Pkw_2!$C$59 -> #DIV/0! | F21: =Erg.Pkw_3!$C$59 -> #DIV/0! | G21: =Erg.Pkw_4!$C$59 -> #DIV/0! | H21: =Erg.Pkw_5!$C$59 -> #DIV/0!
B22: Total | C22: EUR | D22: =IF(SUM(D18:D21)=0,"",SUM(D18:D21)) -> #DIV/0! | E22: =IF(SUM(E18:E21)=0,"",SUM(E18:E21)) -> #DIV/0! | F22: =IF(SUM(F18:F21)=0,"",SUM(F18:F21)) -> #DIV/0! | G22: =IF(SUM(G18:G21)=0,"",SUM(G18:G21)) -> #DIV/0! | H22: =IF(SUM(H18:H21)=0,"",SUM(H18:H21)) -> #DIV/0!
B23: Rangfolge nach Lebenszykluskosten | D23: =IFERROR(_xlfn.RANK.EQ(D22,$D$22:$H$22,1),"") | E23: =IFERROR(_xlfn.RANK.EQ(E22,$D$22:$H$22,1),"") | F23: =IFERROR(_xlfn.RANK.EQ(F22,$D$22:$H$22,1),"") | G23: =IFERROR(_xlfn.RANK.EQ(G22,$D$22:$H$22,1),"") | H23: =IFERROR(_xlfn.RANK.EQ(H22,$D$22:$H$22,1),"")
B24: Übersicht: Treibhausgasemissionen | C24: Check Werte gefüllt | D24: =IF(AND(COUNTIF(D18:D21,0)>0,Antriebsart1="Plug-In-Hybrid (PHEV)"),1,IF(AND(COUNTIF(D18:D21,0)>1,Antriebsart1="Verbrenner"),1,IF(AND(COUNTIF(D18:D21,0)>2,Antriebsart1<>""),1,0))) -> 0 | E24: =IF(AND(COUNTIF(E18:E21,0)>0,Antriebsart2="Plug-In-Hybrid (PHEV)"),1,IF(AND(COUNTIF(E18:E21,0)>1,Antriebsart2="Verbrenner"),1,IF(AND(COUNTIF(E18:E21,0)>2,Antriebsart2<>""),1,0))) -> 0 | F24: =IF(AND(COUNTIF(F18:F21,0)>0,Antriebsart3="Plug-In-Hybrid (PHEV)"),1,IF(AND(COUNTIF(F18:F21,0)>1,Antriebsart3="Verbrenner"),1,IF(AND(COUNTIF(F18:F21,0)>2,Antriebsart3<>""),1,0))) -> 0 | G24: =IF(AND(COUNTIF(G18:G21,0)>0,Antriebsart4="Plug-In-Hybrid (PHEV)"),1,IF(AND(COUNTIF(G18:G21,0)>1,Antriebsart4="Verbrenner"),1,IF(AND(COUNTIF(G18:G21,0)>2,Antriebsart4<>""),1,0))) -> 0 | H24: =IF(AND(COUNTIF(H18:H21,0)>0,Antriebsart5="Plug-In-Hybrid (PHEV)"),1,IF(AND(COUNTIF(H18:H21,0)>1,Antriebsart5="Verbrenner"),1,IF(AND(COUNTIF(H18:H21,0)>2,Antriebsart5<>""),1,0))) -> 0 | I24: =SUM(D24:H24)+Eingabe_Angebotswerte!J23 -> 0
B25: Treibhausgasemissionen Herstellung (Batterie) (Scope 3) | C25: t CO2eq | D25: =Erg.Pkw_1!$C$62 -> #DIV/0! | E25: =Erg.Pkw_2!$C$62 -> #DIV/0! | F25: =Erg.Pkw_3!$C$62 -> #DIV/0! | G25: =Erg.Pkw_4!$C$62 -> #DIV/0! | H25: =Erg.Pkw_5!$C$62 -> #DIV/0!
B26: Treibhausgasemissionen Betrieb (Scope 1 und 2) | C26: t CO2eq | D26: =Erg.Pkw_1!$C$63 -> 0 | E26: =Erg.Pkw_2!$C$63 -> 0 | F26: =Erg.Pkw_3!$C$63 -> 0 | G26: =Erg.Pkw_4!$C$63 -> 0 | H26: =Erg.Pkw_5!$C$63 -> 0
B28: Lebenszykluskosten Diagramm (gesamte Haltedauer)
B30: =D23 | C30: =E23 | D30: =F23 | F30: =G23 | G30: =H23

Sheet Grunddaten
G1: i
B2: MINDESTANFORDERUNGEN | I2: zurück zu "Anleitung"
B4: Vorgeschlage Mindestanforderungen (Umweltkriterien)
B6: Kategorie | C6: Antriebsart | D6: Wert | E6: Eigene Werte nutzen | F6: Einheit | G6: Werte eff.
B7: CO2-Emissionen (WLTP) | C7: Verbrenner | D7: 120 | F7: g/km | G7: =IF(ISNUMBER(E7),E7,D7) -> 120
C8: Verbrenner - Vans und Utilities | D8: 130 | F8: g/km | G8: =IF(ISNUMBER(E8),E8,D8) -> 130
C9: PHEV | D9: 40 | F9: g/km | G9: =IF(ISNUMBER(E9),E9,D9) -> 40
B10: NOX-Emissionen (WLTP) | C10: Verbrenner und PHEV | D10: 64 | F10: mg/km | G10: =IF(ISNUMBER(E10),E10,D10) -> 64
B11: Partikel-Emissionen (WLTP) | C11: Verbrenner und PHEV | D11: 3.6 | F11: mg/km | G11: =IF(ISNUMBER(E11),E11,D11) -> 3.6
B12: Energieverbrauch (WLTP) | C12: BEV | D12: 19 | F12: kWh/100 km | G12: =IF(ISNUMBER(E12),E12,D12) -> 19
C13: BEV - Vans und Utilities | D13: 21 | F13: kWh/100 km | G13: =IF(ISNUMBER(E13),E13,D13) -> 21
B14: Elektrische Mindestreichweite (WLTP) | C14: PHEV | D14: 60 | F14: km | G14: =IF(ISNUMBER(E14),E14,D14) -> 60
B18: ENERGIE- + UMWELTKOSTEN | D18: Die Kosten werden in EUR brutto (nach Steuern) angegeben.
B20: Angaben zu den Energieträgern
B22: Energieträger | D22: Energiepreis
E23: Eigene Werte nutzen | F23: Einheit | G23: Kosten eff. | H23: Quellen: | I23: Quellen eigene Werte:
B24: Strom eigene Ladestation | D24: 46.3 | F24: ct/kWh | G24: =IF(ISNUMBER(E24),E24,D24)/100 -> 0.463 | H24: BDEW (2023)
B25: Strom externe Ladestation | D25: 55.2 | F25: ct/kWh | G25: =IF(ISNUMBER(E25),E25,D25)/100 -> 0.552 | H25: nextmove (2023)
B26: Strom | G26: =G24*Input_Projekt!J29/100+G25*(1-Input_Projekt!J29/100) -> 0.5075
B27: Diesel | D27: 1.659 | F27: EUR/l | G27: =IF(ISNUMBER(E27),E27,D27) -> 1.659 | H27: ADAC (2023b)
B28: Benzin | D28: 1.784 | F28: EUR/l | G28: =IF(ISNUMBER(E28),E28,D28) -> 1.784 | H28: ADAC (2023b)
B29: Erdgas (CNG) | D29: 1.2 | F29: EUR/kg | G29: =IF(ISNUMBER(E29),E29,D29) -> 1.2 | H29: ADAC (2023a)
B32: Externe Umweltkosten - Annahmen
B33: Welche externen Umweltkosten sollen in der LZK-Berechnung berücksichtigt werden? | G33: Kosten eff.
E34: Eigene Werte nutzen
B35: Externe Umweltkosten Treibhausgasemissionen | D35: =IF(KostTHGVorgabe="(Niedrig) 200",200,500) -> 500 | F35: EUR/t CO2eq | G35: =IF(ISNUMBER(E35),E35,D35) -> 500 | H35: Lambrecht et al. (2023)
B37: Externe Umweltkosten NOx (Stickoxide) | D37: 0.02 | F37: EUR/g | G37: =IF(ISNUMBER(E37),E37,D37) -> 0.02 | H37: Lambrecht et al. (2023)
B38: Externe Umweltkosten Partikel (PM2.5) | D38: 0.15 | F38: EUR/g | G38: =IF(ISNUMBER(E38),E38,D38) -> 0.15 | H38: Lambrecht et al. (2023)
B41: Herstellungsemissionen Batterien
B42: THG-Emissionen bei der Batterieherstellung | D42: 84 | F42: kg CO2eq/kWh | G42: =IF(ISNUMBER(E42),E42,D42) -> 84 | H42: Biemann et al. (2023)
B43: Referenz-Batteriechemie: NMC 622

Sheet Erg.Pkw_1
B2: RECHENBLATT PKW 1 | E2: zurück zu "Anleitung"
B4: Angaben zum Angebot
F5: =IF(Antriebsart1="Vollelektrisch (BEV)","Strom","nicht verfügbar") -> nicht verfügbar
B6: Angebotsnummer | C6: 1 | F6: =IF(OR(Antriebsart1="Verbrenner",Antriebsart1="Plug-In-Hybrid (PHEV)"),"Diesel","nicht verfügbar") -> nicht verfügbar
B7: Anbieter | C7: =IF(Anbieter1=0,"",Anbieter1) | F7: =IF(OR(Antriebsart1="Verbrenner",Antriebsart1="Plug-In-Hybrid (PHEV)"),"Benzin","nicht verfügbar") -> nicht verfügbar
F8: =IF(Antriebsart1="Verbrenner","Erdgas (CNG)","nicht verfügbar") -> nicht verfügbar
B9: Angebotenes Fahrzeug
B10: Hersteller | C10: =IF(Hersteller1=0,"",Hersteller1)
B11: Modell | C11: =IF(Modell1=0,"",Modell1)
B12: Zusatzinfos | C12: =IF(Zusatzinfo1=0,"",Zusatzinfo1)
B13: Antriebsart | C13: =IF(Antriebsart1=0,"",Antriebsart1)
B14: Energieträger | C14: =IF(Energie1=0,"",Energie1)
B16: Zusatzberechnungen Plug-In-Hybrid
B18: Anteil elektrisches Fahren ("Utility-Faktor") nach WLTP | C18: =0.0057*(ReichwPHEV1/23)^3-0.0838*(ReichwPHEV1/23)^2+0.4261*(ReichwPHEV1/23)+ 0.1633 -> 0.1633
B19: Verbrauch im reinen Verbrennermodus nach WLTP (errechnet) | C19: =Verbrauch1/(1-0.9*C18) -> 0 | D19: l/100km
B20: Verbrauch im rein elektrischen Modus nach WLTP (errechnet) | C20: =VerbEl_WLTP1/C18 -> 0 | D20: kWh/100km
B21: Realitätsnaher Anteil elektrisches Fahren (empirisch ermittelt) | C21: =0.0021*(ReichwPHEV1/23)^3-0.0358*(ReichwPHEV1/23)^2+0.2607*(ReichwPHEV1/23)- 0.0267 -> -0.0267
A22: i | B22: Kombinierter Verbrauch bei realitätsnahem Anteil elektrisches Fahren | C22: =C19*(1-0.9*C21) -> 0 | D22: l/100km
C23: =C20*C21 -> 0 | D23: kWh/100km
B25: Kosten und umweltrelevante Angaben - Betrieb des Fahrzeugs
B27: Energiekosten
B28: Kraftstoff | C28: =IF(Antriebsart1="Vollelektrisch (BEV)",0,IFERROR(VLOOKUP(Energie1,EnKostList,6,FALSE),0)*IF(Antriebsart1="Plug-In-Hybrid (PHEV)",VerbPHEV1,Verbrauch1)/100*Fahrleistung) -> 0 | D28: EUR/Jahr
B29: Strom | C29: =IF(Antriebsart1="Verbrenner",0,VLOOKUP("Strom",EnKostList,6,FALSE)*IF(Antriebsart1="Plug-In-Hybrid (PHEV)",VerbElPHEV1,VerbEl_WLTP1)/100*Fahrleistung) -> 0 | D29: EUR/Jahr
B30: Total | C30: =SUM(C28:C29) -> 0 | D30: EUR/Jahr
B32: Betrieb: Externe Umweltkosten | C32: =CONCATENATE("Energieträger: ",Energie1) -> Energieträger:
B33: Treibhausgasemissionen (THG) | C33: =IF(Antriebsart1="Plug-In-Hybrid (PHEV)",VerbPHEV1*VLOOKUP(Energie1,CO2List,2,FALSE)/100,CO2_1)*Fahrleistung/1000000 -> 0 | D33: t CO2eq/Jahr
B34: Externe Umweltkosten Treibhausgasemissionen | C34: =C33*Kost_THG -> 0 | D34: EUR/Jahr
B35: NOx (Stickoxide) | C35: =IF(Energie1="Strom",0,NOX_1*Fahrleistung*Kost_NOX/1000) -> 0 | D35: EUR/Jahr
B36: Partikel | C36: =IF(Energie1="Strom",0,Partikel1*Fahrleistung*Kost_Partikel/1000) -> 0 | D36: EUR/Jahr
B37: Total | C37: =SUM(C34:C36) -> 0 | D37: EUR/Jahr
B39: Vorkette: Externe Umweltkosten | C39: =CONCATENATE("Energieträger: ",Energie1,IF(Antriebsart1="Plug-In-Hybrid (PHEV)","+Strom","")) -> Energieträger:
B40: Treibhausgasemissionen (THG) | C40: =IFERROR(IF(Antriebsart1="Vollelektrisch (BEV)",VLOOKUP("Strom",CO2List,3,FALSE)*VerbEl_WLTP1/100*Fahrleistung/1000000,IF(Antriebsart1="Verbrenner",VLOOKUP(Energie1,CO2List,3,FALSE)*Verbrauch1/100*Fahrleistung/1000000,VLOOKUP(Energie1,CO2List,3,FALSE)*VerbPHEV1/100*Fahrleistung/1000000+VLOOKUP("Strom",CO2List,3,FALSE)*VerbElPHEV1/100*Fahrleistung/1000000)),0) -> 0 | D40: t CO2eq/Jahr
B41: Externe Umweltkosten Vorkette | C41: =C40*Kost_THG -> 0 | D41: EUR/Jahr
B43: Umweltrelevante Angaben - Herstellung der Batterie
B45: Herstellung Batterie: Externe Umweltkosten | C45: Batterieherstellung
A46: i | B46: Treibhausgasemissionen (THG) | C46: =IF(OR(Antriebsart1="Vollelektrisch (BEV)",Antriebsart1="Plug-In-Hybrid (PHEV)"),Batterie1*Batterie_THG/1000,0) -> 0 | D46: t CO2eq gesamt
C47: =IF((Fahrleistung*16)<220000,C46*10^6/(Fahrleistung*16),C46*10^6/220000) -> #DIV/0! | D47: g CO2eq/km
B48: Externe Umweltkosten Batterieherstellung | C48: =IF(C47*Fahrleistung/10^6*Haltedauer<C46, C47*Fahrleistung/10^6*Kost_THG, C46/Haltedauer*Kost_THG) -> #DIV/0! | D48: EUR/Jahr
B51: =CONCATENATE("Lebenszykluskosten"," (Haltedauer: ",Haltedauer," Jahre)") -> Lebenszykluskosten (Haltedauer: Jahre)
B52: Kosten des Fahrzeugs über die gesamte Haltedauer gesehen
...

Sheet Erg.Pkw_2
B2: RECHENBLATT PKW 2 | E2: zurück zu "Anleitung"
B4: Angaben zum Angebot
F5: =IF(Antriebsart2="Vollelektrisch (BEV)","Strom","nicht verfügbar") -> nicht verfügbar
B6: Angebotsnummer | C6: 2 | F6: =IF(OR(Antriebsart2="Verbrenner",Antriebsart2="Plug-In-Hybrid (PHEV)"),"Diesel","nicht verfügbar") -> nicht verfügbar
B7: Anbieter | C7: =IF(Anbieter2=0,"",Anbieter2) | F7: =IF(OR(Antriebsart2="Verbrenner",Antriebsart2="Plug-In-Hybrid (PHEV)"),"Benzin","nicht verfügbar") -> nicht verfügbar
F8: =IF(Antriebsart2="Verbrenner","Erdgas (CNG)","nicht verfügbar") -> nicht verfügbar
B9: Angebotenes Fahrzeug
B10: Hersteller | C10: =IF(Hersteller2=0,"",Hersteller2)
B11: Modell | C11: =IF(Modell2=0,"",Modell2)
B12: Zusatzinfos | C12: =IF(Zusatzinfo2=0,"",Zusatzinfo2)
B13: Antriebsart | C13: =IF(Antriebsart2=0,"",Antriebsart2)
B14: Energieträger | C14: =IF(Energie2=0,"",Energie2)
B16: Zusatzberechnungen Plug-In-Hybrid
B18: Anteil elektrisches Fahren ("Utility-Faktor") nach WLTP | C18: =0.0057*(ReichwPHEV2/23)^3-0.0838*(ReichwPHEV2/23)^2+0.4261*(ReichwPHEV2/23)+ 0.1633 -> 0.1633
B19: Verbrauch im reinen Verbrennermodus nach WLTP (errechnet) | C19: =Verbrauch2/(1-0.9*C18) -> 0 | D19: l/100km
B20: Verbrauch im rein elektrischen Modus nach WLTP (errechnet) | C20: =VerbEl_WLTP2/C18 -> 0 | D20: kWh/100km
B21: Realitätsnaher Anteil elektrisches Fahren (empirisch ermittelt) | C21: =0.0021*(ReichwPHEV2/23)^3-0.0358*(ReichwPHEV2/23)^2+0.2607*(ReichwPHEV2/23)- 0.0267 -> -0.0267
A22: i | B22: Kombinierter Verbrauch bei realitätsnahem Anteil elektrisches Fahren | C22: =C19*(1-0.9*C21) -> 0 | D22: l/100km
C23: =C20*C21 -> 0 | D23: kWh/100km
B25: Kosten und umweltrelevante Angaben - Betrieb des Fahrzeugs
B27: Energiekosten
B28: Kraftstoff | C28: =IF(Antriebsart2="Vollelektrisch (BEV)",0,IFERROR(VLOOKUP(Energie2,EnKostList,6,FALSE),0)*IF(Antriebsart2="Plug-In-Hybrid (PHEV)",VerbPHEV2,Verbrauch2)/100*Fahrleistung) -> 0 | D28: EUR/Jahr
B29: Strom | C29: =IF(Antriebsart2="Verbrenner",0,VLOOKUP("Strom",EnKostList,6,FALSE)*IF(Antriebsart2="Plug-In-Hybrid (PHEV)",VerbElPHEV2,VerbEl_WLTP2)/100*Fahrleistung) -> 0 | D29: EUR/Jahr
B30: Total | C30: =SUM(C28:C29) -> 0 | D30: EUR/Jahr
B32: Betrieb: Externe Umweltkosten | C32: =CONCATENATE("Energieträger: ",Energie2) -> Energieträger:
B33: Treibhausgasemissionen (THG) | C33: =IF(Antriebsart2="Plug-In-Hybrid (PHEV)",VerbPHEV2*VLOOKUP(Energie2,CO2List,2,FALSE)/100,CO2_2)*Fahrleistung/1000000 -> 0 | D33: t CO2eq/Jahr
B34: Externe Umweltkosten Treibhausgasemissionen | C34: =C33*Kost_THG -> 0 | D34: EUR/Jahr
B35: NOx (Stickoxide) | C35: =IF(Energie2="Strom",0,NOX_2*Fahrleistung*Kost_NOX/1000) -> 0 | D35: EUR/Jahr
B36: Partikel | C36: =IF(Energie2="Strom",0,Partikel2*Fahrleistung*Kost_Partikel/1000) -> 0 | D36: EUR/Jahr
B37: Total | C37: =SUM(C34:C36) -> 0 | D37: EUR/Jahr
B39: Vorkette: Externe Umweltkosten | C39: =CONCATENATE("Energieträger: ",Energie2,IF(Antriebsart2="Plug-In-Hybrid (PHEV)","+Strom","")) -> Energieträger:
B40: Treibhausgasemissionen (THG) | C40: =IFERROR(IF(Antriebsart2="Vollelektrisch (BEV)",VLOOKUP("Strom",CO2List,3,FALSE)*VerbEl_WLTP2/100*Fahrleistung/1000000,IF(Antriebsart2="Verbrenner",VLOOKUP(Energie2,CO2List,3,FALSE)*Verbrauch2/100*Fahrleistung/1000000,VLOOKUP(Energie2,CO2List,3,FALSE)*VerbPHEV2/100*Fahrleistung/1000000+VLOOKUP("Strom",CO2List,3,FALSE)*VerbElPHEV2/100*Fahrleistung/1000000)),0) -> 0 | D40: t CO2eq/Jahr
B41: Externe Umweltkosten Vorkette | C41: =C40*Kost_THG -> 0 | D41: EUR/Jahr
B43: Umweltrelevante Angaben - Herstellung der Batterie
B45: Herstellung Batterie: Externe Umweltkosten | C45: Batterieherstellung
A46: i | B46: Treibhausgasemissionen (THG) | C46: =IF(OR(Antriebsart2="Vollelektrisch (BEV)",Antriebsart2="Plug-In-Hybrid (PHEV)"),Batterie2*Batterie_THG/1000,0) -> 0 | D46: t CO2eq gesamt
C47: =IF((Fahrleistung*16)<220000,C46*10^6/(Fahrleistung*16),C46*10^6/220000) -> #DIV/0! | D47: g CO2eq/km
B48: Externe Umweltkosten Batterieherstellung | C48: =IF(C47*Fahrleistung/10^6*Haltedauer<C46, C47*Fahrleistung/10^6*Kost_THG, C46/Haltedauer*Kost_THG) -> #DIV/0! | D48: EUR/Jahr
B51: =CONCATENATE("Lebenszykluskosten"," (Haltedauer: ",Haltedauer," Jahre)") -> Lebenszykluskosten (Haltedauer: Jahre)
B52: Kosten des Fahrzeugs über die gesamte Haltedauer gesehen
...

Sheet Erg.Pkw_3
B2: RECHENBLATT PKW 3 | E2: zurück zu "Anleitung"
B4: Angaben zum Angebot
F5: =IF(Antriebsart3="Vollelektrisch (BEV)","Strom","nicht verfügbar") -> nicht verfügbar
B6: Angebotsnummer | C6: 3 | F6: =IF(OR(Antriebsart3="Verbrenner",Antriebsart3="Plug-In-Hybrid (PHEV)"),"Diesel","nicht verfügbar") -> nicht verfügbar
B7: Anbieter | C7: =IF(Anbieter3=0,"",Anbieter3) | F7: =IF(OR(Antriebsart3="Verbrenner",Antriebsart3="Plug-In-Hybrid (PHEV)"),"Benzin","nicht verfügbar") -> nicht verfügbar
F8: =IF(Antriebsart3="Verbrenner","Erdgas (CNG)","nicht verfügbar") -> nicht verfügbar
B9: Angebotenes Fahrzeug
B10: Hersteller | C10: =IF(Hersteller3=0,"",Hersteller3)
B11: Modell | C11: =IF(Modell3=0,"",Modell3)
B12: Zusatzinfos | C12: =IF(Zusatzinfo3=0,"",Zusatzinfo3)
B13: Antriebsart | C13: =IF(Antriebsart3=0,"",Antriebsart3)
B14: Energieträger | C14: =IF(Energie3=0,"",Energie3)
B16: Zusatzberechnungen Plug-In-Hybrid
B18: Anteil elektrisches Fahren ("Utility-Faktor") nach WLTP | C18: =0.0057*(ReichwPHEV3/23)^3-0.0838*(ReichwPHEV3/23)^2+0.4261*(ReichwPHEV3/23)+ 0.1633 -> 0.1633
B19: Verbrauch im reinen Verbrennermodus nach WLTP (errechnet) | C19: =Verbrauch3/(1-0.9*C18) -> 0 | D19: l/100km
B20: Verbrauch im rein elektrischen Modus nach WLTP (errechnet) | C20: =VerbEl_WLTP3/C18 -> 0 | D20: kWh/100km
B21: Realitätsnaher Anteil elektrisches Fahren (empirisch ermittelt) | C21: =0.0021*(ReichwPHEV3/23)^3-0.0358*(ReichwPHEV3/23)^2+0.2607*(ReichwPHEV3/23)- 0.0267 -> -0.0267
A22: i | B22: Kombinierter Verbrauch bei realitätsnahem Anteil elektrisches Fahren | C22: =C19*(1-0.9*C21) -> 0 | D22: l/100km
C23: =C20*C21 -> 0 | D23: kWh/100km
B25: Kosten und umweltrelevante Angaben - Betrieb des Fahrzeugs
B27: Energiekosten
B28: Kraftstoff | C28: =IF(Antriebsart3="Vollelektrisch (BEV)",0,IFERROR(VLOOKUP(Energie3,EnKostList,6,FALSE),0)*IF(Antriebsart3="Plug-In-Hybrid (PHEV)",VerbPHEV3,Verbrauch3)/100*Fahrleistung) -> 0 | D28: EUR/Jahr
B29: Strom | C29: =IF(Antriebsart3="Verbrenner",0,VLOOKUP("Strom",EnKostList,6,FALSE)*IF(Antriebsart3="Plug-In-Hybrid (PHEV)",VerbElPHEV3,VerbEl_WLTP3)/100*Fahrleistung) -> 0 | D29: EUR/Jahr
B30: Total | C30: =SUM(C28:C29) -> 0 | D30: EUR/Jahr
B32: Betrieb: Externe Umweltkosten | C32: =CONCATENATE("Energieträger: ",Energie3) -> Energieträger:
B33: Treibhausgasemissionen (THG) | C33: =IF(Antriebsart3="Plug-In-Hybrid (PHEV)",VerbPHEV3*VLOOKUP(Energie3,CO2List,2,FALSE)/100,CO2_3)*Fahrleistung/1000000 -> 0 | D33: t CO2eq/Jahr
B34: Externe Umweltkosten Treibhausgasemissionen | C34: =C33*Kost_THG -> 0 | D34: EUR/Jahr
B35: NOx (Stickoxide) | C35: =IF(Energie3="Strom",0,NOX_3*Fahrleistung*Kost_NOX/1000) -> 0 | D35: EUR/Jahr
B36: Partikel | C36: =IF(Energie3="Strom",0,Partikel3*Fahrleistung*Kost_Partikel/1000) -> 0 | D36: EUR/Jahr
B37: Total | C37: =SUM(C34:C36) -> 0 | D37: EUR/Jahr
B39: Vorkette: Externe Umweltkosten | C39: =CONCATENATE("Energieträger: ",Energie3,IF(Antriebsart3="Plug-In-Hybrid (PHEV)","+Strom","")) -> Energieträger:
B40: Treibhausgasemissionen (THG) | C40: =IFERROR(IF(Antriebsart3="Vollelektrisch (BEV)",VLOOKUP("Strom",CO2List,3,FALSE)*VerbEl_WLTP3/100*Fahrleistung/1000000,IF(Antriebsart3="Verbrenner",VLOOKUP(Energie3,CO2List,3,FALSE)*Verbrauch3/100*Fahrleistung/1000000,VLOOKUP(Energie3,CO2List,3,FALSE)*VerbPHEV3/100*Fahrleistung/1000000+VLOOKUP("Strom",CO2List,3,FALSE)*VerbElPHEV3/100*Fahrleistung/1000000)),0) -> 0 | D40: t CO2eq/Jahr
B41: Externe Umweltkosten Vorkette | C41: =C40*Kost_THG -> 0 | D41: EUR/Jahr
B43: Umweltrelevante Angaben - Herstellung der Batterie
B45: Herstellung Batterie: Externe Umweltkosten | C45: Batterieherstellung
A46: i | B46: Treibhausgasemissionen (THG) | C46: =IF(OR(Antriebsart3="Vollelektrisch (BEV)",Antriebsart3="Plug-In-Hybrid (PHEV)"),Batterie3*Batterie_THG/1000,0) -> 0 | D46: t CO2eq gesamt
C47: =IF((Fahrleistung*16)<220000,C46*10^6/(Fahrleistung*16),C46*10^6/220000) -> #DIV/0! | D47: g CO2eq/km
B48: Externe Umweltkosten Batterieherstellung | C48: =IF(C47*Fahrleistung/10^6*Haltedauer<C46, C47*Fahrleistung/10^6*Kost_THG, C46/Haltedauer*Kost_THG) -> #DIV/0! | D48: EUR/Jahr
B51: =CONCATENATE("Lebenszykluskosten"," (Haltedauer: ",Haltedauer," Jahre)") -> Lebenszykluskosten (Haltedauer: Jahre)
B52: Kosten des Fahrzeugs über die gesamte Haltedauer gesehen
...

Sheet Erg.Pkw_4
B2: RECHENBLATT PKW 4 | E2: zurück zu "Anleitung"
B4: Angaben zum Angebot
F5: =IF(Antriebsart4="Vollelektrisch (BEV)","Strom","nicht verfügbar") -> nicht verfügbar
B6: Angebotsnummer | C6: 4 | F6: =IF(OR(Antriebsart4="Verbrenner",Antriebsart4="Plug-In-Hybrid (PHEV)"),"Diesel","nicht verfügbar") -> nicht verfügbar
B7: Anbieter | C7: =IF(Anbieter4=0,"",Anbieter4) | F7: =IF(OR(Antriebsart4="Verbrenner",Antriebsart4="Plug-In-Hybrid (PHEV)"),"Benzin","nicht verfügbar") -> nicht verfügbar
F8: =IF(Antriebsart4="Verbrenner","Erdgas (CNG)","nicht verfügbar") -> nicht verfügbar
B9: Angebotenes Fahrzeug
B10: Hersteller | C10: =IF(Hersteller4=0,"",Hersteller4)
B11: Modell | C11: =IF(Modell4=0,"",Modell4)
B12: Zusatzinfos | C12: =IF(Zusatzinfo4=0,"",Zusatzinfo4)
B13: Antriebsart | C13: =IF(Antriebsart4=0,"",Antriebsart4)
B14: Energieträger | C14: =IF(Energie4=0,"",Energie4)
B16: Zusatzberechnungen Plug-In-Hybrid
B18: Anteil elektrisches Fahren ("Utility-Faktor") nach WLTP | C18: =0.0057*(ReichwPHEV4/23)^3-0.0838*(ReichwPHEV4/23)^2+0.4261*(ReichwPHEV4/23)+ 0.1633 -> 0.1633
B19: Verbrauch im reinen Verbrennermodus nach WLTP (errechnet) | C19: =Verbrauch4/(1-0.9*C18) -> 0 | D19: l/100km
B20: Verbrauch im rein elektrischen Modus nach WLTP (errechnet) | C20: =VerbEl_WLTP4/C18 -> 0 | D20: kWh/100km
B21: Realitätsnaher Anteil elektrisches Fahren (empirisch ermittelt) | C21: =0.0021*(ReichwPHEV4/23)^3-0.0358*(ReichwPHEV4/23)^2+0.2607*(ReichwPHEV4/23)- 0.0267 -> -0.0267
A22: i | B22: Kombinierter Verbrauch bei realitätsnahem Anteil elektrisches Fahren | C22: =C19*(1-0.9*C21) -> 0 | D22: l/100km
C23: =C20*C21 -> 0 | D23: kWh/100km
B25: Kosten und umweltrelevante Angaben - Betrieb des Fahrzeugs
B27: Energiekosten
B28: Kraftstoff | C28: =IF(Antriebsart4="Vollelektrisch (BEV)",0,IFERROR(VLOOKUP(Energie4,EnKostList,6,FALSE),0)*IF(Antriebsart4="Plug-In-Hybrid (PHEV)",VerbPHEV4,Verbrauch4)/100*Fahrleistung) -> 0 | D28: EUR/Jahr
B29: Strom | C29: =IF(Antriebsart4="Verbrenner",0,VLOOKUP("Strom",EnKostList,6,FALSE)*IF(Antriebsart4="Plug-In-Hybrid (PHEV)",VerbElPHEV4,VerbEl_WLTP4)/100*Fahrleistung) -> 0 | D29: EUR/Jahr
B30: Total | C30: =SUM(C28:C29) -> 0 | D30: EUR/Jahr
B32: Betrieb: Externe Umweltkosten | C32: =CONCATENATE("Energieträger: ",Energie4) -> Energieträger:
B33: Treibhausgasemissionen (THG) | C33: =IF(Antriebsart4="Plug-In-Hybrid (PHEV)",VerbPHEV4*VLOOKUP(Energie4,CO2List,2,FALSE)/100,CO2_4)*Fahrleistung/1000000 -> 0 | D33: t CO2eq/Jahr
B34: Externe Umweltkosten Treibhausgasemissionen | C34: =C33*Kost_THG -> 0 | D34: EUR/Jahr
B35: NOx (Stickoxide) | C35: =IF(Energie4="Strom",0,NOX_4*Fahrleistung*Kost_NOX/1000) -> 0 | D35: EUR/Jahr
B36: Partikel | C36: =IF(Energie4="Strom",0,Partikel4*Fahrleistung*Kost_Partikel/1000) -> 0 | D36: EUR/Jahr
B37: Total | C37: =SUM(C34:C36) -> 0 | D37: EUR/Jahr
B39: Vorkette: Externe Umweltkosten | C39: =CONCATENATE("Energieträger: ",Energie4,IF(Antriebsart4="Plug-In-Hybrid (PHEV)","+Strom","")) -> Energieträger:
B40: Treibhausgasemissionen (THG) | C40: =IFERROR(IF(Antriebsart4="Vollelektrisch (BEV)",VLOOKUP("Strom",CO2List,3,FALSE)*VerbEl_WLTP4/100*Fahrleistung/1000000,IF(Antriebsart4="Verbrenner",VLOOKUP(Energie4,CO2List,3,FALSE)*Verbrauch4/100*Fahrleistung/1000000,VLOOKUP(Energie4,CO2List,3,FALSE)*VerbPHEV4/100*Fahrleistung/1000000+VLOOKUP("Strom",CO2List,3,FALSE)*VerbElPHEV4/100*Fahrleistung/1000000)),0) -> 0 | D40: t CO2eq/Jahr
B41: Externe Umweltkosten Vorkette | C41: =C40*Kost_THG -> 0 | D41: EUR/Jahr
B43: Umweltrelevante Angaben - Herstellung der Batterie
B45: Herstellung Batterie: Externe Umweltkosten | C45: Batterieherstellung
A46: i | B46: Treibhausgasemissionen (THG) | C46: =IF(OR(Antriebsart4="Vollelektrisch (BEV)",Antriebsart4="Plug-In-Hybrid (PHEV)"),Batterie4*Batterie_THG/1000,0) -> 0 | D46: t CO2eq gesamt
C47: =IF((Fahrleistung*16)<220000,C46*10^6/(Fahrleistung*16),C46*10^6/220000) -> #DIV/0! | D47: g CO2eq/km
B48: Externe Umweltkosten Batterieherstellung | C48: =IF(C47*Fahrleistung/10^6*Haltedauer<C46, C47*Fahrleistung/10^6*Kost_THG, C46/Haltedauer*Kost_THG) -> #DIV/0! | D48: EUR/Jahr
B51: =CONCATENATE("Lebenszykluskosten"," (Haltedauer: ",Haltedauer," Jahre)") -> Lebenszykluskosten (Haltedauer: Jahre)
B52: Kosten des Fahrzeugs über die gesamte Haltedauer gesehen
...

Sheet Erg.Pkw_5
B2: RECHENBLATT PKW 5 | E2: zurück zu "Anleitung"
B4: Angaben zum Angebot
F5: =IF(Antriebsart5="Vollelektrisch (BEV)","Strom","nicht verfügbar") -> nicht verfügbar
B6: Angebotsnummer | C6: 5 | F6: =IF(OR(Antriebsart5="Verbrenner",Antriebsart5="Plug-In-Hybrid (PHEV)"),"Diesel","nicht verfügbar") -> nicht verfügbar
B7: Anbieter | C7: =IF(Anbieter5=0,"",Anbieter5) | F7: =IF(OR(Antriebsart5="Verbrenner",Antriebsart5="Plug-In-Hybrid (PHEV)"),"Benzin","nicht verfügbar") -> nicht verfügbar
F8: =IF(Antriebsart5="Verbrenner","Erdgas (CNG)","nicht verfügbar") -> nicht verfügbar
B9: Angebotenes Fahrzeug
B10: Hersteller | C10: =IF(Hersteller5=0,"",Hersteller5)
B11: Modell | C11: =IF(Modell5=0,"",Modell5)
B12: Zusatzinfos | C12: =IF(Zusatzinfo5=0,"",Zusatzinfo5)
B13: Antriebsart | C13: =IF(Antriebsart5=0,"",Antriebsart5)
B14: Energieträger | C14: =IF(Energie5=0,"",Energie5)
B16: Zusatzberechnungen Plug-In-Hybrid
B18: Anteil elektrisches Fahren ("Utility-Faktor") nach WLTP | C18: =0.0057*(ReichwPHEV5/23)^3-0.0838*(ReichwPHEV5/23)^2+0.4261*(ReichwPHEV5/23)+ 0.1633 -> 0.1633
B19: Verbrauch im reinen Verbrennermodus nach WLTP (errechnet) | C19: =Verbrauch5/(1-0.9*C18) -> 0 | D19: l/100km
B20: Verbrauch im rein elektrischen Modus nach WLTP (errechnet) | C20: =VerbEl_WLTP5/C18 -> 0 | D20: kWh/100km
B21: Realitätsnaher Anteil elektrisches Fahren (empirisch ermittelt) | C21: =0.0021*(ReichwPHEV5/23)^3-0.0358*(ReichwPHEV5/23)^2+0.2607*(ReichwPHEV5/23)- 0.0267 -> -0.0267
A22: i | B22: Kombinierter Verbrauch bei realitätsnahem Anteil elektrisches Fahren | C22: =C19*(1-0.9*C21) -> 0 | D22: l/100km
C23: =C20*C21 -> 0 | D23: kWh/100km
B25: Kosten und umweltrelevante Angaben - Betrieb des Fahrzeugs
B27: Energiekosten
B28: Kraftstoff | C28: =IF(Antriebsart5="Vollelektrisch (BEV)",0,IFERROR(VLOOKUP(Energie5,EnKostList,6,FALSE),0)*IF(Antriebsart5="Plug-In-Hybrid (PHEV)",VerbPHEV5,Verbrauch5)/100*Fahrleistung) -> 0 | D28: EUR/Jahr
B29: Strom | C29: =IF(Antriebsart5="Verbrenner",0,VLOOKUP("Strom",EnKostList,6,FALSE)*IF(Antriebsart5="Plug-In-Hybrid (PHEV)",VerbElPHEV5,VerbEl_WLTP5)/100*Fahrleistung) -> 0 | D29: EUR/Jahr
B30: Total | C30: =SUM(C28:C29) -> 0 | D30: EUR/Jahr
B32: Betrieb: Externe Umweltkosten | C32: =CONCATENATE("Energieträger: ",Energie5) -> Energieträger:
B33: Treibhausgasemissionen (THG) | C33: =IF(Antriebsart5="Plug-In-Hybrid (PHEV)",VerbPHEV5*VLOOKUP(Energie5,CO2List,2,FALSE)/100,CO2_5)*Fahrleistung/1000000 -> 0 | D33: t CO2eq/Jahr
B34: Externe Umweltkosten Treibhausgasemissionen | C34: =C33*Kost_THG -> 0 | D34: EUR/Jahr
B35: NOx (Stickoxide) | C35: =IF(Energie5="Strom",0,NOX_5*Fahrleistung*Kost_NOX/1000) -> 0 | D35: EUR/Jahr
B36: Partikel | C36: =IF(Energie5="Strom",0,Partikel5*Fahrleistung*Kost_Partikel/1000) -> 0 | D36: EUR/Jahr
B37: Total | C37: =SUM(C34:C36) -> 0 | D37: EUR/Jahr
B39: Vorkette: Externe Umweltkosten | C39: =CONCATENATE("Energieträger: ",Energie5,IF(Antriebsart5="Plug-In-Hybrid (PHEV)","+Strom","")) -> Energieträger:
B40: Treibhausgasemissionen (THG) | C40: =IFERROR(IF(Antriebsart5="Vollelektrisch (BEV)",VLOOKUP("Strom",CO2List,3,FALSE)*VerbEl_WLTP5/100*Fahrleistung/1000000,IF(Antriebsart5="Verbrenner",VLOOKUP(Energie5,CO2List,3,FALSE)*Verbrauch5/100*Fahrleistung/1000000,VLOOKUP(Energie5,CO2List,3,FALSE)*VerbPHEV5/100*Fahrleistung/1000000+VLOOKUP("Strom",CO2List,3,FALSE)*VerbElPHEV5/100*Fahrleistung/1000000)),0) -> 0 | D40: t CO2eq/Jahr
B41: Externe Umweltkosten Vorkette | C41: =C40*Kost_THG -> 0 | D41: EUR/Jahr
B43: Umweltrelevante Angaben - Herstellung der Batterie
B45: Herstellung Batterie: Externe Umweltkosten | C45: Batterieherstellung
A46: i | B46: Treibhausgasemissionen (THG) | C46: =IF(OR(Antriebsart5="Vollelektrisch (BEV)",Antriebsart5="Plug-In-Hybrid (PHEV)"),Batterie5*Batterie_THG/1000,0) -> 0 | D46: t CO2eq gesamt
C47: =IF((Fahrleistung*16)<220000,C46*10^6/(Fahrleistung*16),C46*10^6/220000) -> #DIV/0! | D47: g CO2eq/km
B48: Externe Umweltkosten Batterieherstellung | C48: =IF(C47*Fahrleistung/10^6*Haltedauer<C46, C47*Fahrleistung/10^6*Kost_THG, C46/Haltedauer*Kost_THG) -> #DIV/0! | D48: EUR/Jahr
B51: =CONCATENATE("Lebenszykluskosten"," (Haltedauer: ",Haltedauer," Jahre)") -> Lebenszykluskosten (Haltedauer: Jahre)
B52: Kosten des Fahrzeugs über die gesamte Haltedauer gesehen
...

Sheet Emissionsfaktoren
B2: EMISSIONSFAKTOREN | G2: zurück zu "Anleitung"
B4: THG-Emissionen Tailpipe & Vorkette (Well-to-Tank)
C6: TTW: THG | D6: WTT: THG | E6: Einheit
B7: Diesel | C7: 74 | D7: 15.8 | E7: g CO2eq/MJ
B8: Benzin | C8: 75.2 | D8: 14.2 | E8: g CO2eq/MJ
B9: Erdgas (CNG) | C9: 55.8 | D9: 13.7 | E9: g CO2eq/MJ
B11: Quelle: TREMOD (2020)
B13: Umrechnungsfaktoren Energieträger
B15: Energieträger | C15: Ausgangseinheit | E15: Umrechnung in MJ
B16: Diesel | C16: 1 | D16: l | E16: 35.872 | F16: MJ
B17: Benzin | C17: 1 | D17: l | E17: 32.44 | F17: MJ
B18: Erdgas (CNG) | C18: 1 | D18: kg | E18: 46.5 | F18: MJ
B20: Quellen: AGEB (2022); TREMOD (2020)
B23: THG-Emissionen Tailpipe & Vorkette (Well-to-Tank)
H24: Ausgangswert (TREMOD 2020) | M24: Daten aus Projektionsbericht (UBA 2021), Zwischenwerte sind linear interpoliert
C25: TTW: THG | D25: WTT: THG | E25: Einheit
A26: i | B26: Strom | C26: 0 | D26: =SUMIF(I26:AE26,YEAR(TODAY())+ROUND(Haltedauer,0),I28:AE28) -> 402.53333 | E26: g CO2eq/kWh | H26: Jahr | I26: 2022 | J26: 2023 | K26: 2024 | L26: 2025 | M26: 2026 | N26: 2027 | O26: 2028 | P26: 2029 | Q26: 2030 | R26: 2031 | S26: 2032 | T26: 2033 | U26: 2034 | V26: 2035 | W26: 2036 | X26: 2037 | Y26: 2038 | Z26: 2039 | AA26: 2040 | AB26: 2041 | AC26: 2042 | AD26: 2043 | AE26: 2044
A27: i | B27: Diesel | C27: =C7*E16 -> 2654.528 | D27: =D7*E16 -> 566.7776 | E27: g CO2eq/l | H27: g CO₂/kWh lt. Literaturquelle | I27: 420 | J27: 402.53333 | K27: 385.06667 | L27: 367.6 | M27: 351.6 | N27: 335.6 | O27: 319.6 | P27: 303.6 | Q27: 287.6 | R27: 265.44 | S27: 243.28 | T27: 221.12 | U27: 198.96 | V27: 176.8 | W27: 158.84 | X27: 140.88 | Y27: 122.92 | Z27: 104.96 | AA27: 87 | AB27: 69.04 | AC27: 51.08 | AD27: 33.12 | AE27: 15.16
B28: Benzin | C28: =C8*E17 -> 2439.488 | D28: =D8*E17 -> 460.648 | E28: g CO2eq/l | H28: Retrospektiver Mittelwert | I28: 420 | J28: =AVERAGE($I$27:J27) -> 411.26667 | K28: =AVERAGE($I$27:K27) -> 402.53333 | L28: =AVERAGE($I$27:L27) -> 393.8 | M28: =AVERAGE($I$27:M27) -> 385.36 | N28: =AVERAGE($I$27:N27) -> 377.06667 | O28: =AVERAGE($I$27:O27) -> 368.85714 | P28: =AVERAGE($I$27:P27) -> 360.7 | Q28: =AVERAGE($I$27:Q27) -> 352.57778 | ... AE28: =AVERAGE($I$27:AE27) -> 220.07826
B29: Erdgas (CNG) | C29: =C9*E18 -> 2594.7 | D29: =D9*E18 -> 637.05 | E29: g CO2eq/kg

Sheet Listen
B2: Finanzierungsart
B3: Kauf | C3: EUR | D3: Fahrzeuggesamtpreis (brutto)
B4: Leasing | C4: EUR/Monat | D4: Leasingrate (brutto)
B5: Miete | C5: EUR/Monat | D5: Miete (brutto)
B7: Antriebsart
B8: Vollelektrisch (BEV)
B9: Plug-in-Hybrid (PHEV)
B10: Verbrenner
B12: Energieträger
B13: EnList1
B14: EnList2 | D14: Auf den jeweiligen Reitern Pkw1-5 Felder H5-H12,
B15: EnList3 | D15: da abhängig von der jeweils gewählten Antriebsart
B16: EnList4
B17: EnList5
B19: Ausgangseinheiten der Energieträger
B20: Strom | D20: kWh
B21: Diesel | D21: l
B22: Benzin | D22: l
B23: Erdgas (CNG) | D23: kg
B25: Berücksichtung Fahrzeugpreis
B26: Kaufpreis
B27: Wertminderung
B29: Fahrzeugsegment
B30: Standard
B31: Utilities/Mini-Vans/Großraum-Vans
B33: Externe Umweltkosten Treibhausgasemissionen
B34: (Niedrig) 200
B35: (Hoch) 500

Sheet Doku
B2: SCHEMATISCHE DARSTELLUNG DER BERECHNUNG DER LZK | Q2: zurück zu "Anleitung"
B39: 1 Die Stromkosten werden zusätzlich in Abhängigkeit des Anteils Laden eigene Säule/öffentlich (Reiter Input Projekt) berechnet.
B40: 2 Die CO2-Kosten lassen sich zusätzlich im Reiter Input Projekt einstellen.
B41: 3 Plötz, P. & Jöhrens, J. (2021): Realistic Test Cycle Utility Factors for Plug-in Hybrid Electric Vehicles in Europe. Karlsruhe: Fraunhofer Institute for Systems and Innovation Research ISI
B44: Die ausführliche Dokumentation finden Sie als PDF auf der Website
B45: https://www.nachhaltige-oeffentliche-pkw-beschaffung.de unter "Downloads"
B48: LISTE DER FELDNAMEN
B50: Datum | D50: =Input_Projekt!$C$11
B51: Fahrleistung | D51: =Input_Projekt!$C$15
B52: FinArt | D52: =Input_Projekt!$C$17
B53: Haltedauer | D53: =Input_Projekt!$C$19
B54: KaufpreisRech | D54: =Input_Projekt!$C$21
B55: KostTHGVorgabe | D55: =Input_Projekt!$C$24
B56: Projektname_Z1 | D56: =Input_Projekt!$C$6
B57: Projektname_Z2 | D57: =Input_Projekt!$C$7
B58: Projektname_Z3 | D58: =Input_Projekt!$C$8
B59: Segment | D59: =Input_Projekt!$C$13
B60: Unternehmen | D60: =Input_Projekt!$C$9
B61: Zustaendig | D61: =Input_Projekt!$C$10
... B172: SegmentList | D172: =Listen!$B$30:$B$31

Sheet Quellen
B2: Quellenverzeichnis | E2: zurück zu "Anleitung"
B4: ADAC (2023a) | C4: ADAC Preise für Erdgas (CNG)
C5: https://www.adac.de/verkehr/tanken-kraftstoff-antrieb/alternative-antriebe/erdgas/
B6: ADAC (2023b) | C6: ADAC Spritpreis-Entwicklung
C7: https://www.adac.de/verkehr/tanken-kraftstoff-antrieb/deutschland/kraftstoffpreisentwicklung/#seit-2021
B8: AGEB (2022) | C8: AG Energiebilanzen
C9: https://ag-energiebilanzen.de/energieeinheitenumrechner/
B10: BDEW (2023) | C10: BDEW-Strompreisanalyse Juli 2023
C11: https://www.bdew.de/service/daten-und-grafiken/bdew-strompreisanalyse/
B12: BEUC (2016) | C12: BEUC (Europäischer Verbraucherverband) - Low carbon cars in the 2020s: Consumer impacts and EU policy implications
C13: https://www.beuc.eu/publications/beuc-x-2016-121_low_carbon_cars_in_the_2020s-report.pdf
B14: Biemann et al. (2023) | C14: Analyse der Umweltbilanz von Kraftfahrzeugen mit alternativen Antrieben oder Kraftstoffen auf dem Weg zu einem treibhausgasneutralen Verkehr - ifeu-Projekt (laufend) für das UBA
C15: https://www.ifeu.de/projekt/analyse-der-umweltbilanz-von-kraftfahrzeugen-mit-alternativen-antrieben-oder-kraftstoffen-auf-dem-weg-zu-einem-treibhausgasneutralen-verkehr/
B16: Lambrecht et al. (2023) | C16: Entwicklung von geeigneten Instrumenten für die umweltverträgliche Beschaffung von Pkw durch öffentliche Stellen
C17: https://www.nachhaltige-oeffentliche-pkw-beschaffung.de/assets/downloads/Abschlussbericht_Umweltvertraegliche_Pkw-Beschaffung_ifeu.pdf
B18: Matthey und Bünger (2020) | C18: Methodenkonvention 3.1 zur Ermittlung von Umweltkosten
C19: https://www.umweltbundesamt.de/sites/default/files/medien/1410/publikationen/2020-12-21_methodenkonvention_3_1_kostensaetze.pdf
B20: nextmove (2023) | C20: nextmove - Tarifvergleich für Fahrstromanbieter (13.01.2023)
C21: https://nextmove.de/analyse-zum-deutschen-elektroauto-markt/
B22: Plötz & Jöhrens (2021) | C22: Realistic Test Cycle Assessment of Plug-in Hybrid Electric Vehicles in Europe
C23: https://www.isi.fraunhofer.de/content/dam/isi/dokumente/cce/2021/BMU_Kurzpapier_UF_final.pdf
B24: T&E (2021) | C24: Analysis of electric car lifecycle CO₂ emissions - Update
C25: https://www.transportenvironment.org/wp-content/uploads/2022/05/TE_LCA_Update-June.pdf
B26: TREMOD (2020) | C26: Transport Emission Model, ifeu
C27: https://www.ifeu.de/methoden-tools/modelle/tremod/
B28: UBA (2021) | C28: Projektionsberichte (integrierte Energie- und THG-Projektionen)
C29: https://www.umweltbundesamt.de/themen/klima-energie/klimaschutz-energiepolitik-in-deutschland/szenarien-fuer-die-klimaschutz-energiepolitik/integrierte-energie-treibhausgasprojektionen/
